Workbook

Sheet 收集数据表
A1: 店铺全称 | B1: 店铺编码 | C1: 渠道 | D1: 店铺渠道 | E1: 店铺渠道编码 | F1: 店铺简称 | G1: 类型 | H1: 业务模式 | I1: 店铺运营分组 | J1: 店铺运营平台编码 | K1: 平台 | L1: 品牌 | M1: 合同公司 | N1: 货主 | O1: 运营主体
A2: 天猫花西子旗舰店 | B2: DP015 | C2: 天猫渠道 | D2: =VLOOKUP(B2,Sheet13!$A$4:$I$85,9,FALSE) -> 天猫 | E2: =VLOOKUP(D2,渠道!$A$1:$B$28,2,FALSE) -> 01 | F2: 天猫旗舰店 | G2: 线上2C | H2: 直销 | I2: =VLOOKUP(B2,Sheet13!$A$4:$M$85,13,FALSE) -> 天猫 | J2: =VLOOKUP(I2,店铺运营分组!$A$2:$B$12,2,FALSE) -> 01 | K2: 天猫 | L2: 花西子 | M2: 杭州宜格化妆品有限公司 | N2: 杭州宜格化妆品有限公司 | O2: 杭州宜格化妆品有限公司
A3: 抖音花西子旗舰店 | B3: DP007 | C3: 抖音渠道 | D3: =VLOOKUP(B3,Sheet13!$A$4:$I$85,9,FALSE) -> 抖音 | E3: =VLOOKUP(D3,渠道!$A$1:$B$28,2,FALSE) -> 02 | F3: 抖音旗舰店 | G3: 线上2C | H3: 直销 | I3: =VLOOKUP(B3,Sheet13!$A$4:$M$85,13,FALSE) -> 抖音 | J3: =VLOOKUP(I3,店铺运营分组!$A$2:$B$12,2,FALSE) -> 02 | K3: 抖音 | L3: 花西子 | M3: 杭州宜格化妆品有限公司 | N3: 杭州宜格化妆品有限公司 | O3: 杭州宜格化妆品有限公司
A4: 快手花西子旗舰店 | B4: DP031 | C4: 快手渠道 | D4: =VLOOKUP(B4,Sheet13!$A$4:$I$85,9,FALSE) -> 快手 | E4: =VLOOKUP(D4,渠道!$A$1:$B$28,2,FALSE) -> 05 | F4: 快手旗舰店 | G4: 线上2C | H4: 直销 | I4: =VLOOKUP(B4,Sheet13!$A$4:$M$85,13,FALSE) -> 快手 | J4: =VLOOKUP(I4,店铺运营分组!$A$2:$B$12,2,FALSE) -> 05 | K4: 快手 | L4: 花西子 | M4: 杭州宜格化妆品有限公司 | N4: 杭州宜格化妆品有限公司 | O4: 杭州宜格化妆品有限公司
A5: 京东花西子旗舰店 | B5: DP002 | C5: 京东渠道 | D5: =VLOOKUP(B5,Sheet13!$A$4:$I$85,9,FALSE) -> 京东 | E5: =VLOOKUP(D5,渠道!$A$1:$B$28,2,FALSE) -> 03 | F5: 京东旗舰店 | G5: 线上2C | H5: 直销 | I5: =VLOOKUP(B5,Sheet13!$A$4:$M$85,13,FALSE) -> 京东 | J5: =VLOOKUP(I5,店铺运营分组!$A$2:$B$12,2,FALSE) -> 03 | K5: 京东 | L5: 花西子 | M5: 杭州匠泽电子商务有限公司 | N5: 杭州匠泽电子商务有限公司 | O5: 杭州匠泽电子商务有限公司
A6: 京东花西子自营店 | B6: DP033 | C6: 京东渠道 | D6: =VLOOKUP(B6,Sheet13!$A$4:$I$85,9,FALSE) -> 京东 | E6: =VLOOKUP(D6,渠道!$A$1:$B$28,2,FALSE) -> 03 | F6: 京东自营店 | G6: 线下2B | H6: 经销 | I6: =VLOOKUP(B6,Sheet13!$A$4:$M$85,13,FALSE) -> 京东 | J6: =VLOOKUP(I6,店铺运营分组!$A$2:$B$12,2,FALSE) -> 03 | K6: 金蝶 | L6: 花西子 | M6: 杭州匠泽电子商务有限公司 | N6: 杭州匠泽电子商务有限公司 | O6: 杭州匠泽电子商务有限公司
A7: 唯品会花西子自营店 | B7: DP029 | C7: 唯品渠道 | D7: =VLOOKUP(B7,Sheet13!$A$4:$I$85,9,FALSE) -> 唯品会 | E7: =VLOOKUP(D7,渠道!$A$1:$B$28,2,FALSE) -> 04 | F7: 唯品会自营店 | G7: 线上2C | H7: 代销 | I7: =VLOOKUP(B7,Sheet13!$A$4:$M$85,13,FALSE) -> 自营其他 | J7: =VLOOKUP(I7,店铺运营分组!$A$2:$B$12,2,FALSE) -> 08 | K7: 唯品会 | L7: 花西子 | M7: 杭州匠泽电子商务有限公司 | N7: 杭州匠泽电子商务有限公司 | O7: 杭州匠泽电子商务有限公司
A8: 天猫花西子匠泽店 | B8: DP001 | C8: 综合渠道 | D8: =VLOOKUP(B8,Sheet13!$A$4:$I$85,9,FALSE) -> 天猫 | E8: =VLOOKUP(D8,渠道!$A$1:$B$28,2,FALSE) -> 01 | F8: 天猫匠泽店 | G8: 线上2C | H8: 直销 | I8: =VLOOKUP(B8,Sheet13!$A$4:$M$85,13,FALSE) -> 天猫 | J8: =VLOOKUP(I8,店铺运营分组!$A$2:$B$12,2,FALSE) -> 01 | K8: 天猫 | L8: 花西子 | M8: 杭州匠泽电子商务有限公司 | N8: 杭州匠泽电子商务有限公司 | O8: 杭州匠泽电子商务有限公司
A9: 得物花西子旗舰店 | B9: DP054 | C9: 综合渠道 | D9: =VLOOKUP(B9,Sheet13!$A$4:$I$85,9,FALSE) -> 得物 | E9: =VLOOKUP(D9,渠道!$A$1:$B$28,2,FALSE) -> 06 | F9: 得物 | G9: 线上2B | H9: 一件代发 | I9: =VLOOKUP(B9,Sheet13!$A$4:$M$85,13,FALSE) -> 自营其他 | J9: =VLOOKUP(I9,店铺运营分组!$A$2:$B$12,2,FALSE) -> 08 | K9: 得物 | L9: 花西子 | M9: 杭州匠泽电子商务有限公司 | N9: 杭州匠泽电子商务有限公司 | O9: 杭州匠泽电子商务有限公司
A10: 考拉花西子旗舰店 | B10: DP004 | C10: 综合渠道 | D10: =VLOOKUP(B10,Sheet13!$A$4:$I$85,9,FALSE) -> 考拉 | E10: =VLOOKUP(D10,渠道!$A$1:$B$28,2,FALSE) -> 10 | F10: 考拉旗舰店 | G10: 线上2C | H10: 直销 | I10: =VLOOKUP(B10,Sheet13!$A$4:$M$85,13,FALSE) -> 自营其他 | J10: =VLOOKUP(I10,店铺运营分组!$A$2:$B$12,2,FALSE) -> 08 | K10: 考拉 | L10: 花西子 | M10: 杭州匠泽电子商务有限公司 | N10: 杭州匠泽电子商务有限公司 | O10: 杭州匠泽电子商务有限公司
A11: 京东到家 | B11: DP052 | C11: 综合渠道 | D11: =VLOOKUP(B11,Sheet13!$A$4:$I$85,9,FALSE) -> 京东到家 | E11: 28 | F11: 京东到家 | G11: 线上2C | H11: 直销 | I11: =VLOOKUP(B11,Sheet13!$A$4:$M$85,13,FALSE) -> 自营其他 | J11: =VLOOKUP(I11,店铺运营分组!$A$2:$B$12,2,FALSE) -> 08 | K11: 京东 | L11: 花西子 | M11: 杭州匠泽电子商务有限公司 | N11: 杭州匠泽电子商务有限公司 | O11: 杭州匠泽电子商务有限公司
A12: 有赞花西子旗舰店 | B12: DP006 | C12: 有赞 | D12: =VLOOKUP(B12,Sheet13!$A$4:$I$85,9,FALSE) -> 有赞 | E12: =VLOOKUP(D12,渠道!$A$1:$B$28,2,FALSE) -> 14 | F12: 有赞旗舰店 | G12: 线上2C | H12: 直销 | I12: =VLOOKUP(B12,Sheet13!$A$4:$M$85,13,FALSE) -> 微信 | J12: =VLOOKUP(I12,店铺运营分组!$A$2:$B$12,2,FALSE) -> 07 | K12: 有赞 | L12: 花西子 | M12: 杭州花凝香生物科技有限公司 | N12: 杭州宜格化妆品有限公司 | O12: 杭州花凝香生物科技有限公司
A13: 拼多多花西子专卖店 | B13: DP011 | C13: 拼多多 | D13: =VLOOKUP(B13,Sheet13!$A$4:$I$85,9,FALSE) -> 拼多多 | E13: =VLOOKUP(D13,渠道!$A$1:$B$28,2,FALSE) -> 07 | F13: 拼多多专卖店 | G13: 线上2C | H13: 直销 | I13: =VLOOKUP(B13,Sheet13!$A$4:$M$85,13,FALSE) -> 自营其他 | J13: =VLOOKUP(I13,店铺运营分组!$A$2:$B$12,2,FALSE) -> 08 | K13: 拼多多 | L13: 花西子 | M13: 杭州匠泽电子商务有限公司 | N13: 杭州匠泽电子商务有限公司 | O13: 杭州匠泽电子商务有限公司
A14: 拼多多花西子匠泽店 | B14: DP030 | C14: 拼多多 | D14: =VLOOKUP(B14,Sheet13!$A$4:$I$85,9,FALSE) -> 拼多多 | E14: =VLOOKUP(D14,渠道!$A$1:$B$28,2,FALSE) -> 07 | F14: 拼多多专营店 | G14: 线上2C | H14: 直销 | I14: =VLOOKUP(B14,Sheet13!$A$4:$M$85,13,FALSE) -> 自营其他 | J14: =VLOOKUP(I14,店铺运营分组!$A$2:$B$12,2,FALSE) -> 08 | K14: 拼多多 | L14: 花西子 | M14: 杭州匠泽电子商务有限公司 | N14: 杭州匠泽电子商务有限公司 | O14: 杭州匠泽电子商务有限公司
A15: 拼多多花西子美妆专卖店 | B15: DP069 | C15: 拼多多 | D15: =VLOOKUP(B15,Sheet13!$A$4:$I$85,9,FALSE) -> 拼多多 | E15: =VLOOKUP(D15,渠道!$A$1:$B$28,2,FALSE) -> 07 | F15: 拼多多专卖店 | G15: 线上2C | H15: 直销 | I15: =VLOOKUP(B15,Sheet13!$A$4:$M$85,13,FALSE) -> 自营其他 | J15: =VLOOKUP(I15,店铺运营分组!$A$2:$B$12,2,FALSE) -> 08 | K15: 拼多多 | L15: 花西子 | M15: 杭州匠泽电子商务有限公司 | N15: 杭州匠泽电子商务有限公司 | O15: 杭州匠泽电子商务有限公司
A16: 拼多多花西子美妆旗舰店 | B16: DP071 | C16: 拼多多 | D16: =VLOOKUP(B16,Sheet13!$A$4:$I$85,9,FALSE) -> 拼多多 | E16: =VLOOKUP(D16,渠道!$A$1:$B$28,2,FALSE) -> 07 | F16: 拼多多旗舰店 | G16: 线上2C | H16: 直销 | I16: =VLOOKUP(B16,Sheet13!$A$4:$M$85,13,FALSE) -> 自营其他 | J16: =VLOOKUP(I16,店铺运营分组!$A$2:$B$12,2,FALSE) -> 08 | K16: 拼多多 | L16: 花西子 | M16: 杭州匠泽电子商务有限公司 | N16: 杭州匠泽电子商务有限公司 | O16: 杭州匠泽电子商务有限公司
A17: 小红书花西子品牌店 | B17: DP008 | C17: 综合渠道 | D17: =VLOOKUP(B17,Sheet13!$A$4:$I$85,9,FALSE) -> 小红书 | E17: =VLOOKUP(D17,渠道!$A$1:$B$28,2,FALSE) -> 08 | F17: 小红书品牌店 | G17: 线上2C | H17: 直销 | I17: =VLOOKUP(B17,Sheet13!$A$4:$M$85,13,FALSE) -> 自营其他 | J17: =VLOOKUP(I17,店铺运营分组!$A$2:$B$12,2,FALSE) -> 08 | K17: 小红书 | L17: 花西子 | M17: 杭州宜格化妆品有限公司 | N17: 杭州宜格化妆品有限公司 | O17: 杭州宜格化妆品有限公司
A18: 凯德星店 | B18: DP019 | C18: 综合渠道 | D18: =VLOOKUP(B18,Sheet13!$A$4:$I$85,9,FALSE) -> 凯德星 | E18: =VLOOKUP(D18,渠道!$A$1:$B$28,2,FALSE) -> 11 | F18: 凯德星 | G18: 线上2C | H18: 直销 | I18: =VLOOKUP(B18,Sheet13!$A$4:$M$85,13,FALSE) -> 自营其他 | J18: =VLOOKUP(I18,店铺运营分组!$A$2:$B$12,2,FALSE) -> 08 | K18: 凯德星 | L18: 花西子 | M18: 杭州匠泽电子商务有限公司 | N18: 杭州匠泽电子商务有限公司 | O18: 杭州匠泽电子商务有限公司
A19: 体验官微信小程序店 | B19: WeChat01 | C19: 综合渠道 | D19: =VLOOKUP(B19,Sheet13!$A$4:$I$85,9,FALSE) -> 微信 | E19: =VLOOKUP(D19,渠道!$A$1:$B$28,2,FALSE) -> 13 | F19: 体验官小程序 | G19: 线上2C | H19: 直销 | I19: =VLOOKUP(B19,Sheet13!$A$4:$M$85,13,FALSE) -> 微信 | J19: =VLOOKUP(I19,店铺运营分组!$A$2:$B$12,2,FALSE) -> 07 | K19: 微信 | L19: 花西子 | M19: 杭州宜格化妆品有限公司 | N19: 杭州宜格化妆品有限公司 | O19: 杭州宜格化妆品有限公司
A20: 花西子会员俱乐部店 | B20: DP032 | C20: 综合渠道 | D20: =VLOOKUP(B20,Sheet13!$A$4:$I$85,9,FALSE) -> 会员店铺 | E20: =VLOOKUP(D20,渠道!$A$1:$B$28,2,FALSE) -> 15 | F20: 会员店铺 | G20: 线上2C | H20: 直销 | I20: =VLOOKUP(B20,Sheet13!$A$4:$M$85,13,FALSE) -> 自营其他 | J20: =VLOOKUP(I20,店铺运营分组!$A$2:$B$12,2,FALSE) -> 08 | K20: 微信 | L20: 花西子 | M20: 杭州宜格化妆品有限公司 | N20: 杭州宜格化妆品有限公司 | O20: 杭州宜格化妆品有限公司
A21: 快手花西子宜格企业店 | B21: DP080 | C21: 快手渠道 | D21: =VLOOKUP(B21,Sheet13!$A$4:$I$85,9,FALSE) -> 快手 | E21: =VLOOKUP(D21,渠道!$A$1:$B$28,2,FALSE) -> 05 | F21: 快手人设号 | G21: 线上2C | H21: 直销 | I21: =VLOOKUP(B21,Sheet13!$A$4:$M$85,13,FALSE) -> 快手 | J21: =VLOOKUP(I21,店铺运营分组!$A$2:$B$12,2,FALSE) -> 05 | K21: 快手 | L21: 花西子 | M21: 杭州宜格化妆品有限公司 | N21: 杭州宜格化妆品有限公司 | O21: 杭州宜格化妆品有限公司
A22: 微信视频号花西子旗舰店 | B22: DP070 | C22: 综合渠道 | D22: =VLOOKUP(B22,Sheet13!$A$4:$I$85,9,FALSE) -> 微信 | E22: =VLOOKUP(D22,渠道!$A$1:$B$28,2,FALSE) -> 13 | F22: 微信视频号旗舰店 | G22: 线上2C | H22: 直销 | I22: =VLOOKUP(B22,Sheet13!$A$4:$M$85,13,FALSE) -> 微信 | J22: =VLOOKUP(I22,店铺运营分组!$A$2:$B$12,2,FALSE) -> 07 | K22: 微信 | L22: 花西子 | M22: 杭州花凝香生物科技有限公司 | N22: 杭州花凝香生物科技有限公司 | O22: 杭州花凝香生物科技有限公司
A23: 快手花西子东方有佳人店 | B23: DP059 | C23: 快手渠道 | D23: 快手 | E23: 05 | F23: 快手小店 | G23: 线上2C | H23: 直销 | I23: 快手 | J23: =VLOOKUP(I23,店铺运营分组!$A$2:$B$12,2,FALSE) -> 05 | K23: 快手 | L23: 花西子 | M23: 杭州宜格化妆品有限公司 | N23: 杭州宜格化妆品有限公司 | O23: 杭州宜格化妆品有限公司

Sheet 渠道
A1: 渠道名称 | B1: 渠道编码
A2: 天猫 | B2: 01
A3: 抖音 | B3: 02
A4: 京东 | B4: 03
A5: 唯品会 | B5: 04
A6: 快手 | B6: 05
A7: 得物 | B7: 06
A8: 拼多多 | B8: 07
A9: 小红书 | B9: 08
A10: LBS | B10: 09
A11: 考拉 | B11: 10
A12: 凯德星 | B12: 11
... A29: 京东到家 | B29: 28

Sheet 渠道树
A1: 店铺 | B1: 店铺编码 | C1: 渠道 | D1: 渠道编码 | E1: 业务来源（名字变更为业务单元） | F1: 编码(更新) | G1: 业务单元（名字变更为业务来源） | H1: 编码(更新) | I1: 备注
A2: 天猫花西子旗舰店 | B2: DP015 | C2: =VLOOKUP(B2,收集数据表!$B$2:$D$22,3,FALSE) -> 天猫 | D2: =VLOOKUP(B2,收集数据表!$B$2:$E$22,4,FALSE) -> 01 | E2: 天猫自播 | F2: DP01501 | G2: 天猫自播 | H2: DP0150101
A3: 天猫花西子旗舰店 | B3: DP015 | C3: =VLOOKUP(B3,收集数据表!$B$2:$D$22,3,FALSE) -> 天猫 | D3: =VLOOKUP(B3,收集数据表!$B$2:$E$22,4,FALSE) -> 01 | E3: 天猫货架 | F3: DP01502 | G3: 天猫货架 | H3: DP0150201
A4: 天猫花西子旗舰店 | B4: DP015 | C4: =VLOOKUP(B4,收集数据表!$B$2:$D$22,3,FALSE) -> 天猫 | D4: =VLOOKUP(B4,收集数据表!$B$2:$E$22,4,FALSE) -> 01 | E4: 天猫达播-LJQ | F4: DP01503 | G4: 天猫达播-LJQ | H4: DP0150301
A5: 天猫花西子旗舰店 | B5: DP015 | C5: =VLOOKUP(B5,收集数据表!$B$2:$D$22,3,FALSE) -> 天猫 | D5: =VLOOKUP(B5,收集数据表!$B$2:$E$22,4,FALSE) -> 01 | E5: 天猫达播-其他 | F5: DP01504 | G5: 天猫达播-其他 | H5: DP0150401
A6: 抖音花西子旗舰店 | B6: DP007 | C6: =VLOOKUP(B6,收集数据表!$B$2:$D$22,3,FALSE) -> 抖音 | D6: =VLOOKUP(B6,收集数据表!$B$2:$E$22,4,FALSE) -> 02 | E6: 抖音矩阵号 | F6: DP00701 | G6: 彩妆有术 | H6: DP0070101 | I6: 千川投放标签是否到直播间待确认
A7: 抖音花西子旗舰店 | B7: DP007 | C7: =VLOOKUP(B7,收集数据表!$B$2:$D$22,3,FALSE) -> 抖音 | D7: =VLOOKUP(B7,收集数据表!$B$2:$E$22,4,FALSE) -> 02 | E7: 抖音矩阵号 | F7: DP00701 | G7: 花西子妆养旗舰店 | H7: DP0070102
A8: 抖音花西子旗舰店 | B8: DP007 | C8: =VLOOKUP(B8,收集数据表!$B$2:$D$22,3,FALSE) -> 抖音 | D8: =VLOOKUP(B8,收集数据表!$B$2:$E$22,4,FALSE) -> 02 | E8: 抖音矩阵号 | F8: DP00701 | G8: 素人改造 | H8: DP0070103
A9: 抖音花西子旗舰店 | B9: DP007 | C9: =VLOOKUP(B9,收集数据表!$B$2:$D$22,3,FALSE) -> 抖音 | D9: =VLOOKUP(B9,收集数据表!$B$2:$E$22,4,FALSE) -> 02 | E9: 抖音矩阵号 | F9: DP00701 | G9: 东方有佳人 | H9: DP0070104
A10: 抖音花西子旗舰店 | B10: DP007 | C10: =VLOOKUP(B10,收集数据表!$B$2:$D$22,3,FALSE) -> 抖音 | D10: =VLOOKUP(B10,收集数据表!$B$2:$E$22,4,FALSE) -> 02 | E10: 抖音矩阵号 | F10: DP00701 | G10: 礼待佳人 | H10: DP0070105
A11: 抖音花西子旗舰店 | B11: DP007 | C11: =VLOOKUP(B11,收集数据表!$B$2:$D$22,3,FALSE) -> 抖音 | D11: =VLOOKUP(B11,收集数据表!$B$2:$E$22,4,FALSE) -> 02 | E11: 抖音矩阵号 | F11: DP00701 | G11: 花西子礼物精选 | H11: DP0070106
A12: 抖音花西子旗舰店 | B12: DP007 | C12: =VLOOKUP(B12,收集数据表!$B$2:$D$22,3,FALSE) -> 抖音 | D12: =VLOOKUP(B12,收集数据表!$B$2:$E$22,4,FALSE) -> 02 | E12: 抖音矩阵号 | F12: DP00701 | G12: 花西子戏曲红妆 | H12: DP0070107
A13: 抖音花西子旗舰店 | B13: DP007 | C13: =VLOOKUP(B13,收集数据表!$B$2:$D$22,3,FALSE) -> 抖音 | D13: =VLOOKUP(B13,收集数据表!$B$2:$E$22,4,FALSE) -> 02 | E13: 抖音矩阵号 | F13: DP00701 | G13: 花西子在海外 | H13: DP0070108
A14: 抖音花西子旗舰店 | B14: DP007 | C14: =VLOOKUP(B14,收集数据表!$B$2:$D$22,3,FALSE) -> 抖音 | D14: =VLOOKUP(B14,收集数据表!$B$2:$E$22,4,FALSE) -> 02 | E14: 抖音矩阵号 | F14: DP00701 | G14: 美妆龙 | H14: DP0070109
A15: 抖音花西子旗舰店 | B15: DP007 | C15: =VLOOKUP(B15,收集数据表!$B$2:$D$22,3,FALSE) -> 抖音 | D15: =VLOOKUP(B15,收集数据表!$B$2:$E$22,4,FALSE) -> 02 | E15: 抖音自播 | F15: DP00702 | G15: 抖音自播 | H15: DP0070201
A16: 抖音花西子旗舰店 | B16: DP007 | C16: =VLOOKUP(B16,收集数据表!$B$2:$D$22,3,FALSE) -> 抖音 | D16: =VLOOKUP(B16,收集数据表!$B$2:$E$22,4,FALSE) -> 02 | E16: 达播-田恬 | F16: DP00703 | G16: 达播-田恬 | H16: DP0070301
A17: 抖音花西子旗舰店 | B17: DP007 | C17: =VLOOKUP(B17,收集数据表!$B$2:$D$22,3,FALSE) -> 抖音 | D17: =VLOOKUP(B17,收集数据表!$B$2:$E$22,4,FALSE) -> 02 | E17: 达播-其他 | F17: DP00704 | G17: 达播-其他 | H17: DP0070401
A18: 抖音花西子旗舰店 | B18: DP007 | C18: =VLOOKUP(B18,收集数据表!$B$2:$D$22,3,FALSE) -> 抖音 | D18: =VLOOKUP(B18,收集数据表!$B$2:$E$22,4,FALSE) -> 02 | E18: 抖音货架 | F18: DP00705 | G18: 抖音货架 | H18: DP0070501
A19: 快手花西子旗舰店 | B19: DP031 | C19: =VLOOKUP(B19,收集数据表!$B$2:$D$22,3,FALSE) -> 快手 | D19: =VLOOKUP(B19,收集数据表!$B$2:$E$22,4,FALSE) -> 05 | E19: 快手非达播 | F19: DP03101 | G19: 快手非达播 | H19: DP0310101
A20: 快手花西子旗舰店 | B20: DP031 | C20: =VLOOKUP(B20,收集数据表!$B$2:$D$22,3,FALSE) -> 快手 | D20: =VLOOKUP(B20,收集数据表!$B$2:$E$22,4,FALSE) -> 05 | E20: 快手达播 | F20: DP03102 | G20: 快手达播 | H20: DP0310201 | I20: 周周珍可爱，徐婕，瑜大，快手专卖店号，有店铺，但是无销售。
A21: 快手花西子宜格企业店 | B21: DP080 | C21: =VLOOKUP(B21,收集数据表!$B$2:$D$22,3,FALSE) -> 快手 | D21: =VLOOKUP(B21,收集数据表!$B$2:$E$22,4,FALSE) -> 05 | E21: 快手人设号 | F21: DP08001 | G21: 快手人设号 | H21: DP0800101
A22: 京东花西子旗舰店 | B22: DP002 | C22: =VLOOKUP(B22,收集数据表!$B$2:$D$22,3,FALSE) -> 京东 | D22: =VLOOKUP(B22,收集数据表!$B$2:$E$22,4,FALSE) -> 03 | E22: 京东花西子旗舰店 | F22: DP00201 | G22: 京东花西子旗舰店 | H22: DP0020101
A23: 京东花西子自营店 | B23: DP033 | C23: =VLOOKUP(B23,收集数据表!$B$2:$D$22,3,FALSE) -> 京东 | D23: =VLOOKUP(B23,收集数据表!$B$2:$E$22,4,FALSE) -> 03 | E23: 京东花西子自营店 | F23: DP03301 | G23: 京东花西子自营店 | H23: DP0330101
A24: 唯品会花西子自营店 | B24: DP029 | C24: =VLOOKUP(B24,收集数据表!$B$2:$D$22,3,FALSE) -> 唯品会 | D24: =VLOOKUP(B24,收集数据表!$B$2:$E$22,4,FALSE) -> 04 | E24: 唯品会花西子自营店 | F24: DP02901 | G24: 唯品会花西子自营店 | H24: DP0290101
A25: 天猫花西子匠泽店 | B25: DP001 | C25: =VLOOKUP(B25,收集数据表!$B$2:$D$22,3,FALSE) -> 天猫 | D25: =VLOOKUP(B25,收集数据表!$B$2:$E$22,4,FALSE) -> 01 | E25: 天猫花西子匠泽店 | F25: DP00101 | G25: 天猫花西子匠泽店 | H25: DP0010101
A26: 得物花西子旗舰店 | B26: DP054 | C26: =VLOOKUP(B26,收集数据表!$B$2:$D$22,3,FALSE) -> 得物 | D26: =VLOOKUP(B26,收集数据表!$B$2:$E$22,4,FALSE) -> 06 | E26: 得物花西子旗舰店 | F26: DP05401 | G26: 得物花西子旗舰店 | H26: DP0540101
A27: 考拉花西子旗舰店 | B27: DP004 | C27: =VLOOKUP(B27,收集数据表!$B$2:$D$22,3,FALSE) -> 考拉 | D27: =VLOOKUP(B27,收集数据表!$B$2:$E$22,4,FALSE) -> 10 | E27: 考拉花西子旗舰店 | F27: DP00401 | G27: 考拉花西子旗舰店 | H27: DP0040101
A28: 京东到家 | B28: DP052 | C28: =VLOOKUP(B28,收集数据表!$B$2:$D$22,3,FALSE) -> 京东到家 | D28: =VLOOKUP(B28,收集数据表!$B$2:$E$22,4,FALSE) -> 28 | E28: 京东到家 | F28: DP05201 | G28: 京东到家 | H28: DP0520101
A29: 有赞花西子旗舰店 | B29: DP006 | C29: =VLOOKUP(B29,收集数据表!$B$2:$D$22,3,FALSE) -> 有赞 | D29: =VLOOKUP(B29,收集数据表!$B$2:$E$22,4,FALSE) -> 14 | E29: 有赞花西子旗舰店 | F29: DP00601 | G29: 有赞花西子旗舰店 | H29: DP0060101
A30: 拼多多花西子专卖店 | B30: DP011 | C30: =VLOOKUP(B30,收集数据表!$B$2:$D$22,3,FALSE) -> 拼多多 | D30: =VLOOKUP(B30,收集数据表!$B$2:$E$22,4,FALSE) -> 07 | E30: 拼多多花西子专卖店 | F30: DP01101 | G30: 拼多多花西子专卖店 | H30: DP0110101
A31: 拼多多花西子匠泽店 | B31: DP030 | C31: =VLOOKUP(B31,收集数据表!$B$2:$D$22,3,FALSE) -> 拼多多 | D31: =VLOOKUP(B31,收集数据表!$B$2:$E$22,4,FALSE) -> 07 | E31: 拼多多花西子匠泽店 | F31: DP03001 | G31: 拼多多花西子匠泽店 | H31: DP0300101
A32: 拼多多花西子美妆专卖店 | B32: DP069 | C32: =VLOOKUP(B32,收集数据表!$B$2:$D$22,3,FALSE) -> 拼多多 | D32: =VLOOKUP(B32,收集数据表!$B$2:$E$22,4,FALSE) -> 07 | E32: 拼多多花西子美妆专卖店 | F32: DP06901 | G32: 拼多多花西子美妆专卖店 | H32: DP0690101
... A37: 微信视频号花西子旗舰店 | B37: DP070 | C37: =VLOOKUP(B37,收集数据表!$B$2:$D$22,3,FALSE) -> 微信 | D37: =VLOOKUP(B37,收集数据表!$B$2:$E$22,4,FALSE) -> 13 | E37: 微信视频号花西子旗舰店 | F37: DP07001 | G37: 微信视频号花西子旗舰店 | H37: DP0700101
A38: 快手花西子东方有佳人店 | B38: DP059 | C38: 快手 | D38: 05 | E38: 快手花西子东方有佳人店 | F38: DP05901 | G38: 快手花西子东方有佳人店 | H38: DP0590101

Sheet 店铺运营分组
A1: 名称 | B1: 编码
A2: 天猫 | B2: 01
A3: 抖音 | B3: 02
A4: 京东 | B4: 03
A5: 唯品会 | B5: 04
A6: 快手 | B6: 05
A7: 海外 | B7: 06
A8: 微信 | B8: 07
A9: 自营其他 | B9: 08
A10: LBS | B10: 09
A11: 线下 | B11: 10
A12: 虚拟 | B12: 11

Sheet 平台
A1: 编码 | B1: 投放平台
A2: TFPT01 | B2: 淘宝
A3: TFPT02 | B3: 京东
A4: TFPT03 | B4: 唯品会
A5: TFPT04 | B5: 考拉
A6: TFPT05 | B6: 京东到家
A7: TFPT06 | B7: 抖音-巨量纵横
A8: TFPT07 | B8: 抖音
A9: TFPT08 | B9: 小红书
A10: TFPT09 | B10: B站
A11: TFPT10 | B11: 微博
A12: TFPT11 | B12: Uni Desk
... A26: TFPT25 | B26: 凯德星

Sheet 基础信息
A1: 字段 | B1: 字段属性 | C1: 字段解释 | D1: 用途与诉求 | E1: 字段名 | F1: 字段长度 | G1: 是否主键 | H1: 字段备注
A2: 一、 | C2: 基本信息
A3: 店铺/客户ID | B3: 文本 | C3: 客户主数据的唯一编码 | D3: 系统自动生成
A4: 店铺/客户名称 | B4: 文本 | C4: 店铺具体名称，同OMS系统内名称保持一致 | E4: store_full_name
A5: 简称 | B5: 文本 | C5: 店铺简称 | E5: store_abbr_name
A6: 店铺/客户状态 | B6: 下拉-单选 | C6: 用于描述店铺和客户当前是否正常运营的状态 | E6: status
A7: 渠道 | B7: 下拉-单选 | C7: 店铺所对应的销售平台 | E7: channel
A8: 链接 | B8: 文本 | C8: 店铺对应的网址链接
A9: 类型 | B9: 下拉-单选 | C9: 根据客户类型和业务模式分类 | D9: 根据客户类型和业务模式判断后续从销售订单到收入确认、售后以及收款等不同的业财流程环节 | E9: channl_Type
A10: 业务模式 | B10: 下拉-单选 | C10: 以货主视角判断业务模式 | E10: biz_mode
A11: 区域范围 | B11: 下拉-单选 | C11: 预留字段，为后续境外区域拓展
A12: 销售品牌 | B12: 下拉-单选 | C12: 花西子/OGP等 | D12: 用以区分销售品牌 | E12: brand
A13: OMS业务模式 | B13: 下拉-单选 | C13: OMS系统以货主视角判断业务模式 | E13: OMS_biz_mode
A14: 运营模式 | B14: 下拉-单选 | C14: 1）商家运营：运营决定权在商家自己手里 2）平台运营：运营决定权在平台非商家能够管控 3）三方代运营：MCN等第三方机构代运营 | D14: 作为后续主数据结算参考依据 | E14: operation_mode
A15: 运营主体 | B15: 下拉-单选 | C15: 实际运营方，需要确认收入的主体 20221207:讨论后建议不改业务上对运营主体的定义，字段名称改为“结算主体”或“合同主体” | D15: 例如有赞：花凝香；匠泽C店：匠泽 | E15: Operating_entity
A16: 税号 | B16: 文本 | C16: 店铺/客户税号 | D16: 用以在销售开票和付款环节自动带出
A17: 货主 | B17: 下拉-单选 | C17: 即交易主体，发货的库存所属主体 | D17: 用以区分货主和实际运营主体不同的场景，例如有赞：花凝香；匠泽C店：匠泽 | E17: Consignor
A18: 运营供应商（预留） | B18: 下拉-单选 | C18: 预留字段信息，若未来出现三方代运营业务，则填写第三方代运营公司名称 | E18: operating_supllier
A19: 国别 | B19: 下拉-单选 | C19: 店铺/客户公司开设对应的关节
A20: 省会 | B20: 下拉-单选 | C20: 店铺/客户公司开设对应的省会
A21: 城市 | B21: 下拉-单选 | C21: 店铺/客户公司开设对应的城市
A22: 地址 | B22: 文本 | C22: 店铺/客户公司开设对应的地址
A23: 二、 | C23: 附加信息
A24: 发货仓 | B24: 下拉-单选 | C24: 交易主体默认的发货仓库
A25: 客退仓 | B25: 下拉-单选 | C25: 客户退货后默认仓库
A26: 销售部门 | B26: 下拉-单选 | C26: 对应销售所在的一级部门 | D26: 便于未来进行对账推送、流水认领的以及升级问题跟踪等
A27: 销售人员 | B27: 下拉-单选 | C27: 店铺对应主数据销售名称 | D27: 同上
A28: 三、 | C28: 收入与结算信息
A29: 预计结算周期 | B29: 下拉-单选 | C29: 2C：订单发货到平台确认收货的预计周期 2B：入库到出具账单的周期 *有赞可以调整自行设置，其他平台不可自行设置，但是一般不会变化 | D29: 用以提前预判该主数据预计结算时间范围 | E29: Exp_settlement_cycle
A30: 无理由退货期限 | B30: 下拉-单选 | C30: 平台物流签收后的无理由退货期限 | D30: 用以判断确认收入确认时点临界值，确保物流未更新后财务可账务处理 | E30: no_reason_returen_period
A31: 币种 | B31: 下拉-单选 | C31: 店铺/客户结算币种
A32: 结算时点 | C32: 结算具体节点，包括快递签收、订单确认收货等 | D32: 用以判断结算时点
A33: 四、 | C33: 付款条件
A34: 付款条件有效期 | C34: 用于判断付款信息，可能是固定日或固定时长
A35: 付款方式 | B35: 下拉-单选 | C35: 付款详情
A36: 客户信用 | C36: 2B
A37: 授信额度 | C37: 2B
A38: 额度有效期 | C38: 2B
A39: 月结日 | B39: 日期
A40: 五、 | C40: 合同
...

Sheet 基础信息参考
A1: 字段 | B1: 字段类别 | C1: 字段解释 | D1: 用途与诉求 | E1: 字段填写要求 | I1: 下一步行动
E2: 直销 | F2: 经销 | G2: 代销 | H2: 一件代发
A3: 一、 | C3: 基本信息
A4: 店铺/客户ID | C4: 客户主数据的唯一编码 | D4: 系统自动生成 | E4: N/A | F4: N/A | G4: N/A | H4: N/A
A5: 店铺/客户名称 | C5: 店铺具体名称，同OMS系统内名称保持一致 | E5: 必填 | F5: 必填 | G5: 必填 | H5: 必填
A6: 简称 | C6: 店铺简称 | E6: 必填 | F6: 必填 | G6: 必填 | H6: 必填
A7: 店铺/客户状态 | B7: 目前已有 | C7: 用于描述店铺和客户当前是否正常运营的状态： 1）未运营 2）运营中 3）已撤店 …… | E7: 必填 | F7: 必填 | G7: 必填 | H7: 必填 | I7: 沿用主数据字段
A8: 渠道 | C8: 店铺所对应的销售平台： 1）天猫 2）京东 3）抖音 4）快手 5）得物等 | E8: 必填 | F8: 必填 | G8: 必填 | H8: 必填
A9: 链接 | C9: 店铺对应的网址链接 | E9: 必填 | F9: 选填 | G9: 选填 | H9: 选填
A10: 类型 | B10: 建议新增 | C10: 1）线上2C 2）线上2B 3）线下2C 4）线下2B 5）虚拟客户 | D10: 根据客户类型和业务模式判断后续从销售订单到收入确认、售后以及收款等不同的业财流程环节 | E10: 必填 | F10: 必填 | G10: 必填 | H10: 必填
A11: 业务模式 | B11: 建议新增 | C11: 以货主视角判断业务模式： 1）直销模式 2）经销模式 3）一件代发模式 4）代销模式 5）其他 | E11: 必填 | F11: 必填 | G11: 必填 | H11: 必填
A12: 区域范围 | B12: 建议新增 | C12: 预留字段，为后续境外区域拓展 1）境内 2）台湾 3）日本 4）美国等 | E12: 选填 | F12: 选填 | G12: 选填 | H12: 选填
A13: 销售品牌 | C13: 花西子/OGP等 | D13: 用以区分销售品牌 | E13: 必填 | F13: 必填 | G13: 必填 | H13: 必填
A14: 运营模式 | B14: 目前已有 | C14: 1）商家运营：运营决定权在商家自己手里 2）平台运营：运营决定权在平台非商家能够管控 3）三方代运营：MCN等第三方机构代运营 | D14: 作为后续主数据结算参考依据 | E14: 选填 | F14: 选填 | G14: 选填 | H14: 选填
A15: 运营主体 | C15: 实际运营方，需要确认收入的主体 20221207:讨论后建议不改业务上对运营主体的定义，字段名称改为“结算主体”或“合同主体” | D15: 例如有赞：花凝香；匠泽C店：匠泽 | E15: 选填 | F15: 选填 | G15: 选填 | H15: 选填
A16: 货主 | C16: 即交易主体，发货的库存所属主体 | D16: 用以区分货主和实际运营主体不同的场景，例如有赞：花凝香；匠泽C店：匠泽 | E16: 必填 | F16: 必填 | G16: 必填 | H16: 必填
A17: 运营供应商（预留） | B17: 建议新增 | C17: 预留字段信息，若未来出现三方代运营业务，则填写第三方代运营公司名称 | E17: 选填 | F17: 选填 | G17: 选填 | H17: 选填
A18: 国别 | C18: 店铺/客户公司开设对应的关节 | E18: 选填 | F18: 选填 | G18: 选填 | H18: 选填
A19: 省会 | C19: 店铺/客户公司开设对应的省会 | E19: 选填 | F19: 选填 | G19: 选填 | H19: 选填
A20: 城市 | C20: 店铺/客户公司开设对应的城市 | E20: 选填 | F20: 选填 | G20: 选填 | H20: 选填
A21: 地址 | C21: 店铺/客户公司开设对应的地址 | E21: 选填 | F21: 选填 | G21: 选填 | H21: 选填
A22: 二、 | C22: 附加信息
A23: 币种 | C23: 店铺/客户结算币种 | E23: 选填 | F23: 选填 | G23: 选填 | H23: 选填
A24: 税号 | C24: 店铺/客户税号 | D24: 用以在销售开票和付款环节自动带出 | E24: 必填 | F24: 必填 | G24: 必填 | H24: 必填
A25: 发货仓 | C25: 交易主体默认的发货仓库 | E25: 必填 | F25: 必填 | G25: 必填 | H25: 必填
A26: 客退仓 | C26: 客户退货后默认仓库 | E26: 必填 | F26: 必填 | G26: 必填 | H26: 必填
A27: 上架方式 | C27: SKU SPU ID SKU ID | E27: 必填 | F27: 必填 | G27: 必填 | H27: 必填
A28: 销售部门 | C28: 对应销售所在的一级部门 | D28: 便于未来进行对账推送、流水认领的以及升级问题跟踪等 | E28: 必填 | F28: 必填 | G28: 必填 | H28: 必填
A29: 销售人员 | C29: 店铺对应主数据销售名称 | D29: 同上
A30: 三、 | C30: 收入与结算信息
A31: 预计结算周期 | B31: 建议新增 | C31: 2C：订单发货到平台确认收货的预计周期 2B：入库到出具账单的周期 *有赞可以调整自行设置，其他平台不可自行设置，但是一般不会变化 | D31: 用以提前预判该主数据预计结算时间范围 | E31: 必填 | F31: 必填 | G31: 必填 | H31: 必填 | I31: 可能不符合主数据原则，待后续明确使用相关方，判断是否作为主数据维护or在财务系统单独维护
A32: 无理由退货期限 | B32: 建议新增 | C32: 平台物流签收后的无理由退货期限 | D32: 用以判断确认收入确认时点临界值，确保物流未更新后财务可账务处理 | E32: 必填 | F32: 必填 | G32: 必填 | H32: 必填 | I32: 确认新增
A33: 结算时点 | C33: 结算具体节点，包括快递签收、订单确认收货等 | D33: 用以判断结算时点 | E33: 选填 | F33: 选填 | G33: 选填 | H33: 选填 | I33: 建议业务不填写，财务待后续看如何同步此信息，以进行结算提醒
A34: 四、 | C34: 付款条件
A35: 付款条件有效期 | C35: 用于判断付款信息，可能是固定日或固定时长 | E35: 必填 | F35: 必填 | G35: 必填 | H35: 必填
A36: 付款方式 | C36: 付款详情 | E36: 必填 | F36: 必填 | G36: 必填 | H36: 必填
A37: 客户信用 | C37: 2B | E37: 选填 | F37: 必填 | G37: 必填 | H37: 选填
A38: 授信额度 | C38: 2B | E38: 选填 | F38: 必填 | G38: 必填 | H38: 选填
A39: 额度有效期 | C39: 2B | E39: 选填 | F39: 必填 | G39: 必填 | H39: 选填
A40: 月结日 | E40: 必填 | F40: 必填 | G40: 必填 | H40: 必填
...

Sheet 销售部门
A1: 销售部门
A2: 字段 | B2: 是否必填 | C2: 枚举值Code | D2: 枚举值 | E2: 外键 | F2: 备注说明 | G2: 经分是否需要 | H2: 经分是否需要业务处理 | I2: 经分处理逻辑
A3: 销售部门 | B3: Y | D3: NA | G3: Y | H3: N
A4: 店铺 | B4: Y | D4: NA | E4: Stone_Id | F4: 通过Storn_id关联店铺 | G4: Y | H4: N

Sheet 销售人员
A1: 销售部门
A2: 字段 | B2: 是否必填 | C2: 枚举值Code | D2: 枚举值 | E2: 外键 | F2: 备注说明 | G2: 经分是否需要 | H2: 经分是否需要业务处理 | I2: 经分处理逻辑
A3: 销售人员 | B3: Y | D3: NA | G3: Y | H3: N
A4: 店铺 | B4: Y | D4: NA | E4: Stone_Id | F4: 通过Storn_id关联店铺 | G4: Y | H4: N

Sheet 发货仓
A1: 渠道
A2: 字段 | B2: 是否必填 | C2: 枚举值Code | D2: 枚举值 | E2: 外键 | F2: 备注说明 | G2: 经分是否需要 | H2: 经分是否需要业务处理 | I2: 经分处理逻辑
A3: 发货仓名字 | B3: Y | D3: NA | E3: Warehouse_Id | F3: 通过Warehouse_Id关联发货仓表 | G3: Y | H3: N
A4: 店铺 | B4: Y | D4: NA | E4: Stone_Id | F4: 通过Storn_id关联店铺 | G4: Y | H4: N

Sheet 区域范围
A1: 店铺基础信息表
A2: 字段 | B2: 是否必填 | C2: 枚举值Code | D2: 枚举值 | E2: 外键 | F2: 备注说明 | G2: 经分是否需要 | H2: 经分是否需要业务处理 | I2: 经分处理逻辑
A3: 区域范围 | B3: Y | C3: 01 | E3: NA | F3: 枚举值说明 | G3: Y | H3: Y
C4: 02
C5: 03
C6: 04
C7: 05
A8: 国家 | B8: Y | E8: CountryId | F8: 关联国家主数据，Hierarchy结构，父子限制关系
A9: 省 | E9: ProvinceId
A10: 市 | E10: CityId

Sheet 结算主体
A1: 结算主体
A2: 字段 | B2: 是否必填 | C2: 枚举值Code | D2: 枚举值 | E2: 外键 | F2: 备注说明 | G2: 经分是否需要 | H2: 经分是否需要业务处理 | I2: 经分处理逻辑
A3: 主体名称 | B3: Y | C3: 01 | E3: NA | F3: 枚举值说明 | G3: Y | H3: Y
C4: 02
C5: 03
C6: 04
C7: 05
A8: 主体ID
A9: 主体账号
A10: 主体状态

Sheet 枚举值
A1: 字段 | B1: 是否必填 | C1: 枚举值Code | D1: 枚举值 | E1: 外键 | F1: 备注说明 | G1: 经分是否需要 | H1: 经分是否需要业务处理 | I1: 经分处理逻辑
A2: 店铺状态 | B2: Y | C2: 01 | E2: NA | F2: 枚举值说明 | G2: Y | H2: Y
C3: 02
C4: 03
C5: 04
C6: 05
A7: 店铺类型 | B7: Y | C7: 01 | D7: 线上2C | E7: NA | F7: 枚举值说明 | G7: Y | H7: Y
C8: 02 | D8: 线上2B
C9: 03 | D9: 线下2C
C10: 04 | D10: 线下2B
C11: 05 | D11: 虚拟客户
A12: 业务模式 | B12: Y | C12: 01 | E12: NA | F12: 枚举值说明 | G12: Y | H12: Y
C13: 02
C14: 03
C15: 04
C16: 05
A17: 运营模式 | B17: Y | C17: 01 | E17: NA | F17: 枚举值说明 | G17: Y | H17: Y
C18: 02
C19: 03
C20: 04
C21: 05
A22: 销售品牌 | B22: Y | C22: 01 | E22: NA | F22: 枚举值说明 | G22: Y | H22: Y
C23: 02
C24: 03
C25: 04
C26: 05
A27: OMS业务模式 | B27: Y | C27: 01 | E27: NA | F27: 枚举值说明 | G27: Y | H27: Y
C28: 02
C29: 03
C30: 04
C31: 05

Sheet Sheet13
A1: 店铺编码 | B1: 店铺标准名称 | C1: 店铺简称 | D1: 店铺名称 | E1: 店铺类型 | F1: 店铺业务模式 | G1: 币种 | H1: 无理由退货期限 | I1: 店铺渠道 | J1: 店铺链接 | K1: 店铺销售品牌 | L1: 店铺销售区域 | M1: 店铺运营分组 | N1: 店铺合同主体 | O1: 库存主体 | P1: 店铺负责人 | Q1: 店铺运营状态 | R1: 店铺系统状态
A2: 国内：DP+3位流水号 海外：HWDP+3位流水号 虚拟：XNDP+3位流水号 | B2: 店铺按规则定义的标准名称： 店铺渠道+店铺销售品牌+合作类型/店铺合同主体简称 | C2: 店铺的简称： 店铺渠道+合作类型/店铺合同主体简称 | D2: 店铺在平台上登记注册的名称 | E2: 店铺的销售类型 | F2: 商品的销售渠道 | H2: 平台物流签收后的无理由退货期限 | I2: 店铺登记注册的平台 | J2: 店铺对应的渠道网址 | K2: 店铺销售的品牌 | L2: 店铺经营的区域范围 | M2: 店铺所属的运营分组 | N2: 平台与公司签订合同主体 | O2: 货物提供方，发货的库存所属主体 | P2: 管理店铺的人员 | Q2: 店铺的运营状态 | R2: 店铺的系统状态
A3: 主数据 | B3: 主数据 | C3: 主数据 | D3: 待运营部门确认 | E3: 待运营部门确认 | F3: 待运营部门确认 | H3: 待运营部门确认 | I3: 待运营部门确认 | J3: 待运营部门确认 | K3: 待运营部门确认 | L3: 待运营部门确认 | M3: 待运营部门确认 | N3: 待运营部门确认 | O3: 按照销售品牌确认 | P3: 待运营部门确认 | Q3: 待运营部门确认 | R3: 主数据
A4: DP001 | B4: 天猫花西子匠泽店 | C4: 天猫匠泽店 | D4: 天猫花西子匠泽专卖店 | E4: 线上2C | F4: 直销模式 | G4: RMB | H4: 7天 | I4: 天猫 | J4: https://huaxizijz.tmall.com/?spm=a217wi.openworkbeanchtmall.widgets.2.41e65e16R2ERRr | K4: 花西子 | L4: 中国 | M4: 天猫 | N4: 杭州匠泽电子商务有限公司 | O4: 杭州宜格化妆品有限公司 | P4: 北斗（龙军权） | Q4: 运营中 | R4: 启用
A5: DP002 | B5: 京东花西子旗舰店 | C5: 京东旗舰店 | D5: 京东花西子旗舰店 | E5: 线上2C | F5: 直销模式 | G5: RMB | H5: 7天 | I5: 京东 | J5: https://mall.jd.com/index-10177691.html?from=pc | K5: 花西子 | L5: 中国 | M5: 京东 | N5: 杭州匠泽电子商务有限公司 | O5: 杭州宜格化妆品有限公司 | P5: 花楹（陈冬莹） | Q5: 运营中 | R5: 启用
A6: DP004 | B6: 考拉花西子旗舰店 | C6: 考拉旗舰店 | D6: 考拉花西子官方旗舰店 | E6: 线上2C | F6: 直销模式 | G6: RMB | H6: 15天 | I6: 考拉 | J6: https://kmall.kaola.com/pc/1045137689?_fullscreen=true&cdnBaseUrl=http%3A%2F%2Fm.kaolacdn.com&isTestEnvironment=false | K6: 花西子 | L6: 中国 | M6: 自营其他 | N6: 杭州匠泽电子商务有限公司 | O6: 杭州宜格化妆品有限公司 | P6: 小新（李泽君） | Q6: 运营中 | R6: 启用
A7: DP007 | B7: 抖音花西子旗舰店 | C7: 抖音旗舰店 | D7: 抖音花西子官方旗舰店 | E7: 线上2C | F7: 直销模式 | G7: RMB | H7: 7天 | I7: 抖音 | J7: https://haohuo.jinritemai.com/views/shop/index?id=rHQPvZg&origin_type=604&origin_id=0&new_source_type=47&new_source_id=0&source_type=47&source_id=0 | K7: 花西子 | L7: 中国 | M7: 抖音 | N7: 杭州宜格化妆品有限公司 | O7: 杭州宜格化妆品有限公司 | P7: 安歆（吴战） | Q7: 运营中 | R7: 启用
A8: DP008 | B8: 小红书花西子品牌店 | C8: 小红书品牌店 | D8: 小红书花西子品牌店 | E8: 线上2C | F8: 直销模式 | G8: RMB | H8: 7天 | I8: 小红书 | J8: https://www.xiaohongshu.com/vendor/5ad803591c9e8635c95a8a9e?xhsshare=CopyLink&appuid=5a8fbdc311be10146f9d0482&apptime=1592471178 | K8: 花西子 | L8: 中国 | M8: 自营其他 | N8: 杭州宜格化妆品有限公司 | O8: 杭州宜格化妆品有限公司 | P8: 小新（李泽君） | Q8: 运营中 | R8: 启用
A9: WeChat01 | B9: 微信小程序花西子御花园 | C9: 花西子御花园 | D9: 花西子御花园 | E9: 线上2C | F9: 直销模式 | G9: RMB | H9: 7天 | I9: 微信 | J9: 无店铺链接 | K9: 花西子 | L9: 中国 | M9: 微信 | N9: 杭州宜格化妆品有限公司 | O9: 杭州宜格化妆品有限公司 | P9: 汐羽（吴晨珊） | Q9: 运营中 | R9: 启用
A10: DP015 | B10: 天猫花西子旗舰店 | C10: 天猫旗舰店 | D10: 天猫花西子旗舰店 | E10: 线上2C | F10: 直销模式 | G10: RMB | H10: 7天 | I10: 天猫 | J10: https://huaxizi.tmall.com/?spm=a220o.1000855.w5001-17160293638.2.56c92c566oD0Xm&scene=taobao_shop | K10: 花西子 | L10: 中国 | M10: 天猫 | N10: 杭州宜格化妆品有限公司 | O10: 杭州宜格化妆品有限公司 | P10: 苏木（宋晨） | Q10: 运营中 | R10: 启用
A11: DP011 | B11: 拼多多花西子专卖店 | C11: 拼多多专卖店 | D11: 拼多多花西子品牌专卖店 | E11: 线上2C | F11: 直销模式 | G11: RMB | H11: 7天 | I11: 拼多多 | J11: 无店铺链接 | K11: 花西子 | L11: 中国 | M11: 自营其他 | N11: 杭州匠泽电子商务有限公司 | O11: 杭州宜格化妆品有限公司 | P11: 小新（李泽君） | Q11: 运营中 | R11: 启用
A12: DP012 | B12: 天猫OGP旗舰店 | C12: 天猫旗舰店 | D12: OGP旗舰店 | E12: 线上2C | F12: 直销模式 | G12: RMB | H12: 7天 | I12: 天猫 | J12: https://ogphzp.tmall.com/ | K12: OGP | L12: 中国 | M12: 天猫 | N12: 杭州时光肌生物科技有限公司 | O12: 杭州时光肌生物科技有限公司 | P12: 千屿（赵丹丹） | Q12: 运营中 | R12: 启用
A13: DP013 | B13: 小红书OGP品牌店 | C13: 小红书品牌店 | D13: OGP时光肌旗舰店 | E13: 线上2C | F13: 直销模式 | G13: RMB | H13: 7天 | I13: 小红书 | J13: https://www.xiaohongshu.com/vendor/5e02dc43f488980001bca92e?contentId=121620&preview=true&naviHidden=yes | K13: OGP | L13: 中国 | M13: 自营其他 | N13: 杭州时光肌生物科技有限公司 | O13: 杭州时光肌生物科技有限公司 | P13: 梁月（程建波） | Q13: 运营中 | R13: 启用
A14: DP014 | B14: 抖音OGP旗舰店 | C14: 抖音旗舰店 | D14: OGP时光肌官方旗舰店 | E14: 线上2C | F14: 直销模式 | G14: RMB | H14: 7天 | I14: 抖音 | J14: https://fxg.jinritemai.com/ffa/chooseEntries | K14: OGP | L14: 中国 | M14: 抖音 | N14: 杭州时光肌生物科技有限公司 | O14: 杭州时光肌生物科技有限公司 | P14: 哈娜（王丽娜） | Q14: 运营中 | R14: 启用
A15: DP019 | B15: 凯德星店 | C15: 凯德星 | D15: 凯德星 | E15: 线上2C | F15: 直销模式 | G15: RMB | H15: 7天 | I15: 凯德星 | J15: 无店铺链接 | K15: 花西子 | L15: 中国 | M15: 自营其他 | N15: 杭州匠泽电子商务有限公司 | O15: 杭州宜格化妆品有限公司 | P15: 小新（李泽君） | Q15: 运营中 | R15: 启用
... A60: HWDP019 | B60: Tiktok花西子新加坡店 | C60: Tiktok新加坡店 | D60: tiktok_SG | E60: 线上2C | F60: 直销模式 | G60: SGD | H60: 7天 | I60: Tiktok | J60: 无店铺链接 | K60: 花西子 | L60: 新加坡 | M60: 海外 | N60: 杭州宜格化妆品有限公司 | O60: 杭州宜格化妆品有限公司 | P60: 乐事（王明钰） | Q60: 运营中 | R60: 启用
A61: DP024 | B61: 浙帮虚拟店铺 | C61: 浙帮虚拟店铺 | D61: 浙帮虚拟店铺 | E61: 虚拟客户 | F61: 其他 | G61: RMB | H61: 无 | I61: 虚拟 | J61: 无店铺链接 | K61: 花西子 | L61: 中国 | M61: 虚拟 | Q61: 运营中 | R61: 启用
A62: DP041 | B62: 宜格虚拟店铺 | C62: 宜格虚拟店铺 | D62: 宜格虚拟店铺 | E62: 虚拟客户 | F62: 其他 | G62: RMB | H62: 无 | I62: 虚拟 | J62: 无店铺链接 | K62: 花西子 | L62: 中国 | M62: 虚拟 | Q62: 运营中 | R62: 启用
A63: DP042 | B63: 匠泽虚拟店铺 | C63: 匠泽虚拟店铺 | D63: 匠泽虚拟店铺 | E63: 虚拟客户 | F63: 其他 | G63: RMB | H63: 无 | I63: 虚拟 | J63: 无店铺链接 | K63: 花西子 | L63: 中国 | M63: 虚拟 | Q63: 运营中 | R63: 启用
A64: DP043 | B64: 时光肌虚拟店铺 | C64: 时光肌虚拟店铺 | D64: 时光肌虚拟店铺 | E64: 虚拟客户 | F64: 其他 | G64: RMB | H64: 无 | I64: 虚拟 | J64: 无店铺链接 | K64: OGP | L64: 中国 | M64: 虚拟 | Q64: 运营中 | R64: 启用
A65: DP044 | B65: 匠客虚拟店铺 | C65: 匠客虚拟店铺 | D65: 匠客虚拟店铺 | E65: 虚拟客户 | F65: 其他 | G65: RMB | H65: 无 | I65: 虚拟 | J65: 无店铺链接 | K65: 花西子 | L65: 中国 | M65: 虚拟 | Q65: 运营中 | R65: 启用
A66: DP065 | B66: 宜格宜美虚拟店铺 | C66: 宜格宜美虚拟店铺 | D66: 宜格宜美虚拟店铺 | E66: 虚拟客户 | F66: 其他 | G66: RMB | H66: 无 | I66: 虚拟 | J66: 无店铺链接 | K66: 花西子 | L66: 中国 | M66: 虚拟 | Q66: 运营中 | R66: 启用
A67: DP067 | B67: 时光机智能虚拟店铺 | C67: 时光机智能虚拟店铺 | D67: 时光机智能虚拟店铺 | E67: 虚拟客户 | F67: 其他 | G67: RMB | H67: 无 | I67: 虚拟 | J67: 无店铺链接 | K67: OGP | L67: 中国 | M67: 虚拟 | Q67: 运营中 | R67: 启用
A68: DP070 | B68: 微信视频号花西子旗舰店 | C68: 微信视频号旗舰店 | D68: 花西子旗舰店 | E68: 线上2C | F68: 直销模式 | G68: RMB | H68: 7天 | I68: 微信 | J68: 无店铺链接 | K68: 花西子 | L68: 中国 | M68: 微信 | N68: 杭州花凝香生物科技有限公司 | O68: 杭州宜格化妆品有限公司 | P68: 煜橙（刘橙昱） | Q68: 运营中 | R68: 启用
A69: DP071 | B69: 拼多多花西子美妆旗舰店 | C69: 拼多多旗舰店 | D69: 拼多多花西子美妆旗舰店 | E69: 线上2C | F69: 直销模式 | G69: RMB | H69: 7天 | I69: 拼多多 | J69: http://mobile.yangkeduo.com/mall_page.html?mall_id=946072587 | K69: 花西子 | L69: 中国 | M69: 自营其他 | N69: 杭州匠泽电子商务有限公司 | O69: 杭州宜格化妆品有限公司 | P69: 小新（李泽君） | Q69: 运营中 | R69: 启用
A70: DP072 | B70: 特渠睦业和 | C70: 特渠001 | D70: 特渠睦业和 | E70: 线下2B | F70: 一件代发模式 | G70: RMB | H70: 不支持退货 | I70: 特渠 | J70: 无店铺链接 | K70: 花西子 | L70: 中国 | M70: 线下 | N70: 杭州宜格化妆品有限公司 | O70: 杭州宜格化妆品有限公司 | P70: 桩主（陈亮亮） | Q70: 运营中 | R70: 启用
A71: DP073 | B71: 特渠-直客 | C71: 特渠002 | D71: 特渠-直客 | E71: 线下2B | F71: 一件代发模式 | G71: RMB | H71: 不支持退货 | I71: 特渠 | J71: 无店铺链接 | K71: 花西子 | L71: 中国 | M71: 线下 | N71: 杭州宜格化妆品有限公司 | O71: 杭州宜格化妆品有限公司 | P71: 桩主（陈亮亮） | Q71: 运营中 | R71: 启用
A72: DP074 | B72: 拼多多OGP时光肌旗舰店 | C72: 拼多多旗舰店 | D72: OGP时光肌旗舰店 | E72: 线上2C | F72: 直销模式 | G72: RMB | H72: 7天 | I72: 拼多多 | J72: https://mobile.yangkeduo.com/mall_page.html?_x_org=2&refer_share_uin=&refer_share_id=1O7qrdBrxbfibUeT5dSlFIMei0QCeKHH&_x_query=ogp%E8%93%9D%E9%93%9C%E8%83%9C%E8%82%BD%E9%9D%A2%E9%9C%9C&msn=r74qsmbizsfsfnnca7csikqd6a_axbuy&refer_share_channel=copy_link&_wv=41729&mall_id=478070408&_wvx=10 | K72: OGP | L72: 中国 | M72: 自营其他 | N72: 杭州匠客电子商务有限公司 | O72: 杭州时光肌生物科技有限公司 | P72: 还未（张灵军） | Q72: 运营中 | R72: 启用
A73: DP075 | B73: 京东OGP自营旗舰店 | C73: 京东自营店 | D73: OGP京东自营旗舰店 | E73: 线上2B | F73: 经销模式 | G73: RMB | H73: 7天 | I73: 京东 | J73: https://mall.jd.com/index-1000455903.html?from=pc | K73: OGP | L73: 中国 | M73: 京东 | N73: 杭州匠客电子商务有限公司 | O73: 杭州时光肌生物科技有限公司 | P73: 还未（张灵军） | Q73: 运营中 | R73: 启用
A74: DP076 | B74: 特渠馨羽 | C74: 特渠003 | D74: 特渠馨羽 | E74: 线下2B | F74: 一件代发模式 | G74: RMB | H74: 不支持退货 | I74: 特渠 | J74: 无店铺链接 | K74: 花西子 | L74: 中国 | M74: 线下 | N74: 杭州宜格化妆品有限公司 | O74: 杭州宜格化妆品有限公司 | P74: 桩主（陈亮亮） | Q74: 运营中 | R74: 启用
A75: DP077 | B75: 特渠兰城兴 | C75: 特渠004 | D75: 特渠兰城兴 | E75: 线下2B | F75: 一件代发模式 | G75: RMB | H75: 不支持退货 | I75: 特渠 | J75: 无店铺链接 | K75: 花西子 | L75: 中国 | M75: 线下 | N75: 杭州宜格化妆品有限公司 | O75: 杭州宜格化妆品有限公司 | P75: 桩主（陈亮亮） | Q75: 运营中 | R75: 启用
A76: DP078 | B76: 特渠云中鹤 | C76: 特渠005 | D76: 特渠云中鹤 | E76: 线下2B | F76: 一件代发模式 | G76: RMB | H76: 不支持退货 | I76: 特渠 | J76: 无店铺链接 | K76: 花西子 | L76: 中国 | M76: 线下 | N76: 杭州宜格化妆品有限公司 | O76: 杭州宜格化妆品有限公司 | P76: 桩主（陈亮亮） | Q76: 运营中 | R76: 启用
A77: DP079 | B77: 特渠金文 | C77: 特渠006 | D77: 特渠金文 | E77: 线下2B | F77: 一件代发模式 | G77: RMB | H77: 不支持退货 | I77: 特渠 | J77: 无店铺链接 | K77: 花西子 | L77: 中国 | M77: 线下 | N77: 杭州宜格化妆品有限公司 | O77: 杭州宜格化妆品有限公司 | P77: 桩主（陈亮亮） | Q77: 运营中 | R77: 启用
A78: DP080 | B78: 快手花西子宜格企业店 | C78: 快手人设号 | D78: 花西子宜格企业店 | E78: 线上2C | F78: 直销模式 | G78: RMB | H78: 7天 | I78: 快手 | J78: https://app.kwaixiaodian.com/page/kwaishop-c-shoplist?id=1168586727 | K78: 花西子 | L78: 中国 | M78: 快手 | N78: 杭州宜格化妆品有限公司 | O78: 杭州宜格化妆品有限公司 | P78: 青诚（吴雪诚） | Q78: 运营中 | R78: 启用
A79: HWDP020 | B79: Tiktok花西子旗舰店 | C79: Tiktok旗舰店 | D79: Tiktok Shop | E79: 线上2C | F79: 直销模式 | G79: 无币种 | H79: 7天 | I79: Tiktok | J79: 无店铺链接 | K79: 花西子 | L79: 海外 | M79: 海外 | N79: 宜格（香港）国际有限公司 | O79: 杭州宜格化妆品有限公司 | P79: 咻咻（吴休同） | Q79: 运营中 | R79: 启用
... A85: DP086 | B85: 特渠美朵拉 | C85: 特渠009 | D85: 特渠美朵拉 | E85: 线下2B | F85: 一件代发模式 | G85: RMB | H85: 不支持退货 | I85: 特渠 | J85: 无店铺链接 | K85: 花西子 | L85: 中国 | M85: 线下 | N85: 杭州宜格化妆品有限公司 | O85: 杭州宜格化妆品有限公司 | P85: 桩主（陈亮亮） | Q85: 运营中 | R85: 启用
