Workbook

Sheet 平台账单取数整体计划
A1: 营销活动 | B1: 取数平台 | C1: 数据源 | D1: 账号数量 | E1: 优先级 | F1: 进度 | G1: RPA责任人 | H1: 责任人 | I1: 开始日期 | J1: 完成日期 | K1: 表描述 | L1: 标准账单逻辑整理完成时间 | M1: 进度 | N1: 计划结束
A2: 巨量千川 | B2: 抖音 | C2: 巨量千川-财务-财务流水 | D2: 12 | E2: P0 | F2: 已完成 | G2: 鲸歌 | I2: 45061 | J2: 45062 | K2: 抖音-直播自投 抖音-其他 | L2: 45063 | M2: 已完成
A3: 小红书加热 | B3: 小红书 | C3: 小红书聚光-报表-广告计划 | D3: 7 | E3: P1 | F3: 已完成 | G3: 鲸歌 | I3: 45062 | J3: 45063 | K3: 小红书-业务计划 | L3: 45064 | M3: 已完成
A4: 小红书加热 | B4: 小红书 | C4: 小红书聚光-财务-资金钱包 | D4: 7 | E4: P1 | F4: 已完成 | G4: 鲸歌 | I4: 45062 | J4: 45063 | K4: 小红书-省广美妆-资金流水 小红书-拾光宝盒-资金流水 | L4: 45064 | M4: 已完成
A5: 直通车 | B5: 天猫 | C5: 直通车-报表-汇总数据获取（计划报表） | E5: P0 | F5: 已完成 | G5: 林木 | I5: 45064 | J5: 45064 | K5: 天猫-直通车-业务计划 | L5: 45065 | M5: 已完成
A6: 直通车 | B6: 天猫 | C6: 阿里妈妈-账户-账户明细 | E6: P0 | F6: 已完成 | G6: 林木 | I6: 45064 | J6: 45064 | K6: 天猫-直通车-资金流水 | L6: 45065 | M6: 已完成
A7: 引力魔方 | B7: 天猫 | C7: 阿里妈妈-引力魔方-账户-账户明细 | E7: P0 | F7: 已完成 | G7: 桃花 | I7: 45064 | J7: 45064 | K7: 天猫-引力魔方-资金流水 | L7: 45065 | M7: 已完成
A8: 引力魔方 | B8: 天猫 | C8: 阿里妈妈-引力魔方-报表-自定义报表 | E8: P0 | F8: 已完成 | G8: 桃花 | I8: 45064 | J8: 45064 | K8: 天猫-引力魔方-业务计划 | L8: 45065 | M8: 已完成
A9: 万相台 | B9: 天猫 | C9: 万相台-报表-超级短视频 | E9: P0 | F9: 已完成 | G9: 桃花 | I9: 45065 | J9: 45065 | K9: 天猫-万相台-短视频-业务计划 | L9: 45066 | M9: 已完成
A10: 万相台 | B10: 天猫 | C10: 万相台-报表-超级直播 | E10: P0 | F10: 已完成 | G10: 桃花 | I10: 45065 | J10: 45065 | K10: 天猫-万相台-超级直播-业务计划 | L10: 45066 | M10: 已完成
A11: 京准通 | B11: 京东 | C11: 京准通-账户中心-财务记录-消费记录 | E11: P1 | F11: 已完成 | G11: 鲸歌 | I11: 45064 | J11: 45065 | L11: 45066 | M11: 已完成
A12: 互动广告(原京东展位) | B12: 京东 | C12: 京东展位-账户报表-推广计划报表 | E12: P1 | F12: 已完成 | G12: 鲸歌 | I12: 45064 | J12: 45065 | L12: 45066 | M12: 已完成
A13: 互动广告(原京东展位) | B13: 京东 | C13: 京东展位-效果报表-订单效果总览 | E13: P1 | F13: 已完成 | G13: 鲸歌 | I13: 45064 | J13: 45065 | L13: 45066 | M13: 已完成
A14: 热浪引擎 | B14: 天猫 | C14: 热浪引擎-个人中心-资金账户 | E14: P0 | F14: 已完成 | G14: 林木 | I14: 45065 | J14: 45068 | K14: 天猫-热浪引擎 | L14: 45067 | M14: 进行中
A15: 万相台 | B15: 天猫 | C15: 阿里妈妈万相台-账户-账户明细 | E15: P0 | F15: 已完成 | G15: 桃花 | I15: 45065 | J15: 45068 | K15: 天猫-万相台-资金流水 | L15: 45067 | M15: 进行中
A16: UD信息流 | B16: 天猫 | C16: 阿里妈妈-客户报表 | E16: P0 | F16: 已完成 | G16: 林木 | I16: 45076 | J16: 48365 | K16: 天猫-UD信息流-业务计划 | L16: 45069
A17: 淘宝客 | B17: 天猫 | C17: 淘宝联盟-数据分析-CPS订单明细-维权退款订单明细 | E17: P0 | F17: 已完成 | G17: 桃花 | I17: 45069 | J17: 45070 | K17: 天猫-淘宝客-维权逆向 | L17: 45070
A18: UD信息流 | B18: 天猫 | C18: 阿里妈妈-投放账户管理-投放账户日流水 | E18: P0 | F18: 已完成 | G18: 林木 | I18: 48366 | J18: 48367 | K18: 天猫-UD信息流-资金流水 | L18: 45071
A19: 站外广告(原京东直投) | B19: 京东 | C19: 京东直投-账户报表-推广计划 | E19: P1 | F19: 已完成 | G19: 鲸歌 | I19: 45068 | J19: 45070 | L19: 45071
A20: 站外广告(原京东直投) | B20: 京东 | C20: 京东直投-效果报表-订单效果总览 | E20: P1 | F20: 已完成 | G20: 鲸歌 | I20: 45068 | J20: 45070 | L20: 45071
A21: 快车(原京东快车) | B21: 京东 | C21: 京东快车-账户报表-推广计划 | E21: P1 | F21: 已完成 | G21: 鲸歌 | I21: 45068 | J21: 45070 | L21: 45071
A22: 快车(原京东快车) | B22: 京东 | C22: 京东快车-效果报表-订单效果总览 | E22: P1 | F22: 已完成 | G22: 鲸歌 | I22: 45068 | J22: 45070 | L22: 45071
A23: 推荐广告(原京东购物触点) | B23: 京东 | C23: 京东购物触点-账户报表-推广计划报表 | E23: P1 | F23: 已完成 | G23: 鲸歌 | I23: 45068 | J23: 45070 | L23: 45071
A24: 推荐广告(原京东购物触点) | B24: 京东 | C24: 京东购物触点-效果报表-订单效果总揽 | E24: P1 | F24: 已完成 | G24: 鲸歌 | I24: 45068 | J24: 45070 | L24: 45071
A25: 淘宝客 | B25: 天猫 | C25: 淘宝联盟-数据分析-CPS订单明细-成交订单明细 | E25: P0 | F25: 已完成 | G25: 桃花 | I25: 45069 | J25: 45070 | K25: 天猫-淘宝客 | L25: 45073
A26: 磁力引擎 | B26: 快手 | C26: 磁力智投-广告计划报表 | E26: P1 | F26: 已完成 | G26: 桃花 | I26: 45072 | J26: 45075 | L26: 45073
A27: B站起飞加热 | B27: B站 | C27: 三连推广-推广-计划 | E27: P1 | F27: 已完成 | G27: 鲸歌 | I27: 45071 | J27: 45072 | K27: B站-业务计划 | L27: 45073
A28: B站起飞加热 | B28: B站 | C28: 三连推广-财务-交易明细 | E28: P1 | F28: 已完成 | G28: 鲸歌 | I28: 45071 | J28: 45072 | K28: B站-资金流水 | L28: 45073
A29: Target-Max | B29: 唯品会 | C29: 唯品会营销平台-Target-Max-推广计划 | E29: P1 | F29: 已完成 | G29: 鲸歌 | I29: 45075 | J29: 45076 | L29: 45077
A30: 唯智展 | B30: 唯品会 | C30: 唯品会营销平台-唯智展-推广计划 | E30: P1 | F30: 已完成 | G30: 鲸歌 | I30: 45075 | J30: 45076 | L30: 45077
A31: 唯触点 | B31: 唯品会 | C31: 唯品会营销平台-唯触点-广告 | E31: P1 | F31: 已完成 | G31: 鲸歌 | I31: 45075 | J31: 45076 | L31: 45077
A32: 唯直达 | B32: 唯品会 | C32: 唯品会营销平台-唯直达-推广计划 | E32: P1 | F32: 已完成 | G32: 鲸歌 | I32: 45075 | J32: 45076 | L32: 45077
A33: 磁力引擎 | B33: 快手 | C33: 磁力智投-财务-账户流水 | E33: P1 | F33: 已完成 | G33: 桃花 | I33: 45070 | J33: 45071 | L33: 45077
A34: 移动精选 | B34: 唯品会 | C34: 唯品会营销平台-移动精选-推广计划 | E34: P1 | F34: 已完成 | G34: 鲸歌 | I34: 45077 | J34: 45078 | L34: 45079
A35: 腾讯广告 | B35: 唯品会 | C35: 唯品会营销平台-腾讯广告-推广计划 | E35: P1 | F35: 已完成 | G35: 鲸歌 | I35: 45077 | J35: 45078 | L35: 45079
A36: 巨量引擎 | B36: 唯品会 | C36: 唯品会营销平台-巨量引擎-推广计划 | E36: P1 | F36: 已完成 | G36: 鲸歌 | I36: 45077 | J36: 45078 | L36: 45079
A37: 达人卖货 | B37: 唯品会 | C37: 唯品会营销平台-达人卖货-订单明细 | E37: P1 | F37: 已完成 | G37: 鲸歌 | I37: 45077 | J37: 45078 | L37: 45079
A38: 营销平台-财务 | B38: 唯品会 | C38: 唯品会营销平台-财务记录 | E38: P1 | F38: 已完成 | G38: 鲸歌 | I38: 45077 | J38: 45078 | L38: 45079
A39: dou+ | B39: 抖音 | C39: dou+-我的订单 | D39: 3 | E39: P0 | F39: 已完成 | G39: 林木 | I39: 45082 | J39: 45083 | L39: 48367
A40: 矩阵号DOU+ | B40: 抖音 | C40: dou+-我的订单 | D40: 3 | E40: P0 | F40: 未开始 | G40: 林木 | L40: 48367
...

Sheet 取数路径
A1: 营销活动 | B1: 取数平台 | C1: 账单名称 | D1: 取数路径 | E1: 下载至本地报表数量 (单个账号) | F1: 账号 | G1: 密码 | H1: 取数频率 | I1: 手工用时 | J1: 取数步骤1 | K1: 取数步骤2 | L1: 取数步骤3 | M1: 取数链接
A2: ='平台账单取数整体计划'!A2 | B2: ='平台账单取数整体计划'!B2 | C2: 成交订单明细 | D2: ='平台账单取数整体计划'!C2 | F2: 花西子旗舰店:RPA/ 花西子匠泽专卖店:RPA | G2: Huaxizi123 | M2: https://ad.alimama.com/index.htm?spm=a21dvs.24668363.0.0.274768f8GHY1tC
A3: ='平台账单取数整体计划'!A3 | B3: ='平台账单取数整体计划'!B3 | C3: 维权退款订单明细 | D3: ='平台账单取数整体计划'!C3 | M3: https://ad.alimama.com/index.htm?spm=a21dvs.24668363.0.0.274768f8GHY1tC
A4: ='平台账单取数整体计划'!A4 | B4: ='平台账单取数整体计划'!B4 | C4: 资金账户 | D4: ='平台账单取数整体计划'!C4 | M4: https://hot.taobao.com/
A5: ='平台账单取数整体计划'!A5 | B5: ='平台账单取数整体计划'!B5 | C5: 计划报表 | D5: ='平台账单取数整体计划'!C5 | M5: https://subway.simba.taobao.com/?spm=a21dvs.24266564.c25cac020_manage_subway.d3070433f_custom_subway.71d62cdeFpXAP9&source=qnRecommend/index.jsp
A6: ='平台账单取数整体计划'!A6 | B6: ='平台账单取数整体计划'!B6 | C6: 账户明细 | D6: ='平台账单取数整体计划'!C6 | M6: https://subway.simba.taobao.com/?spm=a21dvs.24266564.c25cac020_manage_subway.d3070433f_custom_subway.71d62cdeFpXAP9&source=qnRecommend/index.jsp
A7: ='平台账单取数整体计划'!A11 | B7: ='平台账单取数整体计划'!B11 | C7: 账户明细 | D7: ='平台账单取数整体计划'!C11 | M7: https://tuijian.taobao.com/index.html?spm=a21an.14209965.0.0.1a2c61dbo7rF5x
A8: ='平台账单取数整体计划'!A12 | B8: ='平台账单取数整体计划'!B12 | C8: 自定义报表 | D8: ='平台账单取数整体计划'!C12 | M8: https://tuijian.taobao.com/index.html?spm=a21an.14209965.0.0.1a2c61dbo7rF5x
A9: ='平台账单取数整体计划'!A13 | B9: ='平台账单取数整体计划'!B13 | C9: 报表-超级短视频 | D9: ='平台账单取数整体计划'!C13 | M9: https://adbrain.taobao.com/index.html?spm=a21an.14209965.0.0.678161dbmRBTYH
A10: ='平台账单取数整体计划'!A14 | B10: ='平台账单取数整体计划'!B14 | C10: 报表-超级直播 | D10: ='平台账单取数整体计划'!C14 | M10: https://adbrain.taobao.com/index.html?spm=a21an.14209965.0.0.678161dbmRBTYH
A11: ='平台账单取数整体计划'!A15 | B11: ='平台账单取数整体计划'!B15 | C11: 账户明细 | D11: ='平台账单取数整体计划'!C15 | M11: https://adbrain.taobao.com/index.html?spm=a21an.14209965.0.0.678161dbmRBTYH
A12: ='平台账单取数整体计划'!A7 | B12: ='平台账单取数整体计划'!B7 | C12: 客户报表 | D12: ='平台账单取数整体计划'!C7 | F12: 13456741727 | G12: HXZ8888 | M12: https://unidesk.taobao.com/login.html?spm=a21an.14209965.0.0.678161dbmRBTYH#!/index/index
A13: ='平台账单取数整体计划'!A8 | B13: ='平台账单取数整体计划'!B8 | C13: 投放账户日流水 | D13: ='平台账单取数整体计划'!C8 | M13: https://unidesk.taobao.com/login.html?spm=a21an.14209965.0.0.678161dbmRBTYH#!/index/index
A14: ='平台账单取数整体计划'!A16 | B14: ='平台账单取数整体计划'!B16 | C14: 推商品推广数据 | D14: ='平台账单取数整体计划'!C16 | F14: \
A15: ='平台账单取数整体计划'!A17 | B15: ='平台账单取数整体计划'!B17 | C15: 推直播间推广数据 | D15: ='平台账单取数整体计划'!C17
A16: ='平台账单取数整体计划'!A18 | B16: ='平台账单取数整体计划'!B18 | C16: 财务流水 | D16: ='平台账单取数整体计划'!C18
A17: ='平台账单取数整体计划'!A9 | B17: ='平台账单取数整体计划'!B9 | C17: 计划报表 | D17: ='平台账单取数整体计划'!C9 | F17: \ | M17: https://business.oceanengine.com/site/index
A18: ='平台账单取数整体计划'!A10 | B18: ='平台账单取数整体计划'!B10 | C18: 收支流水日汇总 | D18: ='平台账单取数整体计划'!C10 | M18: https://business.oceanengine.com/site/index
A19: ='平台账单取数整体计划'!A19 | B19: ='平台账单取数整体计划'!B19 | C19: 计划 | D19: ='平台账单取数整体计划'!C19
A20: ='平台账单取数整体计划'!A20 | B20: ='平台账单取数整体计划'!B20 | C20: 计划 | D20: ='平台账单取数整体计划'!C20
A21: ='平台账单取数整体计划'!A21 | B21: ='平台账单取数整体计划'!B21 | C21: 计划 | D21: ='平台账单取数整体计划'!C21
A22: ='平台账单取数整体计划'!A22 | B22: ='平台账单取数整体计划'!B22 | C22: 联盟订单明细 | D22: ='平台账单取数整体计划'!C22
A23: ='平台账单取数整体计划'!A23 | B23: ='平台账单取数整体计划'!B23 | C23: 报告详情 | D23: ='平台账单取数整体计划'!C23
A24: ='平台账单取数整体计划'!A24 | B24: ='平台账单取数整体计划'!B24 | C24: 消费记录 | D24: ='平台账单取数整体计划'!C24 | F24: pop-RPA 自营-RPA | G24: \ | M24: https://jzt.jd.com/home/#/index
A25: ='平台账单取数整体计划'!A25 | B25: ='平台账单取数整体计划'!B25 | C25: 推广计划报表 | D25: ='平台账单取数整体计划'!C25
A26: ='平台账单取数整体计划'!A26 | B26: ='平台账单取数整体计划'!B26 | C26: 订单效果总览 | D26: ='平台账单取数整体计划'!C26
A27: ='平台账单取数整体计划'!A27 | B27: ='平台账单取数整体计划'!B27 | C27: 推广计划报表 | D27: ='平台账单取数整体计划'!C27
A28: ='平台账单取数整体计划'!A28 | B28: ='平台账单取数整体计划'!B28 | C28: 订单效果总览 | D28: ='平台账单取数整体计划'!C28
A29: ='平台账单取数整体计划'!A29 | B29: ='平台账单取数整体计划'!B29 | C29: 推广计划报表 | D29: ='平台账单取数整体计划'!C29
A30: ='平台账单取数整体计划'!A30 | B30: ='平台账单取数整体计划'!B30 | C30: 订单效果总览 | D30: ='平台账单取数整体计划'!C30
A31: ='平台账单取数整体计划'!A31 | B31: ='平台账单取数整体计划'!B31 | C31: 推广计划报表 | D31: ='平台账单取数整体计划'!C31
A32: ='平台账单取数整体计划'!A32 | B32: ='平台账单取数整体计划'!B32 | C32: 订单效果总览 | D32: ='平台账单取数整体计划'!C32
A33: ='平台账单取数整体计划'!A33 | B33: ='平台账单取数整体计划'!B33 | C33: 推广计划 | D33: ='平台账单取数整体计划'!C33 | F33: 18072932996 | G33: \
A34: ='平台账单取数整体计划'!A34 | B34: ='平台账单取数整体计划'!B34 | C34: 推广计划 | D34: ='平台账单取数整体计划'!C34
A35: ='平台账单取数整体计划'!A35 | B35: ='平台账单取数整体计划'!B35 | C35: 广告 | D35: ='平台账单取数整体计划'!C35
A36: ='平台账单取数整体计划'!A36 | B36: ='平台账单取数整体计划'!B36 | C36: 推广计划 | D36: ='平台账单取数整体计划'!C36
A37: ='平台账单取数整体计划'!A37 | B37: ='平台账单取数整体计划'!B37 | C37: 推广计划 | D37: ='平台账单取数整体计划'!C37
A38: ='平台账单取数整体计划'!A38 | B38: ='平台账单取数整体计划'!B38 | C38: 推广计划 | D38: ='平台账单取数整体计划'!C38
A39: ='平台账单取数整体计划'!A39 | B39: ='平台账单取数整体计划'!B39 | C39: 推广计划 | D39: ='平台账单取数整体计划'!C39
A40: ='平台账单取数整体计划'!A40 | B40: ='平台账单取数整体计划'!B40 | C40: 订单明细 | D40: ='平台账单取数整体计划'!C40
...

Sheet 投放账号清单
A1: 核算规范-营销活动 | B1: 营销活动 | C1: 取数平台 | D1: 账单名称 | E1: 账号ID | F1: 账号名称
A2: 淘宝客 | B2: 淘宝客 | C2: 天猫 | D2: 成交订单明细
A3: 淘宝客 | B3: 淘宝客 | C3: 天猫 | D3: 维权退款订单明细
B4: 热浪引擎 | C4: 天猫 | D4: 资金账户
A5: 天猫-直通车 | B5: 直通车 | C5: 天猫 | D5: 计划报表
A6: 天猫-直通车 | B6: 直通车 | C6: 天猫 | D6: 账户明细
A7: UD信息流 | B7: UD信息流 | C7: 天猫 | D7: 客户报表
A8: UD信息流 | B8: UD信息流 | C8: 天猫 | D8: 投放账户日流水
A9: AD信息流 | B9: AD信息流 | C9: 抖音 | D9: 计划报表
A10: AD信息流 | B10: AD信息流 | C10: 抖音 | D10: 收支流水日汇总
A11: 天猫-引力魔方 | B11: 引力魔方 | C11: 天猫 | D11: 账户明细
A12: 天猫-引力魔方 | B12: 引力魔方 | C12: 天猫 | D12: 自定义报表
A13: 天猫-万相台-超级短视频 | B13: 万相台 | C13: 天猫 | D13: 报表-超级短视频
A14: 天猫-万相台-超级直播 | B14: 万相台 | C14: 天猫 | D14: 报表-超级直播
B15: 万相台 | C15: 天猫 | D15: 账户明细
B16: 生意参谋-直播间 | C16: 天猫 | D16: 直播间业绩
A17: 天猫-品牌专区 | B17: 品牌专区？ | C17: 天猫
A18: 天猫-明星店铺 | B18: 明星店铺？ | C18: 天猫
A19: 千川信息流？矩阵号千川信息流？ | B19: 巨量千川 | C19: 抖音 | D19: 计划
B20: 巨量千川 | C20: 抖音 | D20: 计划
B21: 巨量千川 | C21: 抖音 | D21: 财务流水
A22: Dou+？矩阵号dou+？抖音官号dou+？ | B22: dou+ | C22: 抖音 | D22: 我的订单
B23: 精选联盟 | C23: 抖音 | D23: 联盟订单明细
B24: 巨量星图 | C24: 抖音 | D24: 报告详情
B25: 京准通 | C25: 京东到家 | D25: 消费记录
B26: 京东展位 | C26: 京东 | D26: 推广计划报表
B27: 京东展位 | C27: 京东 | D27: 订单效果总览
B28: 京东直投 | C28: 京东 | D28: 推广计划报表
B29: 京东直投 | C29: 京东 | D29: 订单效果总览
B30: 京东快车 | C30: 京东 | D30: 推广计划报表
B31: 京东快车 | C31: 京东 | D31: 订单效果总览
B32: 京东购物触点 | C32: 京东 | D32: 推广计划报表
B33: 京东购物触点 | C33: 京东 | D33: 订单效果总览
B34: Target-Max | C34: 唯品会 | D34: 推广计划
A35: 唯品会-唯品常规投放 | B35: 唯智展 | C35: 唯品会 | D35: 推广计划
A36: 唯品会-唯品常规投放 | B36: 唯触点 | C36: 唯品会 | D36: 广告
A37: 唯品会-唯品常规投放 | B37: 唯直达 | C37: 唯品会 | D37: 推广计划
A38: 唯品会-唯品常规投放 | B38: 移动精选 | C38: 唯品会 | D38: 推广计划
A39: 唯品会-唯品常规投放 | B39: 腾讯广告 | C39: 唯品会 | D39: 推广计划
A40: 唯品会-唯品常规投放 | B40: 巨量引擎 | C40: 唯品会 | D40: 推广计划
...

Sheet 影刀整体排期
A1: 数据源 | B1: 计划开始 | C1: 计划结束 | D1: 开发人员 | E1: 多行文本 5 | F1: 多行文本 6 | G1: 群组 | H1: 日期 | I1: 附件
A2: 生意参谋-直播-直播间业绩 | B2: 暂定
A3: 阿里妈妈-直通车-报表-汇总数据获取（计划报表） | B3: 2023/5/18 | C3: 2023/5/18 | D3: 林木 | E3: √
A4: 阿里妈妈-直通车-账户-账户明细 | B4: 2023/5/18 | C4: 2023/5/18 | D4: 林木 | E4: √
A6: 阿里妈妈-UD-客户报表 | B6: 2023/5/19 | C6: 2023/5/22 | D6: 林木 | E6: 缺少账号，后延
A7: 阿里妈妈-UD-投放账户管理-投放账户日流水 | B7: 2023/5/23 | C7: 2023/5/24 | D7: 林木 | E7: 缺少账号，后延
A10: 阿里妈妈-引力魔方-账户-账户明细 | B10: 2023/5/18 | C10: 2023/5/18 | D10: 桃花 | E10: √
A11: 阿里妈妈-引力魔方-报表-自定义报表 | B11: 2023/5/18 | C11: 2023/5/18 | D11: 桃花 | E11: √
A13: 阿里妈妈-万相台-报表-超级短视频 | B13: 2023/5/19 | C13: 2023/5/19 | D13: 桃花 | E13: √
A14: 阿里妈妈-万相台-报表-超级直播 | B14: 2023/5/19 | C14: 2023/5/19 | D14: 桃花 | E14: √
A15: 阿里妈妈-万相台-账户-账户明细 | B15: 2023/5/19 | C15: 2023/5/22 | D15: 桃花 | E15: 进行中
A16: 热浪引擎-个人中心-资金账户 | B16: 2023/5/23 | C16: 2023/5/24 | D16: 桃花 | E16: 林木，进行中
A17: 淘宝联盟-数据分析-CPS订单明细-维权退款订单明细 | B17: 2023/5/25 | C17: 2023/5/26 | D17: 桃花
A18: 淘宝联盟-数据分析-CPS订单明细-成交订单明细 | B18: 2023/5/29 | C18: 2023/5/30 | D18: 桃花
B20: 2032/5/25 | C20: 2032/5/31 | D20: 进行天猫测试与调优
A22: dou+-我的订单 | B22: 2023/5/31 | C22: 2032/6/1 | D22: 桃花
A23: 精选联盟-数据参谋-联盟订单明细 | B23: 2032/6/2 | C23: 2032/6/5 | D23: 桃花
A24: 巨量星图-我的任务-报告详情 | B24: 2032/6/6 | C24: 2032/6/7 | D24: 桃花
A26: 磁力智投-广告计划报表 | B26: 2023/5/25 | C26: 2023/5/26 | D26: 林木
A27: 磁力智投-财务-账户流水 | B27: 2023/5/29 | C27: 2023/5/30 | D27: 林木
A28: 磁力金牛-数据-专业版报表-报表组 | B28: 2032/6/1 | C28: 2032/6/2 | D28: 林木
A29: 磁力金牛-财务-账户流水 | B29: 2032/6/5 | C29: 2032/6/6 | D29: 林木
B31: 2032/6/7 | C31: 2032/6/9 | D31: 进行抖音、快手测试与调优

Sheet 标准账单转换甘特图
A1: 任务名 | B1: 任务状态 | C1: 备注 | D1: 开始日期 | E1: 截止日期 | F1: 查找引用
A2: 巨量千川 | B2: 已完成 | D2: 45061 | E2: 45065 | F2: 营销活动PRA取数清单
A3: 小红书加热 | B3: 进行中 | D3: 45061 | E3: 45065
A4: 天猫直通车 | B4: 已完成 | D4: 45061 | E4: 45065
A5: 天猫引力魔方 | D5: 45061 | E5: 45065
A6: 天猫万相台 | D6: 45061 | E6: 45065
A7: 京东京准通 | D7: 45061 | E7: 45065
A8: 互动广告(原京东展位) | D8: 45061 | E8: 45065
A9: 热浪引擎 | D9: 45068 | E9: 45072
A10: 天猫UD信息流 | D10: 45068 | E10: 45072
A11: 淘宝客 | D11: 45068 | E11: 45072
A12: 京东站外广告(原京东直投) | D12: 45068 | E12: 45072
A13: 京东快车(原京东快车) | D13: 45068 | E13: 45072
A14: 京东推荐广告(原京东购物触点) | D14: 45061 | E14: 45065
A15: 快手磁力引擎 | D15: 45075 | E15: 45079
A16: B站起飞加热 | D16: 45075 | E16: 45079
... A29: 抖音精选联盟 | D29: 45082 | E29: 45086
A30: 巨量星图
A31: 考拉
A32: 拼多多
A33: 微博
A34: 小红书加热

Sheet KOL标准资金账单确认会排期
A1: 营销活动 | B1: 取数平台 | C1: 进度 | D1: 业务责任人 | E1: 开始日期 | F1: 完成日期 | G1: 业务确认会
A2: 巨量千川 | B2: 抖音 | C2: 进行中 | E2: 45061 | F2: 45062
A3: 小红书加热 | B3: 小红书 | C3: 已完成 | E3: 45062 | F3: 45063
A4: 小红书加热 | B4: 小红书 | C4: 已完成 | E4: 45062 | F4: 45063
A5: 直通车 | B5: 天猫 | C5: 已完成 | E5: 45064 | F5: 45065
A6: 直通车 | B6: 天猫 | C6: 已完成 | E6: 45064 | F6: 45065
A7: 引力魔方 | B7: 天猫 | C7: 已完成 | E7: 45064 | F7: 45065
A8: 引力魔方 | B8: 天猫 | C8: 已完成 | E8: 45064 | F8: 45065
A9: 万相台 | B9: 天猫 | C9: 已完成 | E9: 45064 | F9: 45065
A10: 万相台 | B10: 天猫 | C10: 已完成 | E10: 45064 | F10: 45065
A11: 万相台 | B11: 天猫 | C11: 已完成 | E11: 45064 | F11: 45065
A12: 京准通 | B12: 京东 | C12: 已完成 | E12: 45075 | F12: 45079
A13: 互动广告(原京东展位) | B13: 京东 | C13: 已完成 | E13: 45075 | F13: 45079
... A43: 巨量星图 | B43: 抖音 | C43: 未开始 | E43: 48371 | F43: 48372
A44: AD信息流 | B44: 抖音 | C44: 未开始
A45: AD信息流 | B45: 抖音 | C45: 未开始
A46: 巨量千川 | B46: 抖音 | C46: 进行中
A47: 巨量千川 | B47: 抖音 | C47: 进行中
A48: 磁力金牛 | B48: 快手 | C48: 未开始 | E48: 48366 | F48: 48367
A49: 磁力金牛 | B49: 快手 | C49: 未开始 | E49: 48370 | F49: 48371
A50: 考拉 | B50: 考拉 | C50: 未开始
A51: 考拉 | B51: 考拉 | C51: 未开始
A52: 拼多多 | B52: 拼多多 | C52: 未开始
A53: 拼多多 | B53: 拼多多 | C53: 未开始
A54: 拼多多 | B54: 拼多多 | C54: 未开始
A55: 拼多多 | B55: 拼多多 | C55: 未开始
A56: 拼多多 | B56: 拼多多 | C56: 未开始
A57: 拼多多 | B57: 拼多多 | C57: 未开始
A58: 百度 | B58: 百度 | C58: 未开始
A59: 粉丝通 | B59: 微博 | C59: 未开始
A60: 粉丝通 | B60: 微博 | C60: 未开始
A61: 内容热推 | B61: 小红书蒲公英 | C61: 未开始
A62: 生意参谋-直播间 | B62: 天猫 | C62: 未开始 | D62: 东方
