Workbook

Sheet 投放账户补充
A1: 投放账户ID | B1: 名称 | C1: 业务对接人 | D1: 站内/站外 | E1: 营销活动 | F1: 公司主体 | G1: 平台 | H1: 投放方式（自投/代投） | I1: 平台对合作应供应商名称 | J1: 是否存在充值赠送金 | K1: 是否存在返利 | L1: 是否通过此账户申请开票 | M1: 使用中心 | N1: 使用二级部门 | O1: 使用三级部门 | P1: 财务对接人（如有）
A2: 6336556296 | B2: 花西子Florasis | E2: 微博推广 | F2: 杭州宜格化妆品有限公司 | G2: 微博 | H2: 自投 | I2: 上海宇枫电子商务有限公司 | J2: 是 | K2: 否 | L2: 否
A3: 6965612965 | B3: 花西子美妆日记 | E3: 微博推广 | F3: 杭州宜格化妆品有限公司 | G3: 微博 | H3: 自投 | I3: 上海宇枫电子商务有限公司
A4: 55d34272f5a26377d1b784dd | B4: 花西子Florasis | D4: 站内 | E4: 小红书加热 | I4: 薯一薯二文化传媒（上海）有限公司

Sheet 投放账户（维度数据）
A1: 站内/站外 | B1: 营销活动 | C1: 公司主体 | D1: =+++++#REF! | E1: 投放平台 | F1: 投放方式 | G1: 平台对合作应供应商名称 | H1: 对应业务场景及用途 | I1: 登录网址 | J1: 账号 | K1: 编码 | M1: 是否按消耗开票 | N1: 是否为充值账户 | O1: 是否能取到充值/消耗明细 | P1: 是否存在充值赠送金 | Q1: 是否存在返利 | R1: 是否通过此账户申请开票 | S1: 使用中心 | T1: 使用二级部门 | U1: 使用三级部门 | V1: 使用四级部门 | W1: 业务对接人 | X1: 备注 | Y1: 财务对接人 | Z1: 账户权限owner | AA1: 登录方式
D2: 正常使用/闲置 | E2: 平台的称呼，如： 抖音-巨量千川 抖音-巨量纵横 快手 淘宝AD | F2: 自投/代投 | G2: 供应商全称 | N2: 是/否 | O2: 是/否 | P2: 是/否 | Q2: 是/否 | R2: 是/否 | S2: 一级中心 | Z2: 管理密码人员 | AA2: 验证码/账户密码
A3: 站内 | B3: 考拉-常规投放 | C3: 杭州匠泽电子商务有限公司 | D3: 正常使用 | E3: 考拉 | F3: 自投 | G3: 考拉海购（杭州）科技有限公司 | H3: 考拉 | I3: https://partner.kaola.com/index | J3: 18069829269 | K3: 18069829269 | N3: 否 | O3: 否 | P3: 否 | Q3: 否 | R3: 是 | S3: 品牌运营中心 | T3: 渠道运营部 | U3: 综合渠道运营部 | V3: 综合渠道推广部 | W3: =VLOOKUP(K3,'Sheet11'!$X$2:$AH$279,11,FALSE) | Y3: 贝果 | Z3: 徐庄南 | AA3: 账号密码
A4: 站外 | B4: AD信息流 | C4: 杭州宜格化妆品有限公司 | D4: 暂停投放 | E4: 抖音 | F4: 自投 | G4: 广东省广告集团股份有限公司 | H4: 得物抖音AD引流 | I4: https://business.oceanengine.com/site/promotion?#/account | J4: huaxizi_xinxliuad2@163.com | K4: huaxizi_xinxliuad2@163.com | N4: 否 | O4: 否 | P4: 是 | Q4: 是 | R4: 是 | S4: 品牌运营中心 | W4: =VLOOKUP(K4,'Sheet11'!$X$2:$AH$279,11,FALSE) | X4: 目前未投放 | Y4: 贝果 | Z4: 徐庄南 | AA4: 账号密码
A5: 站内 | B5: 小红书加热 | C5: 杭州宜格化妆品有限公司 | E5: 小红书(TFPT08) | F5: 自投 | G5: 江苏拾光宝盒信息技术有限公司(VEN01761) | J5: 拾光宝盒（花西子美妆） | K5: 117315 | P5: 是(YES) | Q5: 是(YES) | R5: 否 | S5: =VLOOKUP(B5,'Sheet9'!$B$2:$G$191,3,FALSE) | T5: =VLOOKUP(B5,'Sheet9'!$B$2:$G$191,4,FALSE) | U5: =VLOOKUP(B5,'Sheet9'!$B$2:$G$191,5,FALSE) | V5: 内容投放组 | W5: =VLOOKUP(K5,'Sheet11'!$X$2:$AH$279,11,FALSE) | Y5: 贝果 | Z5: 甘草、清和 | AA5: 账号密码
A6: 站内 | B6: 小红书加热 | C6: 杭州宜格化妆品有限公司 | E6: 小红书(TFPT08) | F6: 自投 | G6: 江苏拾光宝盒信息技术有限公司(VEN01761) | J6: 拾光宝盒（花西子Florasis4） | K6: 168640 | P6: 是(YES) | Q6: 是(YES) | R6: 否 | S6: =VLOOKUP(B6,'Sheet9'!$B$2:$G$191,3,FALSE) | T6: =VLOOKUP(B6,'Sheet9'!$B$2:$G$191,4,FALSE) | U6: =VLOOKUP(B6,'Sheet9'!$B$2:$G$191,5,FALSE) | V6: 内容投放组 | W6: =VLOOKUP(K6,'Sheet11'!$X$2:$AH$279,11,FALSE) | Y6: 贝果 | Z6: 甘草、清和 | AA6: 账号密码
A7: 站内 | B7: 小红书加热 | C7: 杭州宜格化妆品有限公司 | E7: 小红书(TFPT08) | F7: 自投 | G7: 广东省广告集团股份有限公司(VEN02800) | J7: 省广集团（花西子Florasis） | K7: 113409 | P7: 是(YES) | Q7: 是(YES) | R7: 否 | S7: =VLOOKUP(B7,'Sheet9'!$B$2:$G$191,3,FALSE) | T7: =VLOOKUP(B7,'Sheet9'!$B$2:$G$191,4,FALSE) | U7: =VLOOKUP(B7,'Sheet9'!$B$2:$G$191,5,FALSE) | V7: 内容投放组 | W7: =VLOOKUP(K7,'Sheet11'!$X$2:$AH$279,11,FALSE) | Y7: 贝果 | Z7: 甘草、清和 | AA7: 账号密码
A8: 站内 | B8: 小红书加热 | C8: 杭州宜格化妆品有限公司 | E8: 小红书(TFPT08) | F8: 自投 | G8: 广东省广告集团股份有限公司(VEN02800) | J8: 省广-美妆 | K8: huaxizi_xhongshu2@163.com | P8: 是(YES) | Q8: 是(YES) | R8: 否 | S8: =VLOOKUP(B8,'Sheet9'!$B$2:$G$191,3,FALSE) | T8: =VLOOKUP(B8,'Sheet9'!$B$2:$G$191,4,FALSE) | U8: =VLOOKUP(B8,'Sheet9'!$B$2:$G$191,5,FALSE) | V8: 内容投放组 | W8: =VLOOKUP(K8,'Sheet11'!$X$2:$AH$279,11,FALSE) | Y8: 贝果 | Z8: 甘草、清和 | AA8: 账号密码
A9: 站内 | B9: 小红书加热 | C9: 杭州宜格化妆品有限公司 | E9: 小红书(TFPT08) | F9: 自投 | G9: 广东省广告集团股份有限公司(VEN02800) | J9: 省广集团（花西子Florasis）02 | K9: 117993 | P9: 是(YES) | Q9: 是(YES) | R9: 否 | S9: =VLOOKUP(B9,'Sheet9'!$B$2:$G$191,3,FALSE) | T9: =VLOOKUP(B9,'Sheet9'!$B$2:$G$191,4,FALSE) | U9: =VLOOKUP(B9,'Sheet9'!$B$2:$G$191,5,FALSE) | V9: 内容投放组 | W9: =VLOOKUP(K9,'Sheet11'!$X$2:$AH$279,11,FALSE) | Y9: 贝果 | Z9: 甘草、清和 | AA9: 账号密码
A10: 站内 | B10: 小红书加热 | C10: 杭州宜格化妆品有限公司 | E10: 小红书(TFPT08) | F10: 自投 | G10: 广东省广告集团股份有限公司(VEN02800) | J10: 省广集团（花西子Florasis）03 | K10: 117992 | P10: 是(YES) | Q10: 是(YES) | R10: 否 | S10: =VLOOKUP(B10,'Sheet9'!$B$2:$G$191,3,FALSE) | T10: =VLOOKUP(B10,'Sheet9'!$B$2:$G$191,4,FALSE) | U10: =VLOOKUP(B10,'Sheet9'!$B$2:$G$191,5,FALSE) | V10: 内容投放组 | W10: =VLOOKUP(K10,'Sheet11'!$X$2:$AH$279,11,FALSE) | Y10: 贝果 | Z10: 甘草、清和 | AA10: 账号密码
A11: 站外 | B11: 小红书加热 | C11: 杭州宜格化妆品有限公司 | E11: 小红书(TFPT08) | F11: 自投 | G11: 江苏拾光宝盒信息技术有限公司(VEN01761) | J11: 拾光宝盒（花西子Florasis3） | K11: 119989 | R11: 否 | S11: =VLOOKUP(B11,'Sheet9'!$B$2:$G$191,3,FALSE) | T11: =VLOOKUP(B11,'Sheet9'!$B$2:$G$191,4,FALSE) | U11: =VLOOKUP(B11,'Sheet9'!$B$2:$G$191,5,FALSE) | V11: 内容投放组 | W11: =VLOOKUP(K11,'Sheet11'!$X$2:$AH$279,11,FALSE) | Y11: 贝果 | Z11: 甘草、清和 | AA11: 账号密码
A12: 站外 | B12: 小红书加热 | C12: 杭州宜格化妆品有限公司 | E12: 小红书(TFPT08) | F12: 自投 | G12: 江苏拾光宝盒信息技术有限公司(VEN01761) | J12: 拾光宝盒（花西子Florasis） | K12: 65933 | R12: 否 | S12: =VLOOKUP(B12,'Sheet9'!$B$2:$G$191,3,FALSE) | T12: =VLOOKUP(B12,'Sheet9'!$B$2:$G$191,4,FALSE) | U12: =VLOOKUP(B12,'Sheet9'!$B$2:$G$191,5,FALSE) | V12: 内容投放组 | W12: =VLOOKUP(K12,'Sheet11'!$X$2:$AH$279,11,FALSE) | Y12: 贝果 | Z12: 甘草、清和 | AA12: 账号密码
A13: 站外 | B13: 小红书加热 | C13: 杭州宜格化妆品有限公司 | E13: 小红书(TFPT08) | F13: 自投 | G13: 江苏拾光宝盒信息技术有限公司(VEN01761) | J13: 拾光宝盒（花西子Florasis2） | K13: 119990 | R13: 否 | S13: =VLOOKUP(B13,'Sheet9'!$B$2:$G$191,3,FALSE) | T13: =VLOOKUP(B13,'Sheet9'!$B$2:$G$191,4,FALSE) | U13: =VLOOKUP(B13,'Sheet9'!$B$2:$G$191,5,FALSE) | V13: 内容投放组 | W13: =VLOOKUP(K13,'Sheet11'!$X$2:$AH$279,11,FALSE) | Y13: 贝果 | Z13: 甘草、清和 | AA13: 账号密码
A14: 站外 | B14: B站起飞加热 | C14: 杭州宜格化妆品有限公司 | D14: 暂停投放 | E14: B站 | F14: 自投 | G14: 杭州羽联信息科技有限公司 | I14: https://ad.bilibili.com/#/home | J14: hongjin@yige-group.com | K14: hongjin@yige-group.com | N14: 否 | O14: 否 | P14: 是 | Q14: 是 | R14: 否 | S14: =VLOOKUP(B14,'Sheet9'!$B$2:$G$191,3,FALSE) | T14: =VLOOKUP(B14,'Sheet9'!$B$2:$G$191,4,FALSE) | U14: =VLOOKUP(B14,'Sheet9'!$B$2:$G$191,5,FALSE) | V14: 内容投放组 | W14: =VLOOKUP(K14,'Sheet11'!$X$2:$AH$279,11,FALSE) | Y14: 贝果 | Z14: 甘草、清和 | AA14: 账号密码
A15: 站外 | B15: B站起飞加热 | C15: 杭州宜格化妆品有限公司 | D15: 暂停投放 | E15: B站 | F15: 自投 | G15: 上海无堂网络科技有限公司 | I15: https://ad.bilibili.com/#/home | J15: wanwan@yige-group.com | K15: wanwan@yige-group.com | N15: 否 | O15: 否 | P15: 是 | Q15: 是 | R15: 否 | S15: =VLOOKUP(B15,'Sheet9'!$B$2:$G$191,3,FALSE) | T15: =VLOOKUP(B15,'Sheet9'!$B$2:$G$191,4,FALSE) | U15: =VLOOKUP(B15,'Sheet9'!$B$2:$G$191,5,FALSE) | V15: 内容投放组 | W15: =VLOOKUP(K15,'Sheet11'!$X$2:$AH$279,11,FALSE) | Y15: 贝果 | Z15: 甘草、清和 | AA15: 账号密码
A16: 站外 | B16: B站起飞加热 | C16: 杭州宜格化妆品有限公司 | D16: 暂停投放 | E16: B站 | F16: 自投 | G16: 上海无堂网络科技有限公司 | I16: https://ad.bilibili.com/#/home | J16: tangli@yige.us | K16: tangli@yige.us | N16: 否 | O16: 否 | P16: 是 | Q16: 是 | R16: 否 | S16: =VLOOKUP(B16,'Sheet9'!$B$2:$G$191,3,FALSE) | T16: =VLOOKUP(B16,'Sheet9'!$B$2:$G$191,4,FALSE) | U16: =VLOOKUP(B16,'Sheet9'!$B$2:$G$191,5,FALSE) | V16: 内容投放组 | W16: =VLOOKUP(K16,'Sheet11'!$X$2:$AH$279,11,FALSE) | Y16: 贝果 | Z16: 甘草、清和 | AA16: 账号密码
A17: 站外 | B17: B站起飞加热 | C17: 杭州宜格化妆品有限公司 | D17: 暂停投放 | E17: B站 | F17: 自投 | G17: 上海无堂网络科技有限公司 | I17: https://ad.bilibili.com/#/home | J17: qinghe@zhimei.us | K17: qinghe@zhimei.us | N17: 否 | O17: 否 | P17: 是 | Q17: 是 | R17: 否 | S17: =VLOOKUP(B17,'Sheet9'!$B$2:$G$191,3,FALSE) | T17: =VLOOKUP(B17,'Sheet9'!$B$2:$G$191,4,FALSE) | U17: =VLOOKUP(B17,'Sheet9'!$B$2:$G$191,5,FALSE) | V17: 内容投放组 | W17: =VLOOKUP(K17,'Sheet11'!$X$2:$AH$279,11,FALSE) | Y17: 贝果 | Z17: 甘草、清和 | AA17: 账号密码
A18: 站外 | B18: B站起飞加热 | C18: 杭州宜格化妆品有限公司 | D18: 暂停投放 | E18: B站 | F18: 自投 | G18: 上海无堂网络科技有限公司 | I18: https://ad.bilibili.com/#/home | J18: kongqing@yige-group.com | K18: kongqing@yige-group.com | N18: 否 | O18: 否 | P18: 是 | Q18: 是 | R18: 否 | S18: =VLOOKUP(B18,'Sheet9'!$B$2:$G$191,3,FALSE) | T18: =VLOOKUP(B18,'Sheet9'!$B$2:$G$191,4,FALSE) | U18: =VLOOKUP(B18,'Sheet9'!$B$2:$G$191,5,FALSE) | V18: 内容投放组 | W18: =VLOOKUP(K18,'Sheet11'!$X$2:$AH$279,11,FALSE) | Y18: 贝果 | Z18: 甘草、清和 | AA18: 账号密码
A19: 站外 | B19: B站起飞加热 | C19: 杭州宜格化妆品有限公司 | D19: 暂停投放 | E19: B站 | F19: 自投 | G19: 北京新线中视文化传播有限公司 | I19: https://ad.bilibili.com/#/home | J19: gancao@yige-group.com | K19: gancao@yige-group.com | N19: 否 | O19: 否 | P19: 是 | Q19: 是 | R19: 否 | S19: =VLOOKUP(B19,'Sheet9'!$B$2:$G$191,3,FALSE) | T19: =VLOOKUP(B19,'Sheet9'!$B$2:$G$191,4,FALSE) | U19: =VLOOKUP(B19,'Sheet9'!$B$2:$G$191,5,FALSE) | V19: 内容投放组 | W19: =VLOOKUP(K19,'Sheet11'!$X$2:$AH$279,11,FALSE) | Y19: 贝果 | Z19: 甘草、清和 | AA19: 账号密码
A20: 站外 | B20: 微博推广 | C20: 杭州宜格化妆品有限公司 | D20: 正常使用 | E20: 微博 | F20: 自投 | G20: 上海宇枫电子商务有限公司 | I20: https://ad.weibo.com/ | J20: 花西子Florasis | K20: 6336556296 | N20: 否 | O20: 否 | P20: 是 | Q20: 否 | R20: 否 | S20: 品牌运营中心 | T20: 运营策略部 | U20: 天猫运营部 | V20: 推广中心组 | W20: =VLOOKUP(K20,'Sheet11'!$X$2:$AH$279,11,FALSE)
A21: 站外 | B21: 微博推广 | C21: 杭州宜格化妆品有限公司 | D21: 正常使用 | E21: 微博 | F21: 自投 | G21: 上海宇枫电子商务有限公司 | J21: 花西子美妆日记 | K21: 6965612965 | N21: 否 | O21: 否 | P21: 是 | Q21: 否 | R21: 否 | S21: 品牌运营中心 | T21: 运营策略部 | U21: 天猫运营部 | V21: 推广中心组 | W21: =VLOOKUP(K21,'Sheet11'!$X$2:$AH$279,11,FALSE)
A22: 站外 | B22: AD信息流 | C22: 杭州宜格化妆品有限公司 | D22: 正常使用 | F22: 自投 | G22: 广东省广告集团股份有限公司 | I22: https://ad.oceanengine.com/ | J22: huaxizi_xinxiliuad@163.com | K22: huaxizi_xinxiliuad@163.com | N22: 否 | O22: 否 | P22: 是 | Q22: 是 | R22: 是 | S22: =VLOOKUP(B22,'Sheet9'!$B$2:$G$191,3,FALSE) | T22: =VLOOKUP(B22,'Sheet9'!$B$2:$G$191,4,FALSE) | U22: =VLOOKUP(B22,'Sheet9'!$B$2:$G$191,5,FALSE) | V22: 推广中心组 | W22: =VLOOKUP(K22,'Sheet11'!$X$2:$AH$279,11,FALSE) | Y22: 贝果 | Z22: 白纸、阿布、志文、循安 | AA22: 账号密码
A23: 站外 | B23: AD信息流 | C23: 杭州宜格化妆品有限公司 | D23: 正常使用 | E23: 天猫抖音AD引流 | F23: 自投 | G23: 广东省广告集团股份有限公司 | I23: https://ad.oceanengine.com/ | J23: huaxizi_xinxiliuad4@163.com | K23: huaxizi_xinxiliuad4@163.com | N23: 否 | O23: 否 | P23: 是 | Q23: 是 | R23: 是 | S23: =VLOOKUP(B23,'Sheet9'!$B$2:$G$191,3,FALSE) | T23: =VLOOKUP(B23,'Sheet9'!$B$2:$G$191,4,FALSE) | U23: =VLOOKUP(B23,'Sheet9'!$B$2:$G$191,5,FALSE) | V23: 推广中心组 | W23: 白纸（张浩霖） | Y23: 贝果 | Z23: 白纸、阿布、志文、循安 | AA23: 账号密码
A24: 站外 | B24: AD信息流 | C24: 杭州宜格化妆品有限公司 | D24: 正常使用 | E24: 天猫抖音AD引流 | F24: 自投 | G24: 广东省广告集团股份有限公司 | I24: https://ad.oceanengine.com/ | J24: huaxizi_xinxliuad5@163.com | K24: huaxizi_xinxliuad5@163.com | N24: 否 | O24: 否 | P24: 是 | Q24: 是 | R24: 是 | S24: =VLOOKUP(B24,'Sheet9'!$B$2:$G$191,3,FALSE) | T24: =VLOOKUP(B24,'Sheet9'!$B$2:$G$191,4,FALSE) | U24: =VLOOKUP(B24,'Sheet9'!$B$2:$G$191,5,FALSE) | V24: 推广中心组 | W24: =VLOOKUP(K24,'Sheet11'!$X$2:$AH$279,11,FALSE) | Y24: 贝果 | Z24: 白纸、阿布、志文、循安 | AA24: 账号密码
A25: 站外 | B25: AD信息流 | C25: 杭州宜格化妆品有限公司 | D25: 正常使用 | E25: 天猫抖音AD引流 | F25: 自投 | G25: 广东省广告集团股份有限公司 | I25: https://ad.oceanengine.com/ | J25: huaxizi_xinxliuad7@163.com | K25: huaxizi_xinxliuad7@163.com | N25: 否 | O25: 否 | P25: 是 | Q25: 是 | R25: 是 | S25: =VLOOKUP(B25,'Sheet9'!$B$2:$G$191,3,FALSE) | T25: =VLOOKUP(B25,'Sheet9'!$B$2:$G$191,4,FALSE) | U25: =VLOOKUP(B25,'Sheet9'!$B$2:$G$191,5,FALSE) | V25: 推广中心组 | W25: =VLOOKUP(K25,'Sheet11'!$X$2:$AH$279,11,FALSE) | Y25: 贝果 | Z25: 白纸、阿布、志文、循安 | AA25: 账号密码
A26: 站外 | B26: AD信息流 | C26: 杭州宜格化妆品有限公司 | D26: 正常使用 | E26: 天猫抖音AD引流 | F26: 自投 | G26: 广东省广告集团股份有限公司 | I26: https://ad.oceanengine.com/ | J26: huaxizi_xinxliuad8@163.com | K26: huaxizi_xinxliuad8@163.com | N26: 否 | O26: 否 | P26: 是 | Q26: 是 | R26: 是 | S26: =VLOOKUP(B26,'Sheet9'!$B$2:$G$191,3,FALSE) | T26: =VLOOKUP(B26,'Sheet9'!$B$2:$G$191,4,FALSE) | U26: =VLOOKUP(B26,'Sheet9'!$B$2:$G$191,5,FALSE) | V26: 推广中心组 | W26: =VLOOKUP(K26,'Sheet11'!$X$2:$AH$279,11,FALSE) | Y26: 贝果 | Z26: 白纸、阿布、志文、循安 | AA26: 账号密码
A27: 站外 | B27: AD信息流 | C27: 杭州宜格化妆品有限公司 | D27: 正常使用 | E27: 天猫抖音AD引流 | F27: 自投 | G27: 群邑（上海）广告有限公司 | I27: https://ad.oceanengine.com/ | J27: huaxizi_xinxliuad9@163.com | K27: huaxizi_xinxliuad9@163.com | N27: 否 | O27: 否 | P27: 是 | Q27: 是 | R27: 是 | S27: =VLOOKUP(B27,'Sheet9'!$B$2:$G$191,3,FALSE) | T27: =VLOOKUP(B27,'Sheet9'!$B$2:$G$191,4,FALSE) | U27: =VLOOKUP(B27,'Sheet9'!$B$2:$G$191,5,FALSE) | V27: 推广中心组 | W27: =VLOOKUP(K27,'Sheet11'!$X$2:$AH$279,11,FALSE) | Y27: 贝果 | Z27: 白纸、阿布、志文、循安 | AA27: 账号密码
A28: 站外 | B28: AD信息流 | C28: 杭州宜格化妆品有限公司 | D28: 正常使用 | E28: 天猫抖音AD引流 | F28: 自投 | G28: 群邑（上海）广告有限公司 | I28: https://ad.oceanengine.com/ | J28: joy.du@mindshareworld.com | K28: joy.du@mindshareworld.com | N28: 否 | O28: 否 | P28: 是 | Q28: 是 | R28: 是 | S28: =VLOOKUP(B28,'Sheet9'!$B$2:$G$191,3,FALSE) | T28: =VLOOKUP(B28,'Sheet9'!$B$2:$G$191,4,FALSE) | U28: =VLOOKUP(B28,'Sheet9'!$B$2:$G$191,5,FALSE) | V28: 推广中心组 | W28: =VLOOKUP(K28,'Sheet11'!$X$2:$AH$279,11,FALSE) | Y28: 贝果 | Z28: 白纸、阿布、志文、循安 | AA28: 账号密码
A29: 站外 | B29: UD信息流 | C29: 杭州宜格化妆品有限公司 | D29: 正常使用 | E29: UD信息流引流 | F29: 自投 | G29: 北京九合互动文化传播有限公司 | I29: https://unidesk.taobao.com/index.html | J29: tb963892057577 | K29: tb963892057577 | N29: 否 | O29: 否 | P29: 是 | Q29: 是 | R29: 是 | S29: =VLOOKUP(B29,'Sheet9'!$B$2:$G$191,3,FALSE) | T29: =VLOOKUP(B29,'Sheet9'!$B$2:$G$191,4,FALSE) | U29: =VLOOKUP(B29,'Sheet9'!$B$2:$G$191,5,FALSE) | V29: 推广中心组 | W29: =VLOOKUP(K29,'Sheet11'!$X$2:$AH$279,11,FALSE) | Y29: 贝果 | Z29: 白纸、阿布、志文 | AA29: 账号密码
A30: 站外 | C30: 杭州宜格化妆品有限公司 | D30: 暂停投放 | E30: 微博信息流引流 | F30: 自投 | G30: 上海宇枫电子商务有限公司 | I30: https://ad.weibo.com/promote2/advertisements?customer_id=6336556296 | J30: adserving_ud0754@weibo.com | K30: adserving_ud0754@weibo.com | N30: 否 | O30: 否 | P30: 是 | Q30: 是 | R30: 是 | W30: =VLOOKUP(K30,'Sheet11'!$X$2:$AH$279,11,FALSE) | Y30: 贝果 | Z30: 白纸、阿布、志文 | AA30: 账号密码
A31: 站外 | C31: 杭州宜格化妆品有限公司 | D31: 正常使用 | E31: 百度信息流引流 | F31: 自投 | G31: 北京云锐国际文化传媒有限公司 | I31: https://cas.baidu.com/?tpl=www2&fromu=http%3A%2F%2Fwww2.b...ommon%2Fappinit.ajax | J31: 杭州宜格化妆品有限公司1（shvipyr花西子3） | K31: 杭州宜格化妆品有限公司1（shvipyr花西子3） | N31: 否 | O31: 否 | P31: 是 | Q31: 是 | R31: 是 | W31: =VLOOKUP(K31,'Sheet11'!$X$2:$AH$279,11,FALSE) | Y31: 贝果 | Z31: 白纸、阿布、循安 | AA31: 账号密码
A32: 站外 | B32: 磁力引擎 | C32: 杭州宜格化妆品有限公司 | D32: 正常使用 | E32: 快手信息流引流 | F32: 自投 | G32: 北京起量文化传媒有限公司 | I32: https://ad.e.kuaishou.com/manage?__accountId__=14861051 | J32: 13362198950 | K32: 13362198950 | N32: 否 | O32: 否 | P32: 是 | Q32: 是 | R32: 是 | S32: =VLOOKUP(B32,'Sheet9'!$B$2:$G$191,3,FALSE) | T32: =VLOOKUP(B32,'Sheet9'!$B$2:$G$191,4,FALSE) | U32: =VLOOKUP(B32,'Sheet9'!$B$2:$G$191,5,FALSE) | V32: 推广中心组 | W32: =VLOOKUP(K32,'Sheet11'!$X$2:$AH$279,11,FALSE) | Y32: 贝果 | Z32: 白纸、羽阳 | AA32: 账号密码
A33: 站外 | B33: 磁力金牛 | C33: 杭州宜格化妆品有限公司 | D33: 正常使用 | E33: 快手磁力金牛 | F33: 自投 | G33: 北京起量文化传媒有限公司 | I33: https://niu.e.kuaishou.com/manage?__accountId__=13304454 | J33: 13396586970 | K33: 13396586970 | N33: 否 | O33: 否 | P33: 是 | Q33: 是 | R33: 是 | S33: =VLOOKUP(B33,'Sheet9'!$B$2:$G$191,3,FALSE) | T33: =VLOOKUP(B33,'Sheet9'!$B$2:$G$191,4,FALSE) | U33: =VLOOKUP(B33,'Sheet9'!$B$2:$G$191,5,FALSE) | V33: 推广中心组 | W33: =VLOOKUP(K33,'Sheet11'!$X$2:$AH$279,11,FALSE) | Y33: 贝果 | Z33: 白纸、羽阳 | AA33: 账号密码
A34: 站外 | B34: 微信-ADQ推广 | C34: 杭州宜格化妆品有限公司 | D34: 正常使用 | E34: 微信渠道投放 | F34: 自投 | G34: 杭州炬美网络科技有限公司 | I34: https://ad.qq.com/atlas/23959502/index | J34: 微信扫码登录 | K34: 微信扫码登录 | N34: 否 | O34: 否 | P34: 是 | Q34: 是 | R34: 是 | S34: =VLOOKUP(B34,'Sheet9'!$B$2:$G$191,3,FALSE) | T34: =VLOOKUP(B34,'Sheet9'!$B$2:$G$191,4,FALSE) | U34: =VLOOKUP(B34,'Sheet9'!$B$2:$G$191,5,FALSE) | V34: 综合渠道推广部 | W34: =VLOOKUP(K34,'Sheet11'!$X$2:$AH$279,11,FALSE) | Y34: 贝果 | Z34: 白纸 | AA34: 账号密码
A35: 站外 | B35: 千川信息流 | C35: 杭州宜格化妆品有限公司 | F35: 自投 | G35: 北京云锐国际文化传媒有限公司 | J35: =VLOOKUP(K35,'Sheet5'!$J$3:$K$200,2,FALSE) | K35: 1727265617683469 | N35: 否 | S35: =VLOOKUP(B35,'Sheet9'!$B$2:$G$191,3,FALSE) | T35: =VLOOKUP(B35,'Sheet9'!$B$2:$G$191,4,FALSE) | U35: =VLOOKUP(B35,'Sheet9'!$B$2:$G$191,5,FALSE) | V35: 抖音推广部 | W35: 兴泉（韩兴泉）、流沙（俞君珠）、奶茶（唐丽）、榴莲（管晓辉）、三喜（王思雨）、白龙（樊苏北）
A36: 站外 | B36: AD信息流 | C36: 杭州宜格化妆品有限公司 | F36: 自投 | G36: 广东省广告集团股份有限公司 | J36: =VLOOKUP(K36,'Sheet5'!$J$3:$K$200,2,FALSE) | K36: 1762866886323341 | N36: 否 | P36: 否 | Q36: 否 | S36: =VLOOKUP(B36,'Sheet9'!$B$2:$G$191,3,FALSE) | T36: =VLOOKUP(B36,'Sheet9'!$B$2:$G$191,4,FALSE) | U36: =VLOOKUP(B36,'Sheet9'!$B$2:$G$191,5,FALSE) | V36: 推广中心组 | W36: =VLOOKUP(K36,'Sheet11'!$X$2:$AH$279,11,FALSE)
A37: 站外 | B37: AD信息流 | C37: 杭州宜格化妆品有限公司 | F37: 自投 | G37: 广东省广告集团股份有限公司 | J37: =VLOOKUP(K37,'Sheet5'!$J$3:$K$200,2,FALSE) | K37: 1758638395883534 | N37: 否 | P37: 否 | Q37: 否 | S37: =VLOOKUP(B37,'Sheet9'!$B$2:$G$191,3,FALSE) | T37: =VLOOKUP(B37,'Sheet9'!$B$2:$G$191,4,FALSE) | U37: =VLOOKUP(B37,'Sheet9'!$B$2:$G$191,5,FALSE) | V37: 推广中心组 | W37: =VLOOKUP(K37,'Sheet11'!$X$2:$AH$279,11,FALSE)
A38: 站外 | B38: AD信息流 | C38: 杭州宜格化妆品有限公司 | F38: 自投 | G38: 广东省广告集团股份有限公司 | J38: =VLOOKUP(K38,'Sheet5'!$J$3:$K$200,2,FALSE) | K38: 1744729041456135 | N38: 否 | P38: 否 | Q38: 否 | S38: =VLOOKUP(B38,'Sheet9'!$B$2:$G$191,3,FALSE) | T38: =VLOOKUP(B38,'Sheet9'!$B$2:$G$191,4,FALSE) | U38: =VLOOKUP(B38,'Sheet9'!$B$2:$G$191,5,FALSE) | V38: 推广中心组 | W38: =VLOOKUP(K38,'Sheet11'!$X$2:$AH$279,11,FALSE)
A39: 站外 | B39: AD信息流 | C39: 杭州宜格化妆品有限公司 | F39: 自投 | G39: 广东省广告集团股份有限公司 | J39: =VLOOKUP(K39,'Sheet5'!$J$3:$K$200,2,FALSE) | K39: 1744631353681928 | N39: 否 | P39: 否 | Q39: 否 | S39: =VLOOKUP(B39,'Sheet9'!$B$2:$G$191,3,FALSE) | T39: =VLOOKUP(B39,'Sheet9'!$B$2:$G$191,4,FALSE) | U39: =VLOOKUP(B39,'Sheet9'!$B$2:$G$191,5,FALSE) | V39: 推广中心组 | W39: =VLOOKUP(K39,'Sheet11'!$X$2:$AH$279,11,FALSE)
A40: 站外 | B40: AD信息流 | C40: 杭州宜格化妆品有限公司 | F40: 自投 | G40: 广东省广告集团股份有限公司 | J40: =VLOOKUP(K40,'Sheet5'!$J$3:$K$200,2,FALSE) | K40: 1752335658405895 | N40: 否 | P40: 否 | Q40: 否 | S40: =VLOOKUP(B40,'Sheet9'!$B$2:$G$191,3,FALSE) | T40: =VLOOKUP(B40,'Sheet9'!$B$2:$G$191,4,FALSE) | U40: =VLOOKUP(B40,'Sheet9'!$B$2:$G$191,5,FALSE) | V40: 推广中心组 | W40: =VLOOKUP(K40,'Sheet11'!$X$2:$AH$279,11,FALSE)
...

Sheet 充值账户-投放（维度数据）
B1: 公司主体 | C1: 投放平台 | D1: 投放方式 | E1: 平台对合作应供应商名称 | F1: 账号 | G1: 编码 | H1: 是否按消耗开票 | I1: 是否为充值账户 | J1: 是否能取到充值/消耗明细 | K1: 是否存在充值赠送金 | L1: 是否存在返利 | M1: 是否通过此账户申请开票 | N1: 使用中心 | O1: 使用二级部门 | P1: 使用三级部门 | Q1: 业务对接人 | R1: 财务对接人
B2: 杭州宜格化妆品有限公司 | C2: 天猫 | D2: 自投 | E2: 杭州阿里妈妈软件服务有限公司 | F2: 天猫花西子旗舰店-直通车 | G2: DP015-ZTC | I2: 是 | J2: 是 | K2: 否 | L2: 否 | M2: 是 | N2: 品牌运营中心 | O2: 广告投放部 | P2: 平台电商部 | Q2: 盐首（刘如敏） | R2: 贝果
B3: 杭州宜格化妆品有限公司 | C3: 天猫 | D3: 自投 | E3: 杭州阿里妈妈软件服务有限公司 | F3: 天猫花西子旗舰店-引力魔方 | G3: DP015-YLMF | I3: 是 | J3: 是 | K3: 否 | L3: 否 | M3: 是 | N3: 品牌运营中心 | O3: 广告投放部 | P3: 平台电商部 | Q3: 盐首（刘如敏） | R3: 贝果
B4: 杭州宜格化妆品有限公司 | C4: 天猫 | D4: 自投 | E4: 浙江阿里巴巴通信技术有限公司 | F4: 天猫花西子旗舰店-万相台 | G4: DP015-WXT | I4: 是 | J4: 是 | K4: 否 | L4: 否 | M4: 是 | N4: 品牌运营中心 | O4: 广告投放部 | P4: 平台电商部 | Q4: 洛竹（程铭） | R4: 贝果
A5: 淘宝匠泽-直通车 | B5: 杭州匠泽电子商务有限公司 | C5: 天猫 | D5: 自投 | E5: 杭州阿里妈妈软件服务有限公司 | F5: 天猫花西子匠泽店-直通车 | G5: DP001-ZTC | I5: 是 | J5: 是 | K5: 否 | L5: 否 | M5: 是 | N5: 品牌运营中心 | O5: 广告投放部 | P5: 平台电商部 | Q5: 盐首（刘如敏） | R5: 贝果
A6: 淘宝匠泽-引力魔方 | B6: 杭州匠泽电子商务有限公司 | C6: 天猫 | D6: 自投 | E6: 杭州阿里妈妈软件服务有限公司 | F6: 天猫花西子匠泽店-引力魔方 | G6: DP001-YLMF | I6: 是 | J6: 是 | K6: 否 | L6: 否 | M6: 是 | N6: 品牌运营中心 | O6: 广告投放部 | P6: 平台电商部 | Q6: 盐首（刘如敏） | R6: 贝果
B7: 杭州匠泽电子商务有限公司 | C7: 天猫 | D7: 自投 | E7: 浙江阿里巴巴通信技术有限公司 | F7: 天猫花西子匠泽店-万相台 | G7: DP001-WXT | I7: 是 | J7: 是 | K7: 否 | L7: 否 | M7: 是 | N7: 品牌运营中心 | O7: 广告投放部 | P7: 平台电商部 | Q7: 盐首（刘如敏） | R7: 贝果
B8: 杭州宜格化妆品有限公司 | C8: 天猫 | D8: 自投 | E8: 杭州阿里妈妈软件服务有限公司 | F8: 天猫花西子旗舰店-淘宝客 | G8: DP015-TBK | I8: 是 | J8: 是 | K8: 否 | L8: 否 | M8: 是 | Q8: 林胖（林玲）
B9: 杭州匠泽电子商务有限公司 | C9: 天猫 | D9: 自投 | E9: 杭州阿里妈妈软件服务有限公司 | F9: 天猫花西子匠泽店-淘宝客 | G9: DP001-TBK | I9: 是 | J9: 是 | K9: 否 | L9: 否 | M9: 是 | Q9: 林胖（林玲）
B10: 杭州匠泽电子商务有限公司 | C10: 京东 | D10: 自投 | E10: 重庆京东海嘉电子商务有限公司 | F10: 京东花西子自营店 | G10: DP033-JDZY | I10: 是 | J10: 是 | K10: 否 | L10: 否 | M10: 是 | N10: 品牌运营中心 | O10: 广告投放部 | P10: 平台电商部 | Q10: 大阳（徐庄南） | R10: 贝果
B11: 杭州匠泽电子商务有限公司 | C11: 京东 | D11: 自投 | E11: 重庆京东海嘉电子商务有限公司 | F11: 京东花西子旗舰店 | G11: DP002-JD | I11: 是 | J11: 是 | K11: 否 | L11: 否 | M11: 是 | N11: 品牌运营中心 | O11: 广告投放部 | P11: 平台电商部 | Q11: 大阳（徐庄南） | R11: 贝果
B12: 杭州匠泽电子商务有限公司 | C12: 唯品会 | D12: 自投 | E12: 广州海珠品唯信息服务有限公司 | F12: 唯品会花西子自营店 | G12: DP029-WPH | I12: 是 | J12: 是 | K12: 否 | L12: 是 | M12: 是 | N12: 品牌运营中心 | O12: 广告投放部 | P12: 平台电商部 | Q12: 立立夏（武雨环） | R12: 贝果
B13: 杭州匠泽电子商务有限公司 | C13: 拼多多 | D13: 自投 | E13: 上海寻梦信息技术有限公司 | F13: 拼多多花西子专卖店 | G13: DP011-PDD | I13: 是 | J13: 是 | Q13: 鹿其（俞麟峰）
B14: 杭州匠泽电子商务有限公司 | C14: 拼多多 | D14: 自投 | E14: 上海寻梦信息技术有限公司 | F14: 拼多多花西子美妆专卖店 | G14: DP069-PDD | I14: 是 | J14: 是 | Q14: 鹿其（俞麟峰）
B15: 杭州匠泽电子商务有限公司 | C15: 拼多多 | D15: 自投 | E15: 上海寻梦信息技术有限公司 | F15: 拼多多花西子美妆旗舰店 | G15: DP071-PDD | I15: 是 | J15: 是 | Q15: 鹿其（俞麟峰）
B16: 杭州匠泽电子商务有限公司 | C16: 拼多多 | D16: 自投 | E16: 上海寻梦信息技术有限公司 | F16: 拼多多花西子匠泽店 | G16: DP030-PDD | I16: 是 | J16: 是 | Q16: 鹿其（俞麟峰）
A17: DOU+ | B17: 杭州宜格化妆品有限公司 | C17: 抖音 | D17: 自投 | E17: 湖北巨量引擎科技有限公司 | F17: 戏曲红妆 | G17: 1713571308516366 | I17: 是 | J17: 是 | K17: 否 | L17: 否 | M17: 是 | N17: 品牌运营中心 | O17: 品牌运营中心-广告投放部-内容投放部 | Q17: 空青
A18: 抖音官号DOU+ | B18: 杭州宜格化妆品有限公司 | C18: 抖音 | D18: 自投 | E18: 湖北巨量引擎科技有限公司 | F18: 花西子在海外 | G18: 1710588438708239 | I18: 是 | J18: 是 | K18: 否 | L18: 否 | M18: 是 | N18: 品牌运营中心 | O18: 抖音部-内容部-综合账号运营组 | Q18: 南嘉
A19: 矩阵号DOU+ | B19: 杭州宜格化妆品有限公司 | C19: 抖音 | D19: 自投 | E19: 湖北巨量引擎科技有限公司 | F19: 花西子妆养旗舰店 | G19: 1689943229305863 | I19: 是 | J19: 是 | K19: 否 | L19: 否 | M19: 是 | N19: 品牌运营中心 | O19: 抖音部-内容部-综合账号运营组 | Q19: 海水
A20: 矩阵号DOU+ | B20: 杭州宜格化妆品有限公司 | C20: 抖音 | D20: 自投 | E20: 湖北巨量引擎科技有限公司 | F20: 花西子官方旗舰店底妆精选 | G20: 1673714311187471 | I20: 是 | J20: 是 | K20: 否 | L20: 否 | M20: 是 | N20: 品牌运营中心 | O20: 抖音部-内容部-综合账号运营组 | Q20: 奈雪/晚意
A21: 矩阵号DOU+ | B21: 杭州宜格化妆品有限公司 | C21: 抖音 | D21: 自投 | E21: 湖北巨量引擎科技有限公司 | F21: 花西子礼物精选 | G21: 1709154203629639 | I21: 是 | J21: 是 | K21: 否 | L21: 否 | M21: 是 | N21: 品牌运营中心 | O21: 抖音部-内容部-综合账号运营组 | Q21: 奈雪/晚意
A22: 矩阵号DOU+ | B22: 杭州宜格化妆品有限公司 | C22: 抖音 | D22: 自投 | E22: 湖北巨量引擎科技有限公司 | F22: 东方有佳人 | G22: 1676272771724301 | I22: 是 | J22: 是 | K22: 否 | L22: 否 | M22: 是 | N22: 品牌运营中心 | O22: 抖音部-内容部-综合账号运营组 | Q22: 海水
A23: 千川信息流 | B23: 杭州宜格化妆品有限公司 | C23: 抖音 | D23: 自投 | E23: 湖北巨量引擎科技有限公司 | F23: 花西子-小店随心推 | G23: 1695646517812232 | I23: 是 | N23: 品牌运营中心 | O23: 渠道运营部 | P23: 抖音部 | Q23: 韩兴泉、奶茶（唐丽）
B24: 杭州宜格化妆品有限公司 | C24: 巨量星图 | E24: 武汉巨量星图科技有限公司 | F24: jinyan@zhimei.us | G24: 1709153479960584 | I24: 是 | Q24: 杜若
A25: DOU+ | B25: 杭州宜格化妆品有限公司 | C25: 抖音 | D25: 自投 | E25: 湖北巨量引擎科技有限公司 | F25: 花西子官方旗舰店 | G25: 1601161499296772 | I25: 是 | N25: 品牌运营中心 | O25: 品牌运营中心-内容电商部-抖音部 | Q25: 空青、七禾、南嘉
B26: 杭州宜格化妆品有限公司 | C26: 天猫 | D26: 自投 | E26: 杭州阿里妈妈淘联信息技术有限公司 | F26: 天猫花西子旗舰店-星任务 | G26: DP015-XRW | Q26: 杜若
A27: 权益红包-直播间 | B27: 杭州宜格化妆品有限公司 | C27: 天猫 | D27: 自投 | E27: 杭州阿里妈妈软件服务有限公司 | F27: 天猫花西子旗舰店-权益红包 | G27: DP015-QYHB | Q27: 阿泽
B28: 杭州宜格化妆品有限公司 | C28: 小红书 | D28: 自投 | E28: 薯一薯二文化传媒（上海）有限公司 | F28: yigehzp@163.com | G28: 55d34272f5a26377d1b784dd

Sheet 基础信息
A1: 字段 | B1: 字段类别 | C1: 字段解释 | D1: 用途与诉求 | E1: 字段名 | F1: 字段长度 | G1: 是否主键 | H1: 字段备注
A2: 公司主体 | B2: 下拉-单选
A3: 营销活动 | B3: 下拉-多选
A4: 公司手机号 | B4: 文本
A5: 公司邮箱 | B5: 文本
A6: 账户ID | B6: 文本
A7: 账户名 | B7: 文本
A8: 账户持有人 | B8: 文本
A9: 供应商名称 | B9: 文本
A10: 投放平台 | B10: 下拉-多选
A11: 账户状态 | B11: 下拉-单选
A12: 充值类型 | B12: 下拉-单选
A13: 是否存在充值赠送 | B13: 下拉-单选
... A21: 数据是否已回收 | B21: 下拉-单选

Sheet 枚举值
A1: 字段 | B1: 是否必填 | C1: 枚举值Code | D1: 枚举值 | E1: 外键 | F1: 备注说明 | G1: 经分是否需要 | H1: 经分是否需要业务处理 | I1: 经分处理逻辑
A2: 账户状态 | B2: Y | C2: 01 | E2: NA | F2: 枚举值说明 | G2: Y | H2: Y
C3: 02
C4: 03
C5: 04
C6: 05
A7: 充值类型 | B7: Y | C7: 01 | E7: NA | F7: 枚举值说明 | G7: Y | H7: Y
C8: 02
C9: 03
C10: 04
C11: 05

Sheet Sheet5
A1: 站内/站外 | B1: 营销活动 | C1: 公司主体 | D1: =+++++H7 | E1: 平台 | F1: 投放方式 | G1: 平台对合作应供应商名称 | H1: 对应业务场景及用途 | I1: 登录网址 | J1: 编码 | K1: 账号 | M1: 编码 | N1: 是否为资金充值账户 | O1: 是否能取到充值/消耗明细 | P1: 是否存在充值赠送金 | Q1: 是否存在返利 | R1: 截止2022年10月31日余额（元） | S1: 是否通过此账户申请开票 | T1: 使用中心 | U1: 使用二级部门 | V1: 使用三级部门 | W1: 业务使用人 | X1: 备注 | Y1: 财务对接人 | Z1: 账户权限owner | AA1: 登录方式
D2: 正常使用/闲置 | E2: 平台的称呼，如： 抖音-巨量千川 抖音-巨量纵横 快手 淘宝AD | F2: 自投/代投 | G2: 供应商全称 | N2: 是/否 | O2: 是/否 | P2: 是/否 | Q2: 是/否 | R2: 不填 | S2: 是/否 | T2: 一级中心 | Z2: 管理密码人员 | AA2: 验证码/账户密码
A3: 站内 | B3: 天猫-直通车 | C3: 杭州宜格化妆品有限公司 | D3: 正常使用 | E3: 淘宝 | F3: 自投 | G3: 杭州阿里妈妈软件服务有限公司 | H3: 直通车 | I3: https://subway.simba.taobao.com/index.jsp?spm=..0.da0f51bf8.6f372030STYU7d&file=indexnew.jsp#!/manage/campaign/detail?campaignId=222191719&start=2022-12-06&end=2022-12-06 | K3: 花西子旗舰店:陈玄、花西子旗舰店:幽兰、花西子旗舰店:盐首、花西子旗舰店:丰垚 | M3: ADV01 | N3: 是 | O3: 是 | P3: 否 | Q3: 否 | R3: 不填 | S3: 是 | T3: 品牌运营中心 | U3: 广告投放部 | V3: 平台电商部 | W3: 杜英晗、刘建旺、刘如敏、韦应峰 | Y3: 贝果 | Z3: 杜英晗、刘建旺、刘如敏、韦应峰 | AA3: 账号密码
A4: 站内 | B4: 天猫-引力魔方 | C4: 杭州宜格化妆品有限公司 | D4: 正常使用 | E4: 淘宝 | F4: 自投 | G4: 杭州阿里妈妈软件服务有限公司 | H4: 引力魔方 | I4: https://tuijian.taobao.com/indexbp.html?spm=a2e1u0.13920195.cf7687754.d17068800.2ab94d63TTfrAB#!/manage/def?spm=a2e1u0.13920195.cf7687754.d17068800.2ab94d63TTfrAB&alias=def&startTime=2022-12-06&endTime=2022-12-06&campaignGroupId=12563920&marketScene=display_user_define&statusList=START%2CPAUSE%2CWAIT | K4: 花西子旗舰店:陈玄、花西子旗舰店:幽兰、花西子旗舰店:盐首、花西子旗舰店:丰垚 | M4: ADV02 | N4: 是 | O4: 是 | P4: 否 | Q4: 否 | R4: 不填 | S4: 是 | T4: 品牌运营中心 | U4: 广告投放部 | V4: 平台电商部 | W4: 杜英晗、刘建旺、刘如敏、韦应峰 | Y4: 贝果 | Z4: 杜英晗、刘建旺、刘如敏、韦应峰 | AA4: 账号密码
A5: 站内 | B5: 天猫-明星店铺 | C5: 杭州宜格化妆品有限公司 | D5: 正常使用 | E5: 淘宝 | F5: 自投 | G5: 杭州阿里妈妈软件服务有限公司 | H5: 明星店铺 | I5: https://branding.taobao.com/index.action?spm=a2e0z.13920195.cf7687754.ddb5ad158.d9df6c51tgUS2R&file=index.action#!/account/index | K5: 花西子旗舰店:陈玄、花西子旗舰店:幽兰、花西子旗舰店:盐首、花西子旗舰店:丰垚 | M5: ADV03 | N5: 是 | O5: 是 | P5: 否 | Q5: 否 | R5: 不填 | S5: 是 | T5: 品牌运营中心 | U5: 广告投放部 | V5: 平台电商部 | W5: 杜英晗、刘建旺、刘如敏、韦应峰 | Y5: 贝果 | Z5: 杜英晗、刘建旺、刘如敏、韦应峰 | AA5: 账号密码
A6: 站内 | B6: 天猫-万相台-超级直播 | C6: 杭州宜格化妆品有限公司 | D6: 正常使用 | E6: 淘宝 | F6: 自投 | G6: 浙江阿里巴巴通信技术有限公司 | H6: 超级直播 | I6: https://adbrain.taobao.com/indexbp.html?spm=a2etp.11817080.cf7687754.1.3cfc340cF6NZNK#!/live/report-rtp/index?alias=duration&bizCode=adStrategyDuration&perspective=report&startTime=2022-11-12&endTime=2022-12-05&vs=false&version=all&dateType=history&effect=15&effectType=click&tab=campaign&reportQuery=%5Bobject%20Object%5D&spm= | K6: 花西子旗舰店:陈玄、花西子旗舰店:幽兰、花西子旗舰店:盐首、花西子旗舰店:丰垚 | M6: ADV04 | N6: 是 | O6: 是 | P6: 否 | Q6: 否 | R6: 不填 | S6: 是 | T6: 品牌运营中心 | U6: 广告投放部 | V6: 平台电商部 | W6: 杜英晗、刘建旺、刘如敏、韦应峰 | Y6: 贝果 | Z6: 杜英晗、刘建旺、刘如敏、韦应峰 | AA6: 账号密码
A7: 站内 | B7: 天猫-万相台-超级短视频 | C7: 杭州宜格化妆品有限公司 | D7: 正常使用 | E7: 淘宝 | F7: 自投 | G7: 浙江阿里巴巴通信技术有限公司 | H7: 超级短视频 | I7: https://adbrain.taobao.com/indexbp.html?spm=a2etp.11817080.cf7687754.1.3cfc340cF6NZNK#!/live/report-rtp/index?alias=duration&bizCode=adStrategyDuration&perspective=report&startTime=2022-11-12&endTime=2022-12-05&vs=false&version=all&dateType=history&effect=15&effectType=click&tab=campaign&reportQuery=%5Bobject%20Object%5D&spm= | K7: 花西子旗舰店:陈玄、花西子旗舰店:幽兰、花西子旗舰店:盐首、花西子旗舰店:丰垚 | M7: ADV05 | N7: 是 | O7: 是 | P7: 否 | Q7: 否 | R7: 不填 | S7: 是 | T7: 品牌运营中心 | U7: 广告投放部 | V7: 平台电商部 | W7: 杜英晗、刘建旺、刘如敏、韦应峰 | Y7: 贝果 | Z7: 杜英晗、刘建旺、刘如敏、韦应峰 | AA7: 账号密码
A8: 站内 | C8: 杭州宜格化妆品有限公司 | D8: 正常使用 | E8: 淘宝 | F8: 自投 | G8: 浙江阿里巴巴通信技术有限公司 | H8: 万相台 | I8: https://adbrain.taobao.com/indexbp.html?spm=a2etp.11817080.cf7687754.1.3cfc340cF6NZNK#!/live/report-rtp/index?alias=duration&bizCode=adStrategyDuration&perspective=report&startTime=2022-11-12&endTime=2022-12-05&vs=false&version=all&dateType=history&effect=15&effectType=click&tab=campaign&reportQuery=%5Bobject%20Object%5D&spm= | K8: 花西子旗舰店:陈玄、花西子旗舰店:幽兰、花西子旗舰店:盐首、花西子旗舰店:丰垚 | M8: ADV06 | N8: 是 | O8: 是 | P8: 否 | Q8: 否 | R8: 不填 | S8: 是 | T8: 品牌运营中心 | U8: 广告投放部 | V8: 平台电商部 | W8: 杜英晗、刘建旺、刘如敏、韦应峰 | Y8: 贝果 | Z8: 杜英晗、刘建旺、刘如敏、韦应峰 | AA8: 账号密码
A9: 站内 | B9: 天猫-超级互动城 | C9: 杭州宜格化妆品有限公司 | D9: 正常使用 | E9: 淘宝 | F9: 自投 | G9: 浙江阿里巴巴通信技术有限公司 | H9: 超级互动城 | I9: https://chaojihudong.taobao.com/indexbp.html?spm=a2e10l.13920195.cf7687754.d17068800.53f4677930Jd7Q#!/manage/shop-guarantee?alias=shop-guarantee&perspective=manage | K9: 花西子旗舰店:陈玄、花西子旗舰店:幽兰、花西子旗舰店:盐首、花西子旗舰店:丰垚 | M9: ADV07 | N9: 是 | O9: 是 | P9: 否 | Q9: 否 | R9: 不填 | S9: 是 | T9: 品牌运营中心 | U9: 广告投放部 | V9: 平台电商部 | W9: 杜英晗、刘建旺、刘如敏、韦应峰 | Y9: 贝果 | Z9: 杜英晗、刘建旺、刘如敏、韦应峰 | AA9: 账号密码
A10: 站内 | C10: 杭州匠泽电子商务有限公司 | D10: 正常使用 | E10: 京东 | F10: 自投 | G10: 重庆京东海嘉电子商务有限公司 | H10: 京东自营 | I10: https://product.shop.jd.com/rest/ware/list/manage?wareStatusStr=onSale&firstQuery=1 | K10: wet67956637 | M10: ADV08 | N10: 是 | O10: 是 | P10: 否 | Q10: 否 | R10: 不填 | S10: 是 | T10: 品牌运营中心 | U10: 广告投放部 | V10: 平台电商部 | W10: 周薇 | Y10: 贝果 | Z10: 周薇 | AA10: 账号密码
A11: 站内 | C11: 杭州匠泽电子商务有限公司 | D11: 正常使用 | E11: 京东 | F11: 自投 | G11: 重庆京东海嘉电子商务有限公司 | H11: 京东自营 | I11: https://product.shop.jd.com/rest/ware/list/manage?wareStatusStr=onSale&firstQuery=1 | K11: 花西子自营-代理2 | M11: ADV09 | N11: 是 | O11: 是 | P11: 否 | Q11: 否 | R11: 不填 | S11: 是 | T11: 品牌运营中心 | U11: 广告投放部 | V11: 平台电商部 | W11: 樗里 | Y11: 贝果 | Z11: 樗里 | AA11: 账号密码
A12: 站内 | C12: 杭州匠泽电子商务有限公司 | D12: 正常使用 | E12: 京东 | F12: 自投 | G12: 重庆京东海嘉电子商务有限公司 | H12: 京东POP | I12: https://product.shop.jd.com/rest/ware/list/manage?wareStatusStr=onSale&firstQuery=1 | K12: 花西子pop委托 | M12: ADV10 | N12: 是 | O12: 是 | P12: 否 | Q12: 否 | R12: 不填 | S12: 是 | T12: 品牌运营中心 | U12: 广告投放部 | V12: 平台电商部 | W12: 樗里 | Y12: 贝果 | Z12: 樗里 | AA12: 账号密码
A13: 站内 | C13: 杭州匠泽电子商务有限公司 | D13: 正常使用 | E13: 京东 | F13: 自投 | G13: 重庆京东海嘉电子商务有限公司 | H13: 京东POP | I13: https://product.shop.jd.com/rest/ware/list/manage?wareStatusStr=onSale&firstQuery=1 | K13: 花西子-麒麟 | M13: ADV11 | N13: 是 | O13: 是 | P13: 否 | Q13: 否 | R13: 不填 | S13: 是 | T13: 品牌运营中心 | U13: 广告投放部 | V13: 平台电商部 | W13: 樗里 | Y13: 贝果 | Z13: 樗里 | AA13: 账号密码
A14: 站内 | C14: 杭州匠泽电子商务有限公司 | D14: 正常使用 | E14: 京东 | F14: 自投 | G14: 重庆京东海嘉电子商务有限公司 | H14: 京东POP | I14: https://product.shop.jd.com/rest/ware/list/manage?wareStatusStr=onSale&firstQuery=1 | K14: 花西子旗舰店 | M14: ADV12 | N14: 是 | O14: 是 | P14: 否 | Q14: 否 | R14: 不填 | S14: 是 | T14: 品牌运营中心 | U14: 广告投放部 | V14: 平台电商部 | W14: 徐庄南 | Y14: 贝果 | Z14: 徐庄南 | AA14: 账号密码
A15: 站内 | C15: 杭州匠泽电子商务有限公司 | D15: 正常使用 | E15: 唯品 | F15: 自投 | G15: 广州海珠品唯信息服务有限公司 | H15: 唯品会 | I15: https://passport.vip.com/login?whereFrom=vipotd&src=https%3A%2F%2Fe.vip.com%2Fmain.html | K15: 15990052165 | M15: ADV13 | N15: 是 | O15: 是 | P15: 否 | Q15: 是 | R15: 不填 | S15: 是 | T15: 品牌运营中心 | U15: 广告投放部 | V15: 平台电商部 | W15: 赵东 | Y15: 贝果 | Z15: 赵东 | AA15: 账号密码
A16: 站内 | C16: 杭州匠泽电子商务有限公司 | D16: 正常使用 | E16: 唯品 | F16: 自投 | G16: 广州海珠品唯信息服务有限公司 | H16: 唯品会 | I16: https://passport.vip.com/login?whereFrom=vipotd&src=https%3A%2F%2Fe.vip.com%2Fmain.html | K16: 15867105936 | M16: ADV14 | N16: 是 | O16: 是 | P16: 否 | Q16: 是 | R16: 不填 | S16: 是 | T16: 品牌运营中心 | U16: 广告投放部 | V16: 平台电商部 | W16: 赵东 | Y16: 贝果 | Z16: 赵东 | AA16: 账号密码
A17: 站内 | C17: 杭州匠泽电子商务有限公司 | D17: 正常使用 | E17: 抖音-巨量纵横 | F17: 自投 | G17: 广东省广告集团股份有限公司 | H17: 京东自营抖音AD引流（CID） | I17: https://business.oceanengine.com/site/promotion?#/account | K17: huaxizi_xinxliuad2@163.com | M17: ADV15 | N17: 是 | O17: 是 | P17: 是 | Q17: 是 | R17: 不填 | S17: 是 | T17: 品牌运营中心 | U17: 广告投放部 | V17: 平台电商部 | W17: 徐庄南 | Y17: 贝果 | Z17: 徐庄南 | AA17: 账号密码
A18: 站内 | C18: 杭州匠泽电子商务有限公司 | D18: 正常使用 | E18: 考拉 | F18: 自投 | G18: 考拉海购（杭州）科技有限公司 | H18: 考拉 | I18: https://partner.kaola.com/index | K18: 18069829269 | M18: ADV16 | N18: 是 | O18: 是 | P18: 否 | Q18: 否 | R18: 不填 | S18: 是 | T18: 品牌运营中心 | U18: 广告投放部 | V18: 平台电商部 | W18: 徐庄南 | Y18: 贝果 | Z18: 徐庄南 | AA18: 账号密码
A19: 站内 | C19: 杭州匠泽电子商务有限公司 | D19: 正常使用 | E19: 京东到家 | F19: 自投 | G19: 上海京东到家元信信息技术有限公司 | H19: 京准通 | I19: https://jzt.jd.com/home/#/index | K19: 杭州匠泽电子商务 | M19: ADV17 | N19: 是 | O19: 是 | P19: 是 | Q19: 否 | R19: 不填 | S19: 是 | T19: 品牌运营中心 | U19: 广告投放部 | V19: 平台电商部 | W19: 徐庄南 | Y19: 贝果 | Z19: 徐庄南 | AA19: 账号密码
A20: 站内 | B20: 天猫-直通车 | C20: 杭州匠泽电子商务有限公司 | D20: 正常使用 | E20: 淘宝 | F20: 自投 | G20: 杭州阿里妈妈软件服务有限公司 | H20: 直通车 | I20: https://subway.simba.taobao.com/index.jsp?spm=..0.da0f51bf8.6f372030STYU7d&file=indexnew.jsp#!/manage/campaign/detail?campaignId=222191719&start=2022-12-06&end=2022-12-06 | K20: 花西子匠泽专卖店:大阳 | M20: ADV18 | N20: 是 | O20: 是 | P20: 否 | Q20: 否 | R20: 不填 | S20: 是 | T20: 品牌运营中心 | U20: 广告投放部 | V20: 平台电商部 | W20: 徐庄南 | Y20: 贝果 | Z20: 徐庄南 | AA20: 账号密码
A21: 站内 | C21: 杭州宜格化妆品有限公司 | D21: 正常使用 | E21: 小红书 | F21: 自投 | G21: 江苏拾光宝盒信息技术有限公司 | H21: 内容加热 | I21: https://ad.xiaohongshu.com/ | K21: shiguang2251@ten-box.cn | M21: ADV20 | N21: 是 | O21: 是 | P21: 是 | Q21: 是 | R21: 不填 | S21: 否 | T21: 品牌运营中心 | U21: 广告投放部 | V21: 内容投放部 | W21: 甘草 | Y21: 贝果 | Z21: 甘草、清和 | AA21: 账号密码
A22: 站内 | C22: 杭州宜格化妆品有限公司 | D22: 正常使用 | E22: 小红书 | F22: 自投 | G22: 江苏拾光宝盒信息技术有限公司 | H22: 内容加热 | I22: https://ad.xiaohongshu.com/ | K22: shiguang1450@ten-box.cn | M22: ADV21 | N22: 是 | O22: 是 | P22: 是 | Q22: 是 | R22: 不填 | S22: 否 | T22: 品牌运营中心 | U22: 广告投放部 | V22: 内容投放部 | W22: 甘草 | Y22: 贝果 | Z22: 甘草、清和 | AA22: 账号密码
A23: 站内 | C23: 杭州宜格化妆品有限公司 | D23: 正常使用 | E23: 小红书 | F23: 自投 | G23: 江苏拾光宝盒信息技术有限公司 | H23: 内容加热 | I23: https://ad.xiaohongshu.com/ | K23: shiguang2272@ten-box.cn | M23: ADV22 | N23: 是 | O23: 是 | P23: 是 | Q23: 是 | R23: 不填 | S23: 否 | T23: 品牌运营中心 | U23: 广告投放部 | V23: 内容投放部 | W23: 甘草 | Y23: 贝果 | Z23: 甘草、清和 | AA23: 账号密码
A24: 站内 | C24: 杭州宜格化妆品有限公司 | D24: 正常使用 | E24: 小红书 | F24: 自投 | G24: 江苏拾光宝盒信息技术有限公司 | H24: 内容加热 | I24: https://ad.xiaohongshu.com/ | K24: shiguang2824@ten-box.cn | M24: ADV24 | N24: 是 | O24: 是 | P24: 是 | Q24: 是 | R24: 不填 | S24: 否 | T24: 品牌运营中心 | U24: 广告投放部 | V24: 内容投放部 | W24: 甘草 | Y24: 贝果 | Z24: 甘草、清和 | AA24: 账号密码
A25: 站内 | C25: 杭州宜格化妆品有限公司 | D25: 正常使用 | E25: 小红书 | F25: 自投 | G25: 广东省广告集团股份有限公司 | H25: 内容加热 | I25: https://ad.xiaohongshu.com/ | K25: huaxizi_xhongshu2@163.com | M25: ADV26 | N25: 是 | O25: 是 | P25: 是 | Q25: 是 | R25: 不填 | S25: 否 | T25: 品牌运营中心 | U25: 广告投放部 | V25: 内容投放部 | W25: 甘草 | Y25: 贝果 | Z25: 甘草、清和 | AA25: 账号密码
A26: 站内 | C26: 杭州宜格化妆品有限公司 | D26: 正常使用 | E26: 小红书 | F26: 自投 | G26: 广东省广告集团股份有限公司 | H26: 内容加热 | I26: https://ad.xiaohongshu.com/ | K26: huaxizi_xhongshu4@163.com | M26: ADV28 | N26: 是 | O26: 是 | P26: 是 | Q26: 是 | R26: 不填 | S26: 否 | T26: 品牌运营中心 | U26: 广告投放部 | V26: 内容投放部 | W26: 甘草 | Y26: 贝果 | Z26: 甘草、清和 | AA26: 账号密码
A27: 站内 | C27: 杭州宜格化妆品有限公司 | D27: 正常使用 | E27: 微博 | F27: 自投 | G27: 上海宇枫 | H27: 微博信息流 | I27: https://ad.weibo.com/ | K27: 花西子Florasis | M27: ADV35 | N27: 是 | O27: 是 | P27: 是 | Q27: 否 | S27: 否 | T27: 品牌运营中心 | U27: 广告投放部 | V27: 内容投放部 | W27: 柏倩倩 | Y27: 贝果 | Z27: 柏倩倩 | AA27: 账号密码
A28: 站内 | C28: 杭州宜格化妆品有限公司 | D28: 正常使用 | E28: 抖音 | F28: 自投 | G28: 上海博观瑞思传媒科技有限公司 | H28: DOU+ | I28: https://doujia.douyin.com/ | K28: 花西子官方旗舰店 | M28: ADV36 | N28: 是 | O28: 是 | P28: 否 | Q28: 否 | S28: 是 | T28: 品牌运营中心 | U28: 广告投放部 | V28: 内容投放部 | W28: 柏倩倩 | Y28: 贝果 | Z28: 柏倩倩 | AA28: 账号密码
A29: 站内 | B29: AD信息流 | C29: 杭州宜格化妆品有限公司 | D29: 正常使用 | E29: 抖音-巨量纵横 | F29: 自投 | G29: 广东省广告集团股份有限公司 | H29: 天猫抖音AD引流 | I29: https://ad.oceanengine.com/ | K29: huaxizi_xinxiliuad@163.com | M29: ADV37 | N29: 是 | O29: 是 | P29: 是 | Q29: 是 | R29: 不填 | S29: 是 | T29: 品牌运营中心 | U29: 广告投放部 | V29: 站外投放部 | W29: 白纸、阿布、志文、循安 | Y29: 贝果 | Z29: 白纸、阿布、志文、循安 | AA29: 账号密码
A30: 站内 | B30: AD信息流 | C30: 杭州宜格化妆品有限公司 | D30: 正常使用 | E30: 抖音-巨量纵横 | F30: 自投 | G30: 广东省广告集团股份有限公司 | H30: 天猫抖音AD引流 | I30: https://ad.oceanengine.com/ | K30: huaxizi_xinxiliuad4@163.com | M30: ADV38 | N30: 是 | O30: 是 | P30: 是 | Q30: 是 | R30: 不填 | S30: 是 | T30: 品牌运营中心 | U30: 广告投放部 | V30: 站外投放部 | W30: 白纸、阿布、志文、循安 | Y30: 贝果 | Z30: 白纸、阿布、志文、循安 | AA30: 账号密码
A31: 站内 | B31: AD信息流 | C31: 杭州宜格化妆品有限公司 | D31: 正常使用 | E31: 抖音-巨量纵横 | F31: 自投 | G31: 广东省广告集团股份有限公司 | H31: 天猫抖音AD引流 | I31: https://ad.oceanengine.com/ | K31: huaxizi_xinxliuad5@163.com | M31: ADV39 | N31: 是 | O31: 是 | P31: 是 | Q31: 是 | R31: 不填 | S31: 是 | T31: 品牌运营中心 | U31: 广告投放部 | V31: 站外投放部 | W31: 白纸、阿布、志文、循安 | Y31: 贝果 | Z31: 白纸、阿布、志文、循安 | AA31: 账号密码
A32: 站内 | B32: AD信息流 | C32: 杭州宜格化妆品有限公司 | D32: 正常使用 | E32: 抖音-巨量纵横 | F32: 自投 | G32: 广东省广告集团股份有限公司 | H32: 天猫抖音AD引流 | I32: https://ad.oceanengine.com/ | K32: huaxizi_xinxliuad7@163.com | M32: ADV40 | N32: 是 | O32: 是 | P32: 是 | Q32: 是 | R32: 不填 | S32: 是 | T32: 品牌运营中心 | U32: 广告投放部 | V32: 站外投放部 | W32: 白纸、阿布、志文、循安 | Y32: 贝果 | Z32: 白纸、阿布、志文、循安 | AA32: 账号密码
A33: 站内 | B33: AD信息流 | C33: 杭州宜格化妆品有限公司 | D33: 正常使用 | E33: 抖音-巨量纵横 | F33: 自投 | G33: 广东省广告集团股份有限公司 | H33: 天猫抖音AD引流 | I33: https://ad.oceanengine.com/ | K33: huaxizi_xinxliuad8@163.com | M33: ADV41 | N33: 是 | O33: 是 | P33: 是 | Q33: 是 | R33: 不填 | S33: 是 | T33: 品牌运营中心 | U33: 广告投放部 | V33: 站外投放部 | W33: 白纸、阿布、志文、循安 | Y33: 贝果 | Z33: 白纸、阿布、志文、循安 | AA33: 账号密码
A34: 站内 | B34: AD信息流 | C34: 杭州宜格化妆品有限公司 | D34: 正常使用 | E34: 抖音-巨量纵横 | F34: 自投 | G34: 群邑（上海）广告有限公司 | H34: 天猫抖音AD引流 | I34: https://ad.oceanengine.com/ | K34: huaxizi_xinxliuad9@163.com | M34: ADV42 | N34: 是 | O34: 是 | P34: 是 | Q34: 是 | R34: 不填 | S34: 是 | T34: 品牌运营中心 | U34: 广告投放部 | V34: 站外投放部 | W34: 白纸、阿布、志文、循安 | Y34: 贝果 | Z34: 白纸、阿布、志文、循安 | AA34: 账号密码
A35: 站内 | B35: AD信息流 | C35: 杭州宜格化妆品有限公司 | D35: 正常使用 | E35: 抖音-巨量纵横 | F35: 自投 | G35: 群邑（上海）广告有限公司 | H35: 天猫抖音AD引流 | I35: https://ad.oceanengine.com/ | K35: joy.du@mindshareworld.com | M35: ADV43 | N35: 是 | O35: 是 | P35: 是 | Q35: 是 | R35: 不填 | S35: 是 | T35: 品牌运营中心 | U35: 广告投放部 | V35: 站外投放部 | W35: 白纸、阿布、志文、循安 | Y35: 贝果 | Z35: 白纸、阿布、志文、循安 | AA35: 账号密码
A36: 站内 | B36: UD信息流 | C36: 杭州宜格化妆品有限公司 | D36: 正常使用 | E36: Uni Desk | F36: 自投 | G36: 北京九合互动文化传播有限公司 | H36: UD信息流引流 | I36: https://unidesk.taobao.com/index.html | K36: tb963892057577 | M36: ADV44 | N36: 是 | O36: 是 | P36: 是 | Q36: 是 | R36: 不填 | S36: 是 | T36: 品牌运营中心 | U36: 广告投放部 | V36: 站外投放部 | W36: 白纸、阿布、志文 | Y36: 贝果 | Z36: 白纸、阿布、志文 | AA36: 账号密码
A37: 站内 | C37: 杭州宜格化妆品有限公司 | D37: 正常使用 | E37: 百度营销 | F37: 自投 | G37: 北京云锐国际文化传媒有限公司 | H37: 百度信息流引流 | I37: https://cas.baidu.com/?tpl=www2&fromu=http%3A%2F%2Fwww2.b...ommon%2Fappinit.ajax | K37: 杭州宜格化妆品有限公司1（shvipyr花西子3） | M37: ADV46 | N37: 是 | O37: 是 | P37: 是 | Q37: 是 | R37: 不填 | S37: 是 | T37: 品牌运营中心 | U37: 广告投放部 | V37: 站外投放部 | W37: 白纸、阿布、循安 | Y37: 贝果 | Z37: 白纸、阿布、循安 | AA37: 账号密码
A38: 站内 | C38: 杭州宜格化妆品有限公司 | D38: 正常使用 | E38: 磁力引擎 | F38: 自投 | G38: 北京起量文化传媒有限公司 | H38: 快手信息流引流 | I38: https://ad.e.kuaishou.com/manage?__accountId__=14861051 | K38: 13362198950 | M38: ADV47 | N38: 是 | O38: 是 | P38: 是 | Q38: 是 | R38: 不填 | S38: 是 | T38: 品牌运营中心 | U38: 广告投放部 | V38: 站外投放部 | W38: 白纸、羽阳 | Y38: 贝果 | Z38: 白纸、羽阳 | AA38: 账号密码
A39: 站内 | B39: 磁力金牛 | C39: 杭州宜格化妆品有限公司 | D39: 正常使用 | E39: 磁力金牛 | F39: 自投 | G39: 北京起量文化传媒有限公司 | H39: 快手磁力金牛 | I39: https://niu.e.kuaishou.com/manage?__accountId__=13304454 | K39: 13396586970 | M39: ADV48 | N39: 是 | O39: 是 | P39: 是 | Q39: 是 | R39: 不填 | S39: 是 | T39: 品牌运营中心 | U39: 广告投放部 | V39: 站外投放部 | W39: 白纸、羽阳 | Y39: 贝果 | Z39: 白纸、羽阳 | AA39: 账号密码
A40: 站内 | C40: 杭州宜格化妆品有限公司 | D40: 正常使用 | E40: 腾讯ADQ | F40: 自投 | G40: 群邑（上海）广告有限公司 | H40: 微信渠道投放 | I40: https://ad.qq.com/atlas/23959502/index | K40: 微信扫码登录 | M40: ADV49 | N40: 是 | O40: 是 | P40: 是 | Q40: 是 | R40: 不填 | S40: 是 | T40: 品牌运营中心 | U40: 广告投放部 | V40: 站外投放部 | W40: 白纸 | Y40: 贝果 | Z40: 白纸 | AA40: 账号密码
...

Sheet Sheet9
A1: 营销活动分类 | B1: 营销活动场景 | C1: 编码 | D1: 一级部门 | E1: 二级部门 | F1: 三级部门 | G1: 四级部门
A2: IP明星内容合作 | B2: IP合作 | C2: YXHD01 | D2: 品牌运营中心 | E2: 市场广告推广部 | F2: 市场推广部 | G2: 市场PR组
A3: IP明星内容合作 | B3: 明星差旅 | C3: YXHD02 | D3: 品牌运营中心 | E3: 市场广告推广部 | F3: 市场推广部 | G3: 娱乐营销组
A4: IP明星内容合作 | B4: 明星代言单次合作 | C4: YXHD03 | D4: 品牌运营中心 | E4: 市场广告推广部 | F4: 市场推广部 | G4: 娱乐营销组
A5: IP明星内容合作 | B5: 明星代言合作 | C5: YXHD04 | D5: 品牌运营中心 | E5: 市场广告推广部 | F5: 市场推广部 | G5: 娱乐营销组
A6: IP明星内容合作 | B6: 明星拍摄 | C6: YXHD05 | D6: 品牌运营中心 | E6: 市场广告推广部 | F6: 市场推广部 | G6: 娱乐营销组
A7: IP明星内容合作 | B7: 明星影综营销号 | C7: YXHD06 | D7: 品牌运营中心 | E7: 市场广告推广部 | F7: 市场推广部 | G7: 娱乐营销组
A8: IP明星内容合作 | B8: 明星妆发造 | C8: YXHD07 | D8: 品牌运营中心 | E8: 市场广告推广部 | F8: 市场推广部 | G8: 娱乐营销组
A9: IP明星内容合作 | B9: 明星综艺线下活动 | C9: YXHD08 | D9: 品牌运营中心 | E9: 市场广告推广部 | F9: 市场推广部 | G9: 娱乐营销组
A10: IP明星内容合作 | B10: 影视综艺植入 | C10: YXHD09 | D10: 品牌运营中心 | E10: 市场广告推广部 | F10: 市场推广部 | G10: 娱乐营销组
A11: 其他达人直播 | B11: 抖音直播服务费-抖音其他 | C11: YXHD10 | D11: 品牌运营中心 | E11: 市场广告推广部 | F11: 达播2部
A12: SKA达人 | B12: 抖音直播服务费-抖音其他 | C12: YXHD11 | D12: 品牌运营中心 | E12: 市场广告推广部 | F12: 达播2部
A13: 田恬 | B13: 抖音直播服务费-田恬 | C13: YXHD12 | D13: 品牌运营中心 | E13: 直播运营部 | F13: 达播BD部
A14: 其他达人直播 | B14: 抖音直播服务费-团长计划 | C14: YXHD13 | D14: 品牌运营中心 | E14: 市场广告推广部 | F14: 达播2部
A15: 其他达人直播 | B15: 抖音直播坑位费-抖音其他 | C15: YXHD14 | D15: 品牌运营中心 | E15: 市场广告推广部 | F15: 达播2部
A16: SKA达人 | B16: 抖音直播坑位费-抖音其他 | C16: YXHD15 | D16: 品牌运营中心 | E16: 市场广告推广部 | F16: 达播2部
A17: 田恬 | B17: 抖音直播坑位费-田恬 | C17: YXHD16 | D17: 品牌运营中心 | E17: 直播运营部 | F17: 达播BD部
A18: 其他达人直播 | B18: 抖音直播坑位费-团长计划 | C18: YXHD17 | D18: 品牌运营中心 | E18: 市场广告推广部 | F18: 达播2部
A19: 其他达人直播 | B19: 快手直播服务费 | C19: YXHD18 | D19: 品牌运营中心 | E19: 市场广告推广部 | F19: 达播2部
A20: SKA达人 | B20: 快手直播服务费 | C20: YXHD19 | D20: 品牌运营中心 | E20: 市场广告推广部 | F20: 达播2部
A21: 其他达人直播 | B21: 快手直播坑位费 | C21: YXHD20 | D21: 品牌运营中心 | E21: 市场广告推广部 | F21: 达播2部
A22: SKA达人 | B22: 快手直播坑位费 | C22: YXHD21 | D22: 品牌运营中心 | E22: 市场广告推广部 | F22: 达播2部
... A28: SKA达人 | B28: 天猫直播坑位费-其他 | C28: YXHD27 | D28: 品牌运营中心 | E28: 直播运营部 | F28: 达播BD部
A29: 素材创意制作 | B29: AD竞价内容创意-场地租赁 | C29: YXHD28 | D29: 品牌运营中心 | E29: 市场广告推广部 | F29: 广告投放部 | G29: 内容策划组
A30: 素材创意制作 | B30: AD竞价内容创意-动画制作 | C30: YXHD29 | D30: 品牌运营中心 | E30: 市场广告推广部 | F30: 广告投放部 | G30: 内容策划组
A31: 素材创意制作 | B31: AD竞价内容创意-服化道费 | C31: YXHD30 | D31: 品牌运营中心 | E31: 市场广告推广部 | F31: 广告投放部 | G31: 内容策划组
A32: 素材创意制作 | B32: AD竞价内容创意-建模服务 | C32: YXHD31 | D32: 品牌运营中心 | E32: 市场广告推广部 | F32: 广告投放部 | G32: 内容策划组
A33: 素材创意制作 | B33: AD竞价内容创意-模特服务 | C33: YXHD32 | D33: 品牌运营中心 | E33: 市场广告推广部 | F33: 广告投放部 | G33: 内容策划组
A34: 素材创意制作 | B34: AD竞价内容创意-内容制作 | C34: YXHD33 | D34: 品牌运营中心 | E34: 市场广告推广部 | F34: 广告投放部 | G34: 内容策划组
A35: 素材创意制作 | B35: AD竞价内容创意-拍摄服务 | C35: YXHD34 | D35: 品牌运营中心 | E35: 市场广告推广部 | F35: 广告投放部 | G35: 内容策划组
A36: 素材创意制作 | B36: AD竞价内容创意-拍摄物料 | C36: YXHD35 | D36: 品牌运营中心 | E36: 市场广告推广部 | F36: 广告投放部 | G36: 内容策划组
A37: 素材创意制作 | B37: AD竞价内容创意-设备租赁 | C37: YXHD36 | D37: 品牌运营中心 | E37: 市场广告推广部 | F37: 广告投放部 | G37: 内容策划组
A38: 素材创意制作 | B38: AD竞价内容创意-视频制作 | C38: YXHD37 | D38: 品牌运营中心 | E38: 市场广告推广部 | F38: 广告投放部 | G38: 内容策划组
A39: 素材创意制作 | B39: AD竞价内容创意-图文平面制作 | C39: YXHD38 | D39: 品牌运营中心 | E39: 市场广告推广部 | F39: 广告投放部 | G39: 内容策划组
A40: 素材创意制作 | B40: AD竞价内容创意-舞台场地 | C40: YXHD39 | D40: 品牌运营中心 | E40: 市场广告推广部 | F40: 广告投放部 | G40: 内容策划组
... A77: 内容加热 | B77: 内容热推 | C77: YXHD76 | D77: 品牌运营中心 | E77: 市场广告推广部 | F77: 市场推广部 | G77: 内容投放组
A78: 素材创意制作 | B78: 天猫淘内内容 | C78: YXHD77 | D78: 品牌运营中心 | E78: 直播运营部 | F78: 达播BD部
A79: 内容加热 | B79: 微博粉条 | C79: YXHD78 | D79: 品牌运营中心 | E79: 市场广告推广部 | F79: 市场推广部 | G79: 内容投放组
A80: 内容加热 | B80: 微博搜索 | C80: YXHD79 | D80: 品牌运营中心 | E80: 市场广告推广部 | F80: 市场推广部 | G80: 内容投放组
A81: 内容加热 | B81: 小红书加热 | C81: YXHD80 | D81: 品牌运营中心 | E81: 市场广告推广部 | F81: 市场推广部 | G81: 内容投放组
...

Sheet Sheet10
A1: 店铺 | B1: 抖音号 | C1: 千川账户名称 | D1: 千川账户id
A2: 花西子官方旗舰店 | B2: 花西子官方旗舰店 | C2: 群邑-直播-官号1 | D2: 1727535271575630
C3: 云锐-直播-官号2 | D3: 1727265617683469
C4: 博观-直播-官号1 | D4: 1695557841246222
C5: 省广-直播-官号1 | D5: 1727435690629127
C6: 博观7-花西子-官号 | D6: 1765947662124040
C7: 知定堂-图文1-引流 | D7: 1761146745368653
C8: 博观-图文1-引流 | D8: 1760222811427847
C9: 花西子-小店随心推 | D9: 1695646517812232
B10: 东方有佳人 | C10: 知定堂3户-东方有佳人 | D10: 1766564041175070
C11: 博观4户-东方有佳人 | D11: 1760519144208525
B12: 花西子礼物精选 | C12: 博观5户-礼物精选 | D12: 1761057229537293
B13: 花西子官旗彩妆甄选 | C13: 博观6户-彩妆有术 | D13: 1761057340544014
C14: 博观3户-彩妆有术 | D14: 1760519091540999
B15: 妆养旗舰店 | C15: 知定堂1户-妆养 | D15: 1761153809509390
C16: 省广-矩阵直播-妆养 | D16: 1743277556435982
C17: 知定堂2户-妆养 | D17: 1766309736108040
A20: 投放账户 | B20: 名称 | C20: 业务对接人 | D20: 站内/站外 | E20: 营销活动（可从营销活动sheet页中查看营销活动全集） | F20: 公司主体 | G20: 平台 | H20: 投放方式（自投/代投） | I20: 平台对合作应供应商名称 | J20: 是否存在充值赠送金 | K20: 是否存在返利 | L20: 是否通过此账户申请开票 | M20: 使用中心 | N20: 使用二级部门 | O20: 使用三级部门 | P20: 财务对接人（如有）
A21: 16909143 | B21: 花西子官方旗舰店-群邑2 | C21: 难却 | E21: 磁力金牛 | F21: 杭州宜格化妆品有限公司 | G21: 快手 | H21: 自投 | I21: 群邑（上海）广告有限公司 | J21: 否 | K21: 是 | L21: 否 | M21: 品牌运营中心 | N21: 快手部 | O21: 快手运营推广部
A22: 16909147 | B22: 花西子官方旗舰店-群邑4 | C22: 难却 | E22: 磁力金牛 | F22: 杭州宜格化妆品有限公司 | G22: 快手 | H22: 自投 | I22: 群邑（上海）广告有限公司 | J22: 否 | K22: 是 | L22: 否 | M22: 品牌运营中心 | N22: 快手部 | O22: 快手运营推广部
A23: 16909144 | B23: 花西子官方旗舰店-群邑3 | C23: 难却 | E23: 磁力金牛 | F23: 杭州宜格化妆品有限公司 | G23: 快手 | H23: 自投 | I23: 群邑（上海）广告有限公司 | J23: 否 | K23: 是 | L23: 否 | M23: 品牌运营中心 | N23: 快手部 | O23: 快手运营推广部
A24: 16909146 | B24: 花西子官方旗舰店-全站ROI | C24: 难却 | E24: 磁力金牛 | F24: 杭州宜格化妆品有限公司 | G24: 快手 | H24: 自投 | I24: 群邑（上海）广告有限公司 | J24: 否 | K24: 是 | L24: 否 | M24: 品牌运营中心 | N24: 快手部 | O24: 快手运营推广部
A25: 13304453 | B25: 花西子Florasis-云锐测试 | C25: 难却 | E25: 磁力金牛 | F25: 杭州宜格化妆品有限公司 | G25: 快手 | H25: 自投 | I25: 快手平台 | J25: 否 | K25: 否 | L25: 否 | M25: 品牌运营中心 | N25: 快手部 | O25: 快手运营推广部
A26: 16909148 | B26: 花西子官方旗舰店-返货2户 | C26: 难却 | E26: 磁力金牛 | F26: 杭州宜格化妆品有限公司 | G26: 快手 | H26: 自投 | I26: 快手平台 | J26: 否 | K26: 否 | L26: 否 | M26: 品牌运营中心 | N26: 快手部 | O26: 快手运营推广部
A27: 16481647 | B27: 花西子官方旗舰店（浅度账户） | C27: 难却 | E27: 磁力金牛 | F27: 杭州宜格化妆品有限公司 | G27: 快手 | H27: 自投 | I27: 快手平台 | J27: 否 | K27: 否 | L27: 否 | M27: 品牌运营中心 | N27: 快手部 | O27: 快手运营推广部
A28: 17553440 | B28: 花西子官方旗舰店-直播托管对投-李楠楠 | C28: 难却 | E28: 磁力金牛 | F28: 杭州宜格化妆品有限公司 | G28: 快手 | H28: 自投 | I28: 快手平台 | J28: 否 | K28: 否 | L28: 否 | M28: 品牌运营中心 | N28: 快手部 | O28: 快手运营推广部
A29: 16909145 | B29: 花西子官方旗舰店-群邑-RSH代投 | C29: 难却 | E29: 磁力金牛 | F29: 杭州宜格化妆品有限公司 | G29: 快手 | H29: 自投 | I29: 群邑（上海）广告有限公司 | J29: 否 | K29: 是 | L29: 否 | M29: 品牌运营中心 | N29: 快手部 | O29: 快手运营推广部
A33: 投放账户 | B33: 名称 | C33: 业务对接人 | D33: 站内/站外 | E33: 营销活动（可从营销活动sheet页中查看营销活动全集） | F33: 公司主体 | G33: 平台 | H33: 投放方式（自投/代投） | I33: 平台对合作应供应商名称 | J33: 是否存在充值赠送金 | K33: 是否存在返利 | L33: 是否通过此账户申请开票 | M33: 使用中心 | N33: 使用二级部门 | O33: 使用三级部门 | P33: 财务对接人（如有）
A34: huaxizicai1@eastgarden.com | B34: huaxizicai1@eastgarden.com | C34: 一样 | D34: 站外 | E34: B站起飞加热 | F34: 杭州宜格化妆品有限公司 | G34: B站 | H34: 代投 | I34: 上海小花猫文化传播有限公司 | J34: 是 | K34: 否 | L34: 是 | M34: 品牌运营中心 | N34: 市场推广部 | O34: 内容加热 | P34: 洛一
A35: huaxizicai2@eastgarden.com | B35: huaxizicai2@eastgarden.com | C35: 一样 | D35: 站外 | E35: B站起飞加热 | F35: 杭州宜格化妆品有限公司 | G35: B站 | H35: 代投 | I35: 上海无堂网络科技有限公司 | J35: 是 | K35: 否 | L35: 是 | M35: 品牌运营中心 | N35: 市场推广部 | O35: 内容加热 | P35: 洛一
A36: hxzcaizhuang10@eastgarden.com | B36: hxzcaizhuang10@eastgarden.com | C36: 一样 | D36: 站外 | E36: B站起飞加热 | F36: 杭州宜格化妆品有限公司 | G36: B站 | H36: 代投 | I36: 上海无堂网络科技有限公司 | J36: 是 | K36: 否 | L36: 是 | M36: 品牌运营中心 | N36: 市场推广部 | O36: 内容加热 | P36: 洛一
A37: yige18072932996@163.com | B37: yige18072932996@163.com | C37: 一样 | D37: 无账户 | E37: B站起飞加热 | G37: B站
A38: 263697 | B38: 博观-花西子 | C38: 一样 | D38: 站外 | E38: 小红书加热 | G38: 小红书 | H38: 代投 | I38: 上海博观瑞思传媒科技有限公司 | J38: 无 | K38: 是 | L38: 是 | M38: 品牌运营中心 | N38: 市场推广部 | O38: 内容加热 | P38: 洛一
A39: 283885 | B39: 剧星小红书投放账户 | C39: 一样 | D39: 站外 | E39: 小红书加热 | G39: 小红书 | H39: 代投 | I39: 剧星 | J39: 无 | K39: 是 | L39: 是 | M39: 品牌运营中心 | N39: 市场推广部 | O39: 内容加热 | P39: 洛一
A40: 294814 | B40: 博观-花西子-2 | C40: 一样 | D40: 站外 | E40: 小红书加热 | G40: 小红书 | H40: 代投 | I40: 上海博观瑞思传媒科技有限公司 | J40: 无 | K40: 是 | L40: 是 | M40: 品牌运营中心 | N40: 市场推广部 | O40: 内容加热 | P40: 洛一

Sheet Sheet11
A1: 主键 | B1: 单据编号 | C1: 单据名称 | D1: 创建人[名称] | E1: 使用人[名称] | F1: 业务日期 | G1: 总额 | H1: 总额币种[名称(编码)] | I1: 占用金额 | J1: 占用金额币种[名称(编码)] | K1: 已用金额 | L1: 已用金额币种[名称(编码)] | M1: 还回金额 | N1: 还回金额币种[名称(编码)] | O1: 可用金额 | P1: 可用金额币种[名称(编码)] | Q1: 期初金额 | R1: 期初金额币种[名称(编码)] | S1: 完结状态 | T1: 公司手机号[名称] | U1: 公司邮箱[名称] | V1: 供应商名称[名称] | W1: 投放平台[名称] | X1: 投放账户ID | Y1: 营销活动[名称] | Z1: 充值方式[名称] | AA1: 是否存在充值赠送[名称] | AB1: 是否存在返利[名称] | AC1: 是否做余额管理[名称] | AD1: 是否通过此账户申请开票[名称] | AE1: 数据已全部回收[名称] | AF1: 投放账户已清帐[名称] | AG1: 投放账户状态[名称] | AH1: 业务对接人[名称] | AI1: 财务对接人[名称] | AJ1: 核算主体[名称] | AK1: 数据是否需要回收[名称] | AL1: 是否做过变更[名称] | AM1: 是否存在折扣[名称] | AN1: 投放方式[名称] | AO1: 投放方式生效时间 | AP1: 站内/站外[名称] | AQ1: 充值投放账户 | AR1: 营销活动计划分类[名称] | AS1: 投放账户名称 | AT1: 品牌[名称]
A2: 0317ac13e37b7b5620cd9637bc410001 | D2: ycss02; | G2: 0.00 | I2: 0.00 | K2: 0.00 | M2: 0.00 | O2: 0.00 | Q2: 0.00 | S2: 未完结 | V2: 上海小花猫文化传播有限公司 | W2: 小红书 | X2: 436489 | Y2: 小红书加热 | AA2: 是 | AB2: 是 | AC2: 否 | AD2: 否 | AH2: 一样（谢炀） | AJ2: 杭州宜格化妆品有限公司 | AN2: 自投 | AO2: 36526 | AP2: 站内 | AQ2: 436489 | AS2: 小花猫（花西子Florasis）5 | AT2: 花西子
A3: 0317abf06e8b7b5620cd9637bc410002 | D3: ycss02; | G3: 0.00 | I3: 0.00 | K3: 0.00 | M3: 0.00 | O3: 0.00 | Q3: 0.00 | S3: 未完结 | V3: 上海小花猫文化传播有限公司 | W3: 小红书 | X3: 436491 | Y3: 小红书加热 | AA3: 是 | AB3: 是 | AC3: 否 | AD3: 否 | AH3: 一样（谢炀） | AJ3: 杭州宜格化妆品有限公司 | AN3: 自投 | AO3: 36526 | AP3: 站内 | AQ3: 436491 | AS3: 小花猫（花西子Florasis）4 | AT3: 花西子
A4: 0317a77380fb7b5620cd9637bc410001 | D4: ycss02; | G4: 0.00 | I4: 0.00 | K4: 0.00 | M4: 0.00 | O4: 0.00 | Q4: 0.00 | S4: 未完结 | V4: 湖北巨量引擎科技有限公司 | W4: 抖音 | X4: 1601161499296772 | Y4: DOU+ | AC4: 是 | AJ4: 杭州宜格化妆品有限公司 | AN4: 自投 | AO4: 36526 | AP4: 站内 | AQ4: 1601161499296772 | AS4: 花西子官方旗舰店 | AT4: 花西子
A5: 03156c6a65c21d98ea897767e9600001 | D5: ycss02; | G5: 0.00 | I5: 0.00 | K5: 0.00 | M5: 0.00 | O5: 0.00 | Q5: 0.00 | S5: 未完结 | V5: 江苏拾光宝盒信息技术有限公司 | W5: 小红书 | X5: 117315 | Y5: 小红书加热 | AA5: 是 | AB5: 是 | AC5: 否 | AD5: 否 | AH5: 一样（谢炀） | AJ5: 杭州宜格化妆品有限公司 | AN5: 自投 | AO5: 36526 | AP5: 站内 | AQ5: 117315 | AS5: 拾光宝盒（花西子美妆） | AT5: 花西子
A6: 03156c6a68821d98ea897767e9600001 | D6: ycss02; | G6: 0.00 | I6: 0.00 | K6: 0.00 | M6: 0.00 | O6: 0.00 | Q6: 0.00 | S6: 未完结 | V6: 江苏拾光宝盒信息技术有限公司 | W6: 小红书 | X6: 168640 | Y6: 小红书加热 | AA6: 是 | AB6: 是 | AC6: 否 | AD6: 否 | AH6: 一样（谢炀） | AJ6: 杭州宜格化妆品有限公司 | AN6: 自投 | AO6: 36526 | AP6: 站内 | AQ6: 168640 | AS6: 拾光宝盒（花西子Florasis4） | AT6: 花西子
A7: 03156c6a68e21d98ea897767e9600001 | D7: ycss02; | G7: 0.00 | I7: 0.00 | K7: 0.00 | M7: 0.00 | O7: 0.00 | Q7: 0.00 | S7: 未完结 | V7: 广东省广告集团股份有限公司 | W7: 小红书 | X7: 113409 | Y7: 小红书加热 | AA7: 是 | AB7: 是 | AC7: 否 | AD7: 否 | AH7: 一样（谢炀） | AJ7: 杭州宜格化妆品有限公司 | AN7: 自投 | AO7: 36526 | AP7: 站内 | AQ7: 113409 | AS7: 省广集团（花西子Florasis） | AT7: 花西子
A8: 03156c6a69421d98ea897767e9600001 | D8: ycss02; | G8: 0.00 | I8: 0.00 | K8: 0.00 | M8: 0.00 | O8: 0.00 | Q8: 0.00 | S8: 未完结 | V8: 广东省广告集团股份有限公司 | W8: 小红书 | X8: huaxizi_xhongshu2@163.com | Y8: 小红书加热 | AA8: 是 | AB8: 是 | AC8: 否 | AD8: 否 | AH8: 一样（谢炀） | AJ8: 杭州宜格化妆品有限公司 | AN8: 自投 | AO8: 36526 | AP8: 站内 | AQ8: huaxizi_xhongshu2@163.com | AS8: 省广-美妆 | AT8: 花西子
A9: 03156c6a6b021d98ea897767e9600001 | D9: ycss02; | G9: 0.00 | I9: 0.00 | K9: 0.00 | M9: 0.00 | O9: 0.00 | Q9: 0.00 | S9: 未完结 | V9: 广东省广告集团股份有限公司 | W9: 小红书 | X9: 117993 | Y9: 小红书加热 | AA9: 是 | AB9: 是 | AC9: 否 | AD9: 否 | AH9: 一样（谢炀） | AJ9: 杭州宜格化妆品有限公司 | AN9: 自投 | AO9: 36526 | AP9: 站内 | AQ9: 117993 | AS9: 省广集团（花西子Florasis）02 | AT9: 花西子
A10: 03156c6a6b521d98ea897767e9600001 | D10: ycss02; | G10: 0.00 | I10: 0.00 | K10: 0.00 | M10: 0.00 | O10: 0.00 | Q10: 0.00 | S10: 未完结 | V10: 广东省广告集团股份有限公司 | W10: 小红书 | X10: 117992 | Y10: 小红书加热 | AA10: 是 | AB10: 是 | AC10: 否 | AD10: 否 | AH10: 一样（谢炀） | AJ10: 杭州宜格化妆品有限公司 | AN10: 自投 | AO10: 36526 | AP10: 站内 | AQ10: 117992 | AS10: 省广集团（花西子Florasis）03 | AT10: 花西子
A11: 03156c6a6b921d98ea897767e9600001 | D11: ycss02; | G11: 0.00 | I11: 0.00 | K11: 0.00 | M11: 0.00 | O11: 0.00 | Q11: 0.00 | S11: 未完结 | V11: 江苏拾光宝盒信息技术有限公司 | W11: 小红书 | X11: 119989 | Y11: 小红书加热 | AC11: 否 | AD11: 否 | AH11: 一样（谢炀） | AJ11: 杭州宜格化妆品有限公司 | AN11: 自投 | AO11: 36526 | AP11: 站外 | AQ11: 119989 | AS11: 拾光宝盒（花西子Florasis3） | AT11: 花西子
A12: 03156c6a6c321d98ea897767e9600001 | D12: ycss02; | G12: 0.00 | I12: 0.00 | K12: 0.00 | M12: 0.00 | O12: 0.00 | Q12: 0.00 | S12: 未完结 | V12: 江苏拾光宝盒信息技术有限公司 | W12: 小红书 | X12: 65933 | Y12: 小红书加热 | AC12: 否 | AD12: 否 | AH12: 一样（谢炀） | AJ12: 杭州宜格化妆品有限公司 | AN12: 自投 | AO12: 36526 | AP12: 站外 | AQ12: 65933 | AS12: 拾光宝盒（花西子Florasis） | AT12: 花西子
A13: 03156c6a6c721d98ea897767e9600001 | D13: ycss02; | G13: 0.00 | I13: 0.00 | K13: 0.00 | M13: 0.00 | O13: 0.00 | Q13: 0.00 | S13: 未完结 | V13: 江苏拾光宝盒信息技术有限公司 | W13: 小红书 | X13: 119990 | Y13: 小红书加热 | AC13: 否 | AD13: 否 | AH13: 一样（谢炀） | AJ13: 杭州宜格化妆品有限公司 | AN13: 自投 | AO13: 36526 | AP13: 站外 | AQ13: 119990 | AS13: 拾光宝盒（花西子Florasis2） | AT13: 花西子
A14: 03156c6a6cc21d98ea897767e9600001 | D14: ycss02; | G14: 0.00 | I14: 0.00 | K14: 0.00 | M14: 0.00 | O14: 0.00 | Q14: 0.00 | S14: 未完结 | V14: 上海博观瑞思传媒科技有限公司 | W14: 小红书 | X14: 307497 | Y14: 小红书加热 | AC14: 否 | AD14: 否 | AH14: 一样（谢炀） | AJ14: 杭州宜格化妆品有限公司 | AN14: 自投 | AO14: 36526 | AP14: 站外 | AQ14: 307497 | AS14: 博观-花西子-3 | AT14: 花西子
A15: 03156c6a6d021d98ea897767e9600001 | D15: ycss02; | G15: 0.00 | I15: 0.00 | K15: 0.00 | M15: 0.00 | O15: 0.00 | Q15: 0.00 | S15: 未完结 | V15: 上海剧星传媒股份有限公司 | W15: 小红书 | X15: sd_xx@visionstar.cn | Y15: 小红书加热 | AC15: 否 | AD15: 否 | AH15: 一样（谢炀） | AJ15: 杭州宜格化妆品有限公司 | AN15: 自投 | AO15: 36526 | AP15: 站外 | AQ15: sd_xx@visionstar.cn | AS15: 剧星小红书投放账户 | AT15: 花西子
A16: 03156c6a6d421d98ea897767e9600001 | D16: ycss02; | G16: 0.00 | I16: 0.00 | K16: 0.00 | M16: 0.00 | O16: 0.00 | Q16: 0.00 | S16: 未完结 | V16: 上海博观瑞思传媒科技有限公司 | W16: 小红书 | X16: 263697 | Y16: 小红书加热 | AC16: 否 | AD16: 否 | AH16: 一样（谢炀） | AJ16: 杭州宜格化妆品有限公司 | AN16: 代投 | AO16: 36526 | AP16: 站外 | AQ16: 263697 | AS16: 博观-花西子 | AT16: 花西子
A17: 03156c6a6d921d98ea897767e9600001 | D17: ycss02; | G17: 0.00 | I17: 0.00 | K17: 0.00 | M17: 0.00 | O17: 0.00 | Q17: 0.00 | S17: 未完结 | V17: 上海剧星传媒股份有限公司 | W17: 小红书 | X17: 283885 | Y17: 小红书加热 | AA17: 否 | AB17: 是 | AC17: 否 | AD17: 否 | AH17: 一样（谢炀） | AJ17: 杭州宜格化妆品有限公司 | AN17: 代投 | AO17: 36526 | AP17: 站外 | AQ17: 283885 | AS17: 剧星小红书投放账户 | AT17: 花西子
A18: 03156c6a6dd21d98ea897767e9600002 | D18: ycss02; | G18: 0.00 | I18: 0.00 | K18: 0.00 | M18: 0.00 | O18: 0.00 | Q18: 0.00 | S18: 未完结 | V18: 上海博观瑞思传媒科技有限公司 | W18: 小红书 | X18: 294814 | Y18: 小红书加热 | AA18: 否 | AB18: 是 | AC18: 否 | AD18: 否 | AH18: 一样（谢炀） | AJ18: 杭州宜格化妆品有限公司 | AN18: 代投 | AO18: 36526 | AP18: 站外 | AQ18: 294814 | AS18: 博观-花西子-2 | AT18: 花西子
A19: 03156c6a6e121d98ea897767e9600002 | D19: ycss02; | G19: 0.00 | I19: 0.00 | K19: 0.00 | M19: 0.00 | O19: 0.00 | Q19: 0.00 | S19: 未完结 | V19: 江苏拾光宝盒信息技术有限公司 | W19: 小红书 | X19: 395388 | Y19: 小红书加热 | AA19: 是 | AB19: 是 | AC19: 否 | AD19: 否 | AH19: 一样（谢炀） | AJ19: 杭州宜格化妆品有限公司 | AN19: 自投 | AO19: 36526 | AP19: 站内 | AQ19: 395388 | AS19: 拾光宝盒（花西子Florasis5） | AT19: 花西子
A20: 03156c6a6e621d98ea897767e9600002 | D20: ycss02; | G20: 0.00 | I20: 0.00 | K20: 0.00 | M20: 0.00 | O20: 0.00 | Q20: 0.00 | S20: 未完结 | V20: 江苏拾光宝盒信息技术有限公司 | W20: 小红书 | X20: 395353 | Y20: 小红书加热 | AA20: 是 | AB20: 是 | AC20: 否 | AD20: 否 | AJ20: 杭州宜格化妆品有限公司 | AN20: 自投 | AO20: 36526 | AP20: 站内 | AQ20: 395353 | AS20: 拾光宝盒（花西子Florasis6） | AT20: 花西子
A21: 03156c6a6ef21d98ea897767e9600002 | D21: ycss02; | G21: 0.00 | I21: 0.00 | K21: 0.00 | M21: 0.00 | O21: 0.00 | Q21: 0.00 | S21: 未完结 | V21: 江苏拾光宝盒信息技术有限公司 | W21: 小红书 | X21: 395350 | Y21: 小红书加热 | AA21: 是 | AB21: 是 | AC21: 否 | AD21: 否 | AH21: 一样（谢炀） | AJ21: 杭州宜格化妆品有限公司 | AN21: 自投 | AO21: 36526 | AP21: 站内 | AQ21: 395350 | AS21: 拾光宝盒（花西子Florasis7） | AT21: 花西子
A22: 03156c6a6f421d98ea897767e9600002 | D22: ycss02; | G22: 0.00 | I22: 0.00 | K22: 0.00 | M22: 0.00 | O22: 0.00 | Q22: 0.00 | S22: 未完结 | V22: 江苏拾光宝盒信息技术有限公司 | W22: 小红书 | X22: 409695 | Y22: 小红书加热 | AA22: 是 | AB22: 是 | AC22: 否 | AD22: 否 | AH22: 一样（谢炀） | AJ22: 杭州宜格化妆品有限公司 | AN22: 自投 | AO22: 36526 | AP22: 站内 | AQ22: 409695 | AS22: 拾光宝盒（花西子Florasis8） | AT22: 花西子
A23: 03156c6a6f821d98ea897767e9600002 | D23: ycss02; | G23: 0.00 | I23: 0.00 | K23: 0.00 | M23: 0.00 | O23: 0.00 | Q23: 0.00 | S23: 未完结 | V23: 江苏拾光宝盒信息技术有限公司 | W23: 小红书 | X23: 409688 | Y23: 小红书加热 | AA23: 是 | AB23: 是 | AC23: 否 | AD23: 否 | AH23: 一样（谢炀） | AJ23: 杭州宜格化妆品有限公司 | AN23: 自投 | AO23: 36526 | AP23: 站内 | AQ23: 409688 | AS23: 拾光宝盒（花西子Florasis9） | AT23: 花西子
A24: 03156c6a6fc21d98ea897767e9600002 | D24: ycss02; | G24: 0.00 | I24: 0.00 | K24: 0.00 | M24: 0.00 | O24: 0.00 | Q24: 0.00 | S24: 未完结 | V24: 江苏拾光宝盒信息技术有限公司 | W24: 小红书 | X24: 409687 | Y24: 小红书加热 | AA24: 是 | AB24: 是 | AC24: 否 | AD24: 否 | AH24: 一样（谢炀） | AJ24: 杭州宜格化妆品有限公司 | AN24: 自投 | AO24: 36526 | AP24: 站内 | AQ24: 409687 | AS24: 拾光宝盒（花西子Florasis10） | AT24: 花西子
A25: 03156c6a70021d98ea897767e9600002 | D25: ycss02; | G25: 0.00 | I25: 0.00 | K25: 0.00 | M25: 0.00 | O25: 0.00 | Q25: 0.00 | S25: 未完结 | V25: 广东省广告集团股份有限公司 | W25: 小红书 | X25: 118100 | Y25: 小红书加热 | AA25: 是 | AB25: 是 | AC25: 否 | AD25: 否 | AH25: 一样（谢炀） | AJ25: 杭州宜格化妆品有限公司 | AN25: 自投 | AO25: 36526 | AP25: 站内 | AQ25: 118100 | AS25: 省广集团（花西子美妆）03 | AT25: 花西子
A26: 03156c6a70521d98ea897767e9600000 | D26: ycss02; | G26: 0.00 | I26: 0.00 | K26: 0.00 | M26: 0.00 | O26: 0.00 | Q26: 0.00 | S26: 未完结 | V26: 上海小花猫文化传播有限公司 | W26: 小红书 | X26: 435968 | Y26: 小红书加热 | AA26: 是 | AB26: 是 | AC26: 否 | AD26: 否 | AH26: 一样（谢炀） | AJ26: 杭州宜格化妆品有限公司 | AN26: 自投 | AO26: 36526 | AP26: 站内 | AQ26: 435968 | AS26: 小花猫（花西子Florasis）6 | AT26: 花西子
A27: 03156c6a70921d98ea897767e9600001 | D27: ycss02; | G27: 0.00 | I27: 0.00 | K27: 0.00 | M27: 0.00 | O27: 0.00 | Q27: 0.00 | S27: 未完结 | V27: 上海小花猫文化传播有限公司 | W27: 小红书 | X27: 424140 | Y27: 小红书加热 | AA27: 是 | AB27: 是 | AC27: 否 | AD27: 否 | AH27: 一样（谢炀） | AJ27: 杭州宜格化妆品有限公司 | AN27: 自投 | AO27: 36526 | AP27: 站内 | AQ27: 424140 | AS27: 小花猫（花西子Florasis）3 | AT27: 花西子
A28: 03156c6a70d21d98ea897767e9600001 | D28: ycss02; | G28: 0.00 | I28: 0.00 | K28: 0.00 | M28: 0.00 | O28: 0.00 | Q28: 0.00 | S28: 未完结 | V28: 上海小花猫文化传播有限公司 | W28: 小红书 | X28: 424127 | Y28: 小红书加热 | AA28: 是 | AB28: 是 | AC28: 否 | AD28: 否 | AH28: 一样（谢炀） | AJ28: 杭州宜格化妆品有限公司 | AN28: 自投 | AO28: 36526 | AP28: 站内 | AQ28: 424127 | AS28: xhm_huaxizi02@163.com | AT28: 花西子
A29: 03156c6a71121d98ea897767e9600001 | D29: ycss02; | G29: 0.00 | I29: 0.00 | K29: 0.00 | M29: 0.00 | O29: 0.00 | Q29: 0.00 | S29: 未完结 | V29: 上海小花猫文化传播有限公司 | W29: 小红书 | X29: 424132 | Y29: 小红书加热 | AA29: 是 | AB29: 是 | AC29: 否 | AD29: 否 | AH29: 一样（谢炀） | AJ29: 杭州宜格化妆品有限公司 | AN29: 自投 | AO29: 36526 | AP29: 站内 | AQ29: 424132 | AS29: 小花猫（花西子Florasis）1 | AT29: 花西子
A30: 03156c6a71621d98ea897767e9600001 | D30: ycss02; | G30: 0.00 | I30: 0.00 | K30: 0.00 | M30: 0.00 | O30: 0.00 | Q30: 0.00 | S30: 未完结 | V30: 杭州凡淳品牌管理有限公司 | W30: 小红书 | X30: 433696 | Y30: 小红书加热 | AC30: 否 | AD30: 否 | AH30: 一样（谢炀） | AJ30: 杭州宜格化妆品有限公司 | AN30: 自投 | AO30: 36526 | AP30: 站内 | AQ30: 433696 | AS30: （FC）花西子小黛伞 | AT30: 花西子
A31: 03156c6a71a21d98ea897767e9600001 | D31: ycss02; | G31: 0.00 | I31: 0.00 | K31: 0.00 | M31: 0.00 | O31: 0.00 | Q31: 0.00 | S31: 未完结 | V31: 杭州凡淳品牌管理有限公司 | W31: 小红书 | X31: 436678 | Y31: 小红书加热 | AC31: 否 | AD31: 否 | AH31: 一样（谢炀） | AJ31: 杭州宜格化妆品有限公司 | AN31: 自投 | AO31: 36526 | AP31: 站内 | AQ31: 436678 | AS31: （FC）花西子三花喷雾 | AT31: 花西子
A32: 03156c6a72121d98ea897767e9600001 | D32: ycss02; | G32: 0.00 | I32: 0.00 | K32: 0.00 | M32: 0.00 | O32: 0.00 | Q32: 0.00 | S32: 未完结 | V32: 杭州凡淳品牌管理有限公司 | W32: 小红书 | X32: 423721 | Y32: 小红书加热 | AC32: 否 | AD32: 否 | AH32: 一样（谢炀） | AJ32: 杭州宜格化妆品有限公司 | AN32: 自投 | AO32: 36526 | AP32: 站内 | AQ32: 423721 | AS32: （FC）花西子 | AT32: 花西子
A33: 03147392a8f8ffcff3f0d6cfb2be0002 | D33: ycss02; | G33: 0.00 | I33: 0.00 | K33: 0.00 | M33: 0.00 | O33: 0.00 | Q33: 0.00 | S33: 未完结 | V33: 杭州阿里妈妈软件服务有限公司 | W33: 天猫 | X33: DP015-034 | Y33: 天猫-万相台-常规投放 | AH33: 洛竹（程铭） | AJ33: 杭州宜格化妆品有限公司 | AN33: 自投 | AO33: 36526 | AP33: 站内 | AQ33: 天猫花西子旗舰店-万相台 | AS33: 天猫花西子旗舰店-万相台-会员快 | AT33: 花西子
A34: 03147392aa78ffcff3f0d6cfb2be0002 | D34: ycss02; | G34: 0.00 | I34: 0.00 | K34: 0.00 | M34: 0.00 | O34: 0.00 | Q34: 0.00 | S34: 未完结 | V34: 浙江阿里巴巴通信技术有限公司 | W34: 天猫 | X34: DP001-034 | Y34: 天猫-万相台-常规投放 | AH34: 盐首（刘如敏） | AJ34: 杭州匠泽电子商务有限公司 | AN34: 自投 | AO34: 36526 | AP34: 站内 | AQ34: 天猫花西子旗舰店-万相台 | AS34: 天猫花西子匠泽店-万相台-会员快 | AT34: 花西子
A35: 0314402379c8ffcff3f0d6cfb2be0002 | D35: ycss02; | G35: 0.00 | I35: 0.00 | K35: 0.00 | M35: 0.00 | O35: 0.00 | Q35: 0.00 | S35: 未完结 | V35: 广东省广告集团股份有限公司 | W35: 抖音-巨量纵横 | X35: huaxizi_xinxiliuad4@163.com | Y35: AD信息流 | AA35: 是 | AB35: 是 | AC35: 否 | AD35: 是 | AH35: 白纸（张浩霖） | AJ35: 杭州宜格化妆品有限公司 | AN35: 自投 | AO35: 36526 | AP35: 站外 | AQ35: huaxizi_xinxiliuad4@163.com | AS35: huaxizi_xinxiliuad4@163.com | AT35: 花西子
A36: 031440237ac8ffcff3f0d6cfb2be0002 | D36: ycss02; | G36: 0.00 | I36: 0.00 | K36: 0.00 | M36: 0.00 | O36: 0.00 | Q36: 0.00 | S36: 未完结 | V36: 广东省广告集团股份有限公司 | W36: 抖音-巨量纵横 | X36: huaxizi_xinxliuad5@163.com | Y36: AD信息流 | AA36: 是 | AB36: 是 | AC36: 否 | AD36: 是 | AH36: 白纸（张浩霖） | AJ36: 杭州宜格化妆品有限公司 | AN36: 自投 | AO36: 36526 | AP36: 站外 | AQ36: huaxizi_xinxliuad5@163.com | AS36: huaxizi_xinxliuad5@163.com | AT36: 花西子
A37: 031440237bb8ffcff3f0d6cfb2be0002 | D37: ycss02; | G37: 0.00 | I37: 0.00 | K37: 0.00 | M37: 0.00 | O37: 0.00 | Q37: 0.00 | S37: 未完结 | V37: 广东省广告集团股份有限公司 | W37: 抖音-巨量纵横 | X37: huaxizi_xinxliuad7@163.com | Y37: AD信息流 | AA37: 是 | AB37: 是 | AC37: 否 | AD37: 是 | AH37: 白纸（张浩霖） | AJ37: 杭州宜格化妆品有限公司 | AN37: 自投 | AO37: 36526 | AP37: 站外 | AQ37: huaxizi_xinxliuad7@163.com | AS37: huaxizi_xinxliuad7@163.com | AT37: 花西子
A38: 031440237cb8ffcff3f0d6cfb2be0002 | D38: ycss02; | G38: 0.00 | I38: 0.00 | K38: 0.00 | M38: 0.00 | O38: 0.00 | Q38: 0.00 | S38: 未完结 | V38: 广东省广告集团股份有限公司 | W38: 抖音-巨量纵横 | X38: huaxizi_xinxliuad8@163.com | Y38: AD信息流 | AA38: 是 | AB38: 是 | AC38: 否 | AD38: 是 | AH38: 白纸（张浩霖） | AJ38: 杭州宜格化妆品有限公司 | AN38: 自投 | AO38: 36526 | AP38: 站外 | AQ38: huaxizi_xinxliuad8@163.com | AS38: huaxizi_xinxliuad8@163.com | AT38: 花西子
