Workbook

Sheet 费用类型
A1: 费用类型编码 | B1: 费用类型 | C1: 费用大类编码 | D1: 费用大类 | E1: 费用小类编码 | F1: 费用小类
A2: FY01 | B2: 营销费用 | C2: FY0101 | D2: 达人推广费 | E2: FY010101 | F2: 内容推广费 | G2: 销售费用_营销费用_内容制作费(6601.36.14)
E3: FY010102 | F3: 达人合作费 | G3: 销售费用_营销费用_达人发布费(6601.36.04)
E4: FY010103 | F4: 达人推广佣金 | G4: 销售费用_营销费用_推广服务费(6601.36.23)
C5: FY0102 | D5: 店铺运营费 | E5: FY010201 | F5: 店铺服务费
E6: FY010202 | F6: 快递拦截费
E7: FY010203 | F7: 代收保险费
E8: FY010204 | F8: 支付服务费
E9: FY010205 | F9: 平台技术服务费
E10: FY010206 | F10: 支付手续费
E11: FY010207 | F11: 平台软件费
E12: FY010208 | F12: 短信服务费
C13: FY0103 | D13: 媒介宣传费 | E13: FY010301 | F13: 线上媒介费 | G13: 销售费用_营销费用_线上推广费(6601.36.24)
E14: FY010302 | F14: 线下媒介费 | G14: 销售费用_营销费用_线下推广费(6601.36.25)
E15: FY010303 | F15: 媒体宣发费 | G15: 销售费用_营销费用_线上推广费(6601.36.24)
C16: FY0104 | D16: 内容制作费 | E16: FY010401 | F16: 视频制作费 | G16: 销售费用_营销费用_视频制作费(6601.36.21)
E17: FY010402 | F17: 动画制作费 | G17: 销售费用_营销费用_动画制作费(6601.36.07)
E18: FY010403 | F18: 图文平面制作费 | G18: 销售费用_营销费用_图文平面制作费(6601.36.22)
E19: FY010404 | F19: 建模服务费 | G19: 销售费用_营销费用_建模服务费(6601.36.10)
E20: FY010405 | F20: 渲染服务费 | G20: 销售费用_营销费用_渲染服务费(6601.36.26)
E21: FY010406 | F21: 模特服务费 | G21: 销售费用_营销费用_模特服务费(6601.36.13)
E22: FY010407 | F22: 专业人物合作费 | G22: 销售费用_营销费用_专业人物合作费(6601.36.32)
E23: FY010408 | F23: 服化道费用 | G23: 销售费用_营销费用_服化道费用(6601.36.08)
E24: FY010409 | F24: 拍摄服务费 | G24: 销售费用_营销费用_拍摄服务费(6601.36.15)
E25: FY010410 | F25: 拍摄物料费 | G25: 销售费用_营销费用_拍摄物料费(6601.36.16)
E26: FY010411 | F26: 内容制作费 | G26: 销售费用_营销费用_内容制作费(6601.36.14)
E27: FY010412 | F27: 视觉设计费 | G27: 销售费用_营销费用_视觉设计费(6601.36.42)
C28: FY0105 | D28: 品牌宣传费 | E28: FY010501 | F28: 市场调研费 | G28: 销售费用_营销费用_市场调研费(6601.36.20)
E29: FY010502 | F29: 明星合作费 | G29: 销售费用_营销费用_明星合作费(6601.36.12)
E30: FY010503 | F30: 创意策划服务费 | G30: 销售费用_营销费用_策划服务费(6601.36.01)
E31: FY010504 | F31: 活动策划服务费 | G31: 销售费用_营销费用_策划服务费(6601.36.01)
E32: FY010505 | F32: 营销宣传费 | G32: 销售费用_营销费用_营销宣传费(6601.36.27)
E33: FY010506 | F33: 品牌植入费 | G33: 销售费用_营销费用_品牌植入费(6601.36.17)
E34: FY010507 | F34: 公关服务费 | G34: 销售费用_营销费用_公关服务费(6601.36.36)
C35: FY0106 | D35: 其他费用 | E35: FY010601 | F35: 场地租赁费 | G35: 销售费用_营销费用_场地租赁费(6601.36.02)
E36: FY010602 | F36: 设备租赁费 | G36: 销售费用_营销费用_设备租赁费(6601.36.19)
E37: FY010603 | F37: 舞台场地搭建费 | G37: 销售费用_营销费用_搭建服务费(6601.36.03)
E38: FY010604 | F38: 日常营运费用 | G38: 暂未上线
E39: FY010605 | F39: 明星差旅费 | G39: 暂未上线
E40: FY010606 | F40: 公关礼品费 | G40: 销售费用_营销费用_公关礼品费(6601.36.09)
...

Sheet 映射
A1: *源维度-业财-费用类型[名称(编码)] | B1: *目标维度-核算科目[名称(编码)] | C1: 默认值[名称(编码)] | F1: 编码 | G1: 默认值[名称(编码)]
A2: 内容推广费(FY010101) | B2: 销售费用_营销费用_内容制作费(6601.36.14) | C2: 销售费用_营销费用_内容制作费(6601.36.14) | F2: FY010101 | G2: 销售费用_营销费用_内容制作费(6601.36.14)
A3: 达人合作费(FY010102) | B3: 销售费用_营销费用_达人发布费(6601.36.04) | C3: 销售费用_营销费用_达人发布费(6601.36.04) | F3: FY010102 | G3: 销售费用_营销费用_达人发布费(6601.36.04)
A4: 达人推广佣金(FY010103) | B4: 销售费用_营销费用_推广服务费(6601.36.23) | C4: 销售费用_营销费用_推广服务费(6601.36.23) | F4: FY010103 | G4: 销售费用_营销费用_推广服务费(6601.36.23)
A5: 线上媒介费(FY010301) | B5: 销售费用_营销费用_线上推广费(6601.36.24) | C5: 销售费用_营销费用_线上推广费(6601.36.24) | F5: FY010301 | G5: 销售费用_营销费用_线上推广费(6601.36.24)
A6: 线下媒介费(FY010302) | B6: 销售费用_营销费用_线下推广费(6601.36.25) | C6: 销售费用_营销费用_线下推广费(6601.36.25) | F6: FY010302 | G6: 销售费用_营销费用_线下推广费(6601.36.25)
A7: 媒体宣发费(FY010303) | B7: 销售费用_营销费用_线上推广费(6601.36.24) | C7: 销售费用_营销费用_线上推广费(6601.36.24) | F7: FY010303 | G7: 销售费用_营销费用_线上推广费(6601.36.24)
A8: 视频制作费(FY010401) | B8: 销售费用_营销费用_视频制作费(6601.36.21) | C8: 销售费用_营销费用_视频制作费(6601.36.21) | F8: FY010401 | G8: 销售费用_营销费用_视频制作费(6601.36.21)
A9: 动画制作费(FY010402) | B9: 销售费用_营销费用_动画制作费(6601.36.07) | C9: 销售费用_营销费用_动画制作费(6601.36.07) | F9: FY010402 | G9: 销售费用_营销费用_动画制作费(6601.36.07)
A10: 图文平面制作费(FY010403) | B10: 销售费用_营销费用_图文平面制作费(6601.36.22) | C10: 销售费用_营销费用_图文平面制作费(6601.36.22) | F10: FY010403 | G10: 销售费用_营销费用_图文平面制作费(6601.36.22)
A11: 建模服务费(FY010404) | B11: 销售费用_营销费用_建模服务费(6601.36.10) | C11: 销售费用_营销费用_建模服务费(6601.36.10) | F11: FY010404 | G11: 销售费用_营销费用_建模服务费(6601.36.10)
A12: 渲染服务费(FY010405) | B12: 销售费用_营销费用_渲染服务费(6601.36.26) | C12: 销售费用_营销费用_渲染服务费(6601.36.26) | F12: FY010405 | G12: 销售费用_营销费用_渲染服务费(6601.36.26)
... A41: 咨询服务费（FY010611） | B41: 销售费用_营销费用_咨询服务费(6601.36.41) | C41: 销售费用_营销费用_咨询服务费(6601.36.41) | F41: FY010611 | G41: 销售费用_营销费用_咨询服务费(6601.36.41)

Sheet 基础信息
A1: 字段 | B1: 字段类别 | C1: 字段解释 | D1: 用途与诉求
A2: 费用大类 | B2: 下拉-单选
A3: 费用大类编码 | B3: 文本
A4: 费用小类 | B4: 下拉-单选
A5: 费用小类编码 | B5: 文本
A6: 发票类目建议 | B6: 下拉-多选

Sheet 枚举值
A1: 字段 | B1: 是否必填 | C1: 枚举值Code | D1: 枚举值 | E1: 外键 | F1: 备注说明 | G1: 经分是否需要 | H1: 经分是否需要业务处理 | I1: 经分处理逻辑
A2: 费用大类 | B2: Y | C2: 01 | E2: NA | F2: 枚举值说明 | G2: Y | H2: Y
C3: 02
C4: 03
C5: 04
C6: 05
A7: 费用小类 | E7: 费用大类编码

Sheet 费用大小类列表
A1: 序号 | B1: 费用大类 | C1: 费用小类 | D1: 费用类别 | E1: 营销活动场景 | F1: 一级预算科目 | G1: 二级预算科目 | H1: 一级部门 | I1: 二级部门 | J1: 三级部门 | K1: 四级部门 | L1: 会计科目（新） | M1: 科目编码（新） | N1: 是否允许无票 | O1: 发票类目建议 | P1: 费控系统表单字段要求 | V1: 财务入账科目字段要求
P2: 项目 | Q2: 一级部门 | R2: 二级部门 | S2: 品牌 | T2: 店铺 | U2: 广宣 | V2: 项目 | W2: 一级部门 | X2: 二级部门 | Y2: 品牌 | Z2: 店铺 | AA2: 广宣
A3: =ROW(B3)-2 | B3: 媒介宣传费 | C3: 线上媒介费 | D3: 营销费用 | E3: 抖音品牌信息流 | F3: 品牌媒介 | G3: 线上品宣媒介 | H3: 品牌运营中心 | I3: 市场广告推广部 | J3: 广告投放部 | K3: 媒介部 | L3: 销售费用_营销费用_线上推广费 | M3: 6601.36.24 | O3: 技术服务费？服务费？
A4: =ROW(B4)-2 | B4: 媒介宣传费 | C4: 线上媒介费 | D4: 营销费用 | E4: 快手品牌信息流 | F4: 品牌媒介 | G4: 线上品宣媒介 | H4: 品牌运营中心 | I4: 市场广告推广部 | J4: 广告投放部 | K4: 媒介部 | L4: 销售费用_营销费用_线上推广费 | M4: 6601.36.24
A5: =ROW(B5)-2 | B5: 媒介宣传费 | C5: 线上媒介费 | D5: 营销费用 | E5: 开屏类广告 | F5: 品牌媒介 | G5: 线上品宣媒介 | H5: 品牌运营中心 | I5: 市场广告推广部 | J5: 广告投放部 | K5: 媒介部 | L5: 销售费用_营销费用_线上推广费 | M5: 6601.36.24 | O5: 广告发布费
A6: =ROW(B6)-2 | B6: 媒介宣传费 | C6: 线上媒介费 | D6: 营销费用 | E6: 程序化投放 | F6: 品牌媒介 | G6: 线上品宣媒介 | H6: 品牌运营中心 | I6: 市场广告推广部 | J6: 广告投放部 | K6: 媒介部 | L6: 销售费用_营销费用_线上推广费 | M6: 6601.36.24 | O6: 广告发布费
A7: =ROW(B7)-2 | B7: 媒介宣传费 | C7: 线上媒介费 | D7: 营销费用 | E7: OTT广告 | F7: 品牌媒介 | G7: 线上品宣媒介 | H7: 品牌运营中心 | I7: 市场广告推广部 | J7: 广告投放部 | K7: 媒介部 | L7: 销售费用_营销费用_线上推广费 | M7: 6601.36.24 | O7: 广告发布费
A8: =ROW(B8)-2 | B8: 媒介宣传费 | C8: 线上媒介费 | D8: 营销费用 | E8: OTV广告 | F8: 品牌媒介 | G8: 线上品宣媒介 | H8: 品牌运营中心 | I8: 市场广告推广部 | J8: 广告投放部 | K8: 媒介部 | L8: 销售费用_营销费用_线上推广费 | M8: 6601.36.24 | O8: 广告发布费
A9: =ROW(B9)-2 | B9: 媒介宣传费 | C9: 线上媒介费 | D9: 营销费用 | E9: 商业化资源包合作 | F9: 品牌媒介 | G9: 线上品宣媒介 | H9: 品牌运营中心 | I9: 市场广告推广部 | J9: 广告投放部 | K9: 媒介部 | L9: 销售费用_营销费用_线上推广费 | M9: 6601.36.24 | O9: 广告发布费
A10: =ROW(B10)-2 | B10: 媒介宣传费 | C10: 线上媒介费 | D10: 营销费用 | E10: 广告效果监测 | F10: 品牌媒介 | G10: 线上品宣媒介 | H10: 品牌运营中心 | I10: 市场广告推广部 | J10: 广告投放部 | K10: 媒介部 | L10: 销售费用_营销费用_线上推广费 | M10: 6601.36.24 | O10: 广告发布费
A11: =ROW(B11)-2 | B11: 媒介宣传费 | C11: 线下媒介费 | D11: 营销费用 | E11: 电梯广告 | F11: 品牌媒介 | G11: 线下品宣媒介 | H11: 品牌运营中心 | I11: 市场广告推广部 | J11: 广告投放部 | K11: 媒介部 | L11: 销售费用_营销费用_线下推广费 | M11: 6601.36.25 | O11: 广告发布费
A12: =ROW(B12)-2 | B12: 媒介宣传费 | C12: 线下媒介费 | D12: 营销费用 | E12: 电影院广告 | F12: 品牌媒介 | G12: 线下品宣媒介 | H12: 品牌运营中心 | I12: 市场广告推广部 | J12: 广告投放部 | K12: 媒介部 | L12: 销售费用_营销费用_线下推广费 | M12: 6601.36.25 | O12: 广告发布费
A13: =ROW(B13)-2 | B13: 媒介宣传费 | C13: 线下媒介费 | D13: 营销费用 | E13: 地标广告 | F13: 品牌媒介 | G13: 线下品宣媒介 | H13: 品牌运营中心 | I13: 市场广告推广部 | J13: 广告投放部 | K13: 媒介部 | L13: 销售费用_营销费用_线下推广费 | M13: 6601.36.25 | O13: 广告发布费
A14: =ROW(B14)-2 | B14: 品牌宣传费 | C14: 市场调研费 | D14: 营销费用 | E14: 投放策略调研 | F14: 品牌媒介 | G14: 调研费（其他非标） | H14: 品牌运营中心 | I14: 市场广告推广部 | J14: 策略部 | L14: ="销售费用_"&D14&"_"&C14 | M14: 6601.36.20 | O14: 调研服务费
A15: =ROW(B15)-2 | B15: 内容制作费 | C15: 视频制作费 | D15: 营销费用 | E15: =G15&"-"&LEFT(C15,4) | F15: 品类内容推广 | G15: AD竞价内容创意 | H15: 品牌运营中心 | I15: 市场广告推广部 | J15: 广告投放部 | K15: 内容策划组 | L15: ="销售费用_"&D15&"_"&C15 | M15: 6601.36.21 | O15: =C15
A16: =ROW(B16)-2 | B16: 内容制作费 | C16: 动画制作费 | D16: 营销费用 | E16: =G16&"-"&LEFT(C16,4) | F16: 品类内容推广 | G16: AD竞价内容创意 | H16: 品牌运营中心 | I16: 市场广告推广部 | J16: 广告投放部 | K16: 内容策划组 | L16: ="销售费用_"&D16&"_"&C16 | M16: 6601.36.07 | O16: =C16
A17: =ROW(B17)-2 | B17: 内容制作费 | C17: 图文平面制作费 | D17: 营销费用 | E17: =G17&"-"&LEFT(C17,6) | F17: 品类内容推广 | G17: AD竞价内容创意 | H17: 品牌运营中心 | I17: 市场广告推广部 | J17: 广告投放部 | K17: 内容策划组 | L17: ="销售费用_"&D17&"_"&C17 | M17: 6601.36.22 | O17: =C17
A18: =ROW(B18)-2 | B18: 内容制作费 | C18: 建模服务费 | D18: 营销费用 | E18: =G18&"-"&LEFT(C18,4) | F18: 品类内容推广 | G18: AD竞价内容创意 | H18: 品牌运营中心 | I18: 市场广告推广部 | J18: 广告投放部 | K18: 内容策划组 | L18: ="销售费用_"&D18&"_"&C18 | M18: 6601.36.10 | O18: =C18
A19: =ROW(B19)-2 | B19: 内容制作费 | C19: 渲染服务费 | D19: 营销费用 | E19: =G19&"-"&LEFT(C19,4) | F19: 品类内容推广 | G19: AD竞价内容创意 | H19: 品牌运营中心 | I19: 市场广告推广部 | J19: 广告投放部 | K19: 内容策划组 | L19: ="销售费用_"&D19&"_"&C19 | M19: 6601.36.26 | O19: =C19
A20: =ROW(B20)-2 | B20: 内容制作费 | C20: 模特服务费 | D20: 营销费用 | E20: =G20&"-"&LEFT(C20,4) | F20: 品类内容推广 | G20: AD竞价内容创意 | H20: 品牌运营中心 | I20: 市场广告推广部 | J20: 广告投放部 | K20: 内容策划组 | L20: ="销售费用_"&D20&"_"&C20 | M20: 6601.36.13 | O20: =C20
A21: =ROW(B21)-2 | B21: 内容制作费 | C21: 专业人物合作费 | D21: 营销费用 | E21: =G21&"-"&LEFT(C21,6) | F21: 品类内容推广 | G21: AD竞价内容创意 | H21: 品牌运营中心 | I21: 市场广告推广部 | J21: 广告投放部 | K21: 内容策划组 | L21: ="销售费用_"&D21&"_"&C21 | M21: 6601.36.32 | O21: =C21
A22: =ROW(B22)-2 | B22: 内容制作费 | C22: 服化道费用 | D22: 营销费用 | E22: =G22&"-"&LEFT(C22,4) | F22: 品类内容推广 | G22: AD竞价内容创意 | H22: 品牌运营中心 | I22: 市场广告推广部 | J22: 广告投放部 | K22: 内容策划组 | L22: ="销售费用_"&D22&"_"&C22 | M22: 6601.36.08 | O22: 服装费、化妆费、道具费
A23: =ROW(B23)-2 | B23: 内容制作费 | C23: 拍摄服务费 | D23: 营销费用 | E23: =G23&"-"&LEFT(C23,4) | F23: 品类内容推广 | G23: AD竞价内容创意 | H23: 品牌运营中心 | I23: 市场广告推广部 | J23: 广告投放部 | K23: 内容策划组 | L23: ="销售费用_"&D23&"_"&C23 | M23: 6601.36.15 | O23: =C23
A24: =ROW(B24)-2 | B24: 内容制作费 | C24: 拍摄物料费 | D24: 营销费用 | E24: =G24&"-"&LEFT(C24,4) | F24: 品类内容推广 | G24: AD竞价内容创意 | H24: 品牌运营中心 | I24: 市场广告推广部 | J24: 广告投放部 | K24: 内容策划组 | L24: ="销售费用_"&D24&"_"&C24 | M24: 6601.36.16 | O24: =C24
A25: =ROW(B25)-2 | B25: 内容制作费 | C25: 内容制作费 | D25: 营销费用 | E25: =G25&"-"&LEFT(C25,4) | F25: 品类内容推广 | G25: AD竞价内容创意 | H25: 品牌运营中心 | I25: 市场广告推广部 | J25: 广告投放部 | K25: 内容策划组 | L25: ="销售费用_"&D25&"_"&C25 | M25: 6601.36.14 | O25: =C25
A26: =ROW(B26)-2 | B26: 达人推广费 | C26: 内容推广费 | D26: 营销费用 | E26: DOU+ | F26: 品类内容推广 | G26: 内容加热 | H26: 品牌运营中心 | I26: 市场广告推广部 | J26: 市场推广部 | K26: 内容投放组 | L26: 销售费用_营销费用_线上推广费 | M26: 6601.36.24 | O26: 技术服务费？服务费？
A27: =ROW(B27)-2 | B27: 达人推广费 | C27: 内容推广费 | D27: 营销费用 | E27: 快手作品推荐 | F27: 品类内容推广 | G27: 内容加热 | H27: 品牌运营中心 | I27: 市场广告推广部 | J27: 市场推广部 | K27: 内容投放组 | L27: 销售费用_营销费用_线上推广费 | M27: 6601.36.24 | O27: 技术服务费？服务费？
A28: =ROW(B28)-2 | B28: 达人推广费 | C28: 内容推广费 | D28: 营销费用 | E28: 内容热推 | F28: 品类内容推广 | G28: 内容加热 | H28: 品牌运营中心 | I28: 市场广告推广部 | J28: 市场推广部 | K28: 内容投放组 | L28: 销售费用_营销费用_线上推广费 | M28: 6601.36.24 | O28: 技术服务费？服务费？
A29: =ROW(B29)-2 | B29: 达人推广费 | C29: 内容推广费 | D29: 营销费用 | E29: 内容服务 | F29: 品类内容推广 | G29: 内容加热 | H29: 品牌运营中心 | I29: 市场广告推广部 | J29: 市场推广部 | K29: 内容投放组 | L29: 销售费用_营销费用_线上推广费 | M29: 6601.36.24 | O29: 技术服务费？服务费？
A30: =ROW(B30)-2 | B30: 达人推广费 | C30: 内容推广费 | D30: 营销费用 | E30: 星聚力 | F30: 品类内容推广 | G30: 内容加热 | H30: 品牌运营中心 | I30: 市场广告推广部 | J30: 市场推广部 | K30: 内容投放组 | L30: 销售费用_营销费用_线上推广费 | M30: 6601.36.24 | O30: 技术服务费？服务费？
A31: =ROW(B31)-2 | B31: 达人推广费 | C31: 内容推广费 | D31: 营销费用 | E31: 小红书加热 | F31: 品类内容推广 | G31: 其他新媒体加热 | H31: 品牌运营中心 | I31: 市场广告推广部 | J31: 市场推广部 | K31: 内容投放组 | L31: 销售费用_营销费用_线上推广费 | M31: 6601.36.24 | O31: 技术服务费？服务费？
A32: =ROW(B32)-2 | B32: 达人推广费 | C32: 内容推广费 | D32: 营销费用 | E32: B站起飞加热 | F32: 品类内容推广 | G32: 其他新媒体加热 | H32: 品牌运营中心 | I32: 市场广告推广部 | J32: 市场推广部 | K32: 内容投放组 | L32: 销售费用_营销费用_线上推广费 | M32: 6601.36.24 | O32: 技术服务费？服务费？
A33: =ROW(B33)-2 | B33: 达人推广费 | C33: 内容推广费 | D33: 营销费用 | E33: 微博粉条 | F33: 品类内容推广 | G33: 其他新媒体加热 | H33: 品牌运营中心 | I33: 市场广告推广部 | J33: 市场推广部 | K33: 内容投放组 | L33: 销售费用_营销费用_线上推广费 | M33: 6601.36.24 | O33: 技术服务费？服务费？
A34: =ROW(B34)-2 | B34: 达人推广费 | C34: 内容推广费 | D34: 营销费用 | E34: 粉丝通 | F34: 品类内容推广 | G34: 其他新媒体加热 | H34: 品牌运营中心 | I34: 市场广告推广部 | J34: 市场推广部 | K34: 内容投放组 | L34: 销售费用_营销费用_线上推广费 | M34: 6601.36.24 | O34: 技术服务费？服务费？
A35: =ROW(B35)-2 | B35: 达人推广费 | C35: 内容推广费 | D35: 营销费用 | E35: 微博搜索 | F35: 品类内容推广 | G35: 其他新媒体加热 | H35: 品牌运营中心 | I35: 市场广告推广部 | J35: 市场推广部 | K35: 内容投放组 | L35: 销售费用_营销费用_线上推广费 | M35: 6601.36.24 | O35: 技术服务费？服务费？
A36: =ROW(B36)-2 | B36: 渠道推广费 | C36: 站内推广费 | D36: 营销费用 | E36: 天猫-直通车 | F36: 平台电商推广 | G36: 淘内-推广 | H36: 品牌运营中心 | I36: 运营策略部 | J36: 天猫运营部 | K36: 天猫推广组 | L36: 销售费用_营销费用_线上推广费 | M36: 6601.36.24 | O36: 技术服务费？服务费？
A37: =ROW(B37)-2 | B37: 渠道推广费 | C37: 站内推广费 | D37: 营销费用 | E37: 天猫-引力魔方 | F37: 平台电商推广 | G37: 淘内-推广 | H37: 品牌运营中心 | I37: 运营策略部 | J37: 天猫运营部 | K37: 天猫推广组 | L37: 销售费用_营销费用_线上推广费 | M37: 6601.36.24 | O37: 技术服务费？服务费？
... A58: =ROW(B58)-2 | B58: 渠道推广费 | C58: 站内推广费 | D58: 营销费用 | E58: 京东POP-联合活动 | F58: 平台电商推广 | G58: 京东渠道推广（POP） | H58: 品牌运营中心 | I58: 渠道运营部 | J58: 特色电商部 | K58: 京东唯品推广组 | L58: 销售费用_营销费用_线上推广费 | M58: 6601.36.24 | O58: 技术服务费？服务费？广告费？
A59: =ROW(B59)-2 | B59: 品牌宣传费 | C59: 明星合作费 | D59: 营销费用 | E59: =G59 | F59: 品牌项目 | G59: 日常-创意与物料 | H59: 品牌产品中心 | I59: 品牌营销部 | L59: 销售费用_营销费用_明星合作费 | M59: 6601.36.12 | O59: 代言费 | P59: Y
A60: =ROW(B60)-2 | B60: 渠道推广费 | C60: 站内推广费 | D60: 营销费用 | E60: 唯品会-唯品常规投放 | F60: 平台电商推广 | G60: 唯品渠道推广 | H60: 品牌运营中心 | I60: 渠道运营部 | J60: 特色电商部 | K60: 京东唯品推广组 | L60: 销售费用_营销费用_线上推广费 | M60: 6601.36.24 | O60: 技术服务费？服务费？
...

Sheet 允许个人垫付费用项
A1: 费用大类 | B1: 费用小类 | C1: 费用类别 | D1: 费用小类编码 | E1: 费用大类编码
A2: 内容制作费 | B2: 视频制作费 | C2: 营销费用 | D2: =VLOOKUP(B2,'收集数据表'!C:D,2,0) | E2: =VLOOKUP(A2,'收集数据表'!A:B,2,0)
A3: 内容制作费 | B3: 动画制作费 | C3: 营销费用 | D3: =VLOOKUP(B3,'收集数据表'!C:D,2,0) | E3: =VLOOKUP(A3,'收集数据表'!A:B,2,0)
A4: 内容制作费 | B4: 图文平面制作费 | C4: 营销费用 | D4: =VLOOKUP(B4,'收集数据表'!C:D,2,0) | E4: =VLOOKUP(A4,'收集数据表'!A:B,2,0)
A5: 内容制作费 | B5: 建模服务费 | C5: 营销费用 | D5: =VLOOKUP(B5,'收集数据表'!C:D,2,0) | E5: =VLOOKUP(A5,'收集数据表'!A:B,2,0)
A6: 内容制作费 | B6: 渲染服务费 | C6: 营销费用 | D6: =VLOOKUP(B6,'收集数据表'!C:D,2,0) | E6: =VLOOKUP(A6,'收集数据表'!A:B,2,0)
A7: 内容制作费 | B7: 模特服务费 | C7: 营销费用 | D7: =VLOOKUP(B7,'收集数据表'!C:D,2,0) | E7: =VLOOKUP(A7,'收集数据表'!A:B,2,0)
A8: 内容制作费 | B8: 专业人物合作费 | C8: 营销费用 | D8: =VLOOKUP(B8,'收集数据表'!C:D,2,0) | E8: =VLOOKUP(A8,'收集数据表'!A:B,2,0)
A9: 内容制作费 | B9: 服化道费用 | C9: 营销费用 | D9: =VLOOKUP(B9,'收集数据表'!C:D,2,0) | E9: =VLOOKUP(A9,'收集数据表'!A:B,2,0)
A10: 内容制作费 | B10: 拍摄服务费 | C10: 营销费用 | D10: =VLOOKUP(B10,'收集数据表'!C:D,2,0) | E10: =VLOOKUP(A10,'收集数据表'!A:B,2,0)
A11: 内容制作费 | B11: 拍摄物料费 | C11: 营销费用 | D11: =VLOOKUP(B11,'收集数据表'!C:D,2,0) | E11: =VLOOKUP(A11,'收集数据表'!A:B,2,0)
A12: 内容制作费 | B12: 内容制作费 | C12: 营销费用 | D12: =VLOOKUP(B12,'收集数据表'!C:D,2,0) | E12: =VLOOKUP(A12,'收集数据表'!A:B,2,0)
A13: 其他费用 | B13: 场地租赁费 | C13: 营销费用 | D13: =VLOOKUP(B13,'收集数据表'!C:D,2,0) | E13: =VLOOKUP(A13,'收集数据表'!A:B,2,0)
... A26: 其他费用 | B26: 主播团队激励 | C26: 营销费用 | D26: =VLOOKUP(B26,'收集数据表'!C:D,2,0) | E26: =VLOOKUP(A26,'收集数据表'!A:B,2,0)

Sheet Sheet8
A1: FY010101 | B1: 销售费用_营销费用_内容制作费(6601.36.14)
A2: FY010102 | B2: 销售费用_营销费用_达人发布费(6601.36.04)
A3: FY010103 | B3: 销售费用_营销费用_推广服务费(6601.36.23)
A4: FY010301 | B4: 销售费用_营销费用_线上推广费(6601.36.24)
A5: FY010302 | B5: 销售费用_营销费用_线下推广费(6601.36.25)
A6: FY010303 | B6: 销售费用_营销费用_线上推广费(6601.36.24)
A7: FY010401 | B7: 销售费用_营销费用_视频制作费(6601.36.21)
A8: FY010402 | B8: 销售费用_营销费用_动画制作费(6601.36.07)
A9: FY010403 | B9: 销售费用_营销费用_图文平面制作费(6601.36.22)
A10: FY010404 | B10: 销售费用_营销费用_建模服务费(6601.36.10)
A11: FY010405 | B11: 销售费用_营销费用_渲染服务费(6601.36.26)
A12: FY010406 | B12: 销售费用_营销费用_模特服务费(6601.36.13)
... A40: FY010611 | B40: 销售费用_营销费用_咨询服务费(6601.36.41)

Sheet 收集数据表
A1: 费用大类 | B1: 费用大类编码 | C1: 费用小类 | D1: 费用小类编码 | E1: 费用类别 | F1: 费用类别编码 | G1: 核算科目
A2: 达人推广费 | B2: FY0101 | C2: 内容推广费 | D2: FY010101 | E2: =VLOOKUP(A2,'费用大小类列表'!B3:D288,3,FALSE) | F2: FY01 | G2: =VLOOKUP(D2,'映射'!$F$2:$G$39,2,FALSE)
A3: 达人推广费 | B3: FY0101 | C3: 达人合作费 | D3: FY010102 | E3: =VLOOKUP(A3,'费用大小类列表'!B4:D289,3,FALSE) | F3: FY01 | G3: =VLOOKUP(D3,'映射'!$F$2:$G$39,2,FALSE)
A4: 达人推广费 | B4: FY0101 | C4: 达人推广佣金 | D4: FY010103 | E4: =VLOOKUP(A4,'费用大小类列表'!B5:D290,3,FALSE) | F4: FY01 | G4: =VLOOKUP(D4,'映射'!$F$2:$G$39,2,FALSE)
A5: 店铺运营费 | B5: FY0102 | C5: 店铺服务费 | D5: FY010201 | E5: =VLOOKUP(A5,'费用大小类列表'!B6:D291,3,FALSE) | F5: FY01 | G5: =VLOOKUP(D5,'映射'!$F$2:$G$39,2,FALSE)
A6: 店铺运营费 | B6: FY0102 | C6: 快递拦截费 | D6: FY010202 | E6: =VLOOKUP(A6,'费用大小类列表'!B7:D292,3,FALSE) | F6: FY01 | G6: =VLOOKUP(D6,'映射'!$F$2:$G$39,2,FALSE)
A7: 店铺运营费 | B7: FY0102 | C7: 代收保险费 | D7: FY010203 | E7: =VLOOKUP(A7,'费用大小类列表'!B8:D293,3,FALSE) | F7: FY01 | G7: =VLOOKUP(D7,'映射'!$F$2:$G$39,2,FALSE)
A8: 店铺运营费 | B8: FY0102 | C8: 支付服务费 | D8: FY010204 | E8: =VLOOKUP(A8,'费用大小类列表'!B9:D294,3,FALSE) | F8: FY01 | G8: =VLOOKUP(D8,'映射'!$F$2:$G$39,2,FALSE)
A9: 店铺运营费 | B9: FY0102 | C9: 平台技术服务费 | D9: FY010205 | E9: =VLOOKUP(A9,'费用大小类列表'!B10:D295,3,FALSE) | F9: FY01 | G9: =VLOOKUP(D9,'映射'!$F$2:$G$39,2,FALSE)
A10: 店铺运营费 | B10: FY0102 | C10: 支付手续费 | D10: FY010206 | E10: =VLOOKUP(A10,'费用大小类列表'!B11:D296,3,FALSE) | F10: FY01 | G10: =VLOOKUP(D10,'映射'!$F$2:$G$39,2,FALSE)
A11: 店铺运营费 | B11: FY0102 | C11: 平台软件费 | D11: FY010207 | E11: =VLOOKUP(A11,'费用大小类列表'!B12:D297,3,FALSE) | F11: FY01 | G11: =VLOOKUP(D11,'映射'!$F$2:$G$39,2,FALSE)
A12: 媒介宣传费 | B12: FY0103 | C12: 线上媒介费 | D12: FY010301 | E12: =VLOOKUP(A12,'费用大小类列表'!B13:D298,3,FALSE) | F12: FY01 | G12: =VLOOKUP(D12,'映射'!$F$2:$G$39,2,FALSE)
A13: 媒介宣传费 | B13: FY0103 | C13: 线下媒介费 | D13: FY010302 | E13: =VLOOKUP(A13,'费用大小类列表'!B14:D299,3,FALSE) | F13: FY01 | G13: =VLOOKUP(D13,'映射'!$F$2:$G$39,2,FALSE)
... A44: 其他费用 | B44: FY0106 | C44: 竞品采买 | D44: FY010609 | E44: =VLOOKUP(A44,'费用大小类列表'!B45:D330,3,FALSE) | F44: FY01 | G44: =VLOOKUP(D44,'映射'!$F$2:$G$39,2,FALSE)
A45: 其他费用 | B45: FY0106 | C45: 授权使用费 | D45: FY010610
A46: 其他费用 | B46: FY0106 | C46: 咨询服务费 | D46: FY010611
A47: 渠道推广费 | B47: FY0107 | C47: 站内推广费 | D47: FY010701 | E47: =VLOOKUP(A47,'费用大小类列表'!B45:D330,3,FALSE) | F47: FY01 | G47: =VLOOKUP(D47,'映射'!$F$2:$G$39,2,FALSE)
A48: 渠道推广费 | B48: FY0107 | C48: 站外推广费 | D48: FY010702 | E48: =VLOOKUP(A48,'费用大小类列表'!B46:D331,3,FALSE) | F48: FY01 | G48: =VLOOKUP(D48,'映射'!$F$2:$G$39,2,FALSE)
A49: 渠道推广费 | B49: FY0107 | C49: 代运营服务费 | D49: FY010703 | E49: =VLOOKUP(A49,'费用大小类列表'!B47:D332,3,FALSE) | F49: FY01 | G49: =VLOOKUP(D49,'映射'!$F$2:$G$39,2,FALSE)
A50: 渠道推广费 | B50: FY0107 | C50: 直播服务费 | D50: FY010704 | E50: =VLOOKUP(A50,'费用大小类列表'!B48:D333,3,FALSE) | F50: FY01 | G50: =VLOOKUP(D50,'映射'!$F$2:$G$39,2,FALSE)
A51: 渠道推广费 | B51: FY0107 | C51: 直播坑位费 | D51: FY010705 | E51: =VLOOKUP(A51,'费用大小类列表'!B49:D334,3,FALSE) | F51: FY01 | G51: =VLOOKUP(D51,'映射'!$F$2:$G$39,2,FALSE)
A52: 渠道推广费 | B52: FY0107 | C52: 线下推广费 | D52: FY010706 | E52: =VLOOKUP(A52,'费用大小类列表'!B50:D335,3,FALSE) | F52: FY01 | G52: =VLOOKUP(D52,'映射'!$F$2:$G$39,2,FALSE)
A53: 渠道推广费 | B53: FY0107 | C53: 代运营佣金 | D53: FY010707 | E53: =VLOOKUP(A53,'费用大小类列表'!B51:D336,3,FALSE) | F53: FY01 | G53: =VLOOKUP(D53,'映射'!$F$2:$G$39,2,FALSE)
A54: 渠道推广费 | B54: FY0107 | C54: 直播间物料费 | D54: FY010708 | E54: =VLOOKUP(A54,'费用大小类列表'!B52:D337,3,FALSE) | F54: FY01 | G54: =VLOOKUP(D54,'映射'!$F$2:$G$39,2,FALSE)
A55: 渠道推广费 | B55: FY0107 | C55: 直播间活动费 | D55: FY010709 | E55: =VLOOKUP(A55,'费用大小类列表'!B53:D338,3,FALSE) | F55: FY01 | G55: =VLOOKUP(D55,'映射'!$F$2:$G$39,2,FALSE)
