Workbook

Sheet 营销活动7.7
A1: 营销活动分类 | B1: 编码 | C1: 营销活动 | D1: 一级预算科目 | E1: 二级预算科目 | F1: 状态 | G1: 能否到店铺 | H1: 店铺 | I1: 店铺编码 | J1: 渠道 | K1: 业务来源 | L1: 业务单元 | M1: 能否到品类（单品简称） | N1: 能否到SKU | O1: 是否允许个人报销 | P1: 是否允许无票报销 | Q1: 费用类型 | R1: 费用大类 | S1: 费用小类 | T1: 一级部门 | U1: 二级部门 | V1: 三级部门 | W1: 四级部门 | X1: 核算科目
A2: IP明星内容合作 | B2: YXHD01 | C2: IP合作 | D2: IP明星内容合作 | E2: 品牌IP及娱乐营销 | F2: 启用 | G2: 否 | M2: 否 | N2: 否 | O2: 否 | P2: 否 | Q2: 营销费用 | R2: 品牌宣传费 | S2: 创意策划服务费 | T2: 品牌运营中心 | U2: 市场广告推广部 | V2: 市场推广部 | W2: 市场PR组
A3: IP明星内容合作 | B3: YXHD02 | C3: 明星差旅 | D3: IP明星内容合作 | E3: 明星差旅 | F3: 启用 | G3: 否 | M3: 否 | N3: 否 | O3: 是 | P3: 是 | Q3: 营销费用 | R3: 其他费用 | S3: 明星差旅费 | T3: 品牌运营中心 | U3: 市场广告推广部 | V3: 市场推广部 | W3: 娱乐营销组
A4: IP明星内容合作 | B4: YXHD03 | C4: 明星代言单次合作 | D4: IP明星内容合作 | E4: 明星代言单次 | F4: 启用 | G4: 否 | M4: 否 | N4: 否 | O4: 否 | P4: 否 | Q4: 营销费用 | R4: 品牌宣传费 | S4: 明星合作费 | T4: 品牌运营中心 | U4: 市场广告推广部 | V4: 市场推广部 | W4: 娱乐营销组
A5: IP明星内容合作 | B5: YXHD04 | C5: 明星代言合作 | D5: IP明星内容合作 | E5: 明星代言摊销 | F5: 启用 | G5: 否 | M5: 否 | N5: 否 | O5: 否 | P5: 否 | Q5: 营销费用 | R5: 品牌宣传费 | S5: 明星合作费 | T5: 品牌运营中心 | U5: 市场广告推广部 | V5: 市场推广部 | W5: 娱乐营销组
A6: IP明星内容合作 | B6: YXHD05 | C6: 明星拍摄 | D6: IP明星内容合作 | E6: 明星拍摄 | F6: 启用 | G6: 否 | M6: 否 | N6: 否 | O6: 是 | P6: 是 | Q6: 营销费用 | R6: 其他费用 | S6: 场地租赁费 | T6: 品牌运营中心 | U6: 市场广告推广部 | V6: 市场推广部 | W6: 娱乐营销组
A7: IP明星内容合作 | B7: YXHD06 | C7: 明星影综营销号 | D7: IP明星内容合作 | E7: 品牌IP及娱乐营销 | F7: 启用 | G7: 否 | M7: 否 | N7: 否 | O7: 否 | P7: 否 | Q7: 营销费用 | R7: 品牌宣传费 | S7: 营销宣传费 | T7: 品牌运营中心 | U7: 市场广告推广部 | V7: 市场推广部 | W7: 娱乐营销组
A8: IP明星内容合作 | B8: YXHD07 | C8: 明星妆发造 | D8: IP明星内容合作 | E8: 明星妆发造 | F8: 启用 | G8: 否 | M8: 否 | N8: 否 | O8: 是 | P8: 是 | Q8: 营销费用 | R8: 内容制作费 | S8: 服化道费用 | T8: 品牌运营中心 | U8: 市场广告推广部 | V8: 市场推广部 | W8: 娱乐营销组
A9: IP明星内容合作 | B9: YXHD08 | C9: 明星综艺线下活动 | D9: IP明星内容合作 | E9: 明星代言单次 | F9: 启用 | G9: 否 | M9: 否 | N9: 否 | O9: 否 | P9: 否 | Q9: 营销费用 | R9: 品牌宣传费 | S9: 创意策划服务费 | T9: 品牌运营中心 | U9: 市场广告推广部 | V9: 市场推广部 | W9: 娱乐营销组
A10: IP明星内容合作 | B10: YXHD09 | C10: 影视综艺植入 | D10: IP明星内容合作 | E10: 品牌IP及娱乐营销 | F10: 启用 | G10: 否 | M10: 否 | N10: 否 | O10: 否 | P10: 否 | Q10: 营销费用 | R10: 品牌宣传费 | S10: 品牌植入费 | T10: 品牌运营中心 | U10: 市场广告推广部 | V10: 市场推广部 | W10: 娱乐营销组
A11: 其他达人直播 | B11: YXHD10 | C11: 抖音直播服务费-抖音其他 | D11: 达人直播 | E11: 佣金-抖音其他 | F11: 启用 | G11: 是 | H11: 抖音花西子旗舰店 | I11: DP007 | J11: 抖音 | K11: 达播-其他 | L11: 达播-其他 | M11: 是 | N11: 否 | O11: 否 | P11: 否 | Q11: 营销费用 | R11: 渠道推广费 | S11: 直播服务费 | T11: 品牌运营中心 | U11: 市场广告推广部 | V11: 达播2部
A12: 田恬 | B12: YXHD12 | C12: 抖音直播服务费-田恬 | E12: 佣金-田恬 | F12: 启用 | G12: 是 | H12: 抖音花西子旗舰店 | I12: DP007 | J12: 抖音 | K12: 达播-田恬 | L12: 达播-田恬 | M12: 是 | N12: 是 | O12: 否 | P12: 否 | Q12: 营销费用 | R12: 渠道推广费 | S12: 直播服务费 | T12: 品牌运营中心 | U12: 直播运营部 | V12: SKA达播部
A13: 其他达人直播 | B13: YXHD13 | C13: 抖音直播服务费-团长计划 | D13: 达人直播 | E13: 佣金-团长计划 | F13: 启用 | G13: 是 | H13: 抖音花西子旗舰店 | I13: DP007 | J13: 抖音 | K13: 达播-其他 | L13: 达播-其他 | M13: 是 | N13: 否 | O13: 否 | P13: 否 | Q13: 营销费用 | R13: 渠道推广费 | S13: 直播服务费 | T13: 品牌运营中心 | U13: 市场广告推广部 | V13: 达播2部
A14: 其他达人直播 | B14: YXHD14 | C14: 抖音直播坑位费-抖音其他 | D14: 达人直播 | E14: 服务费-抖音其他 | F14: 启用 | G14: 是 | H14: 抖音花西子旗舰店 | I14: DP007 | J14: 抖音 | K14: 达播-其他 | L14: 达播-其他 | M14: 否 | N14: 否 | O14: 否 | P14: 否 | Q14: 营销费用 | R14: 渠道推广费 | S14: 直播坑位费 | T14: 品牌运营中心 | U14: 市场广告推广部 | V14: 达播2部
A15: 田恬 | B15: YXHD16 | C15: 抖音直播坑位费-田恬 | D15: 达人直播 | E15: 服务费-田恬 | F15: 启用 | G15: 是 | H15: 抖音花西子旗舰店 | I15: DP007 | J15: 抖音 | K15: 达播-田恬 | L15: 达播-田恬 | M15: 否 | N15: 否 | O15: 否 | P15: 否 | Q15: 营销费用 | R15: 渠道推广费 | S15: 直播坑位费 | T15: 品牌运营中心 | U15: 直播运营部 | V15: SKA达播部
A16: 其他达人直播 | B16: YXHD17 | C16: 抖音直播坑位费-团长计划 | D16: 达人直播 | E16: 服务费-团长计划 | F16: 启用 | G16: 是 | H16: 抖音花西子旗舰店 | I16: DP007 | J16: 抖音 | K16: 达播-其他 | L16: 达播-其他 | M16: 否 | N16: 否 | O16: 否 | P16: 否 | Q16: 营销费用 | R16: 渠道推广费 | S16: 直播坑位费 | T16: 品牌运营中心 | U16: 市场广告推广部 | V16: 达播2部
A17: 其他达人直播 | B17: YXHD18 | C17: 快手直播服务费 | D17: 达人直播 | E17: 佣金-快手 | F17: 启用 | G17: 是 | H17: 快手花西子旗舰店 | I17: DP031 | J17: 快手 | K17: 快手达播 | L17: 快手达播 | M17: 是 | N17: 是 | O17: 否 | P17: 否 | Q17: 营销费用 | R17: 渠道推广费 | S17: 直播服务费 | T17: 品牌运营中心 | U17: 市场广告推广部 | V17: 达播2部
A18: 其他达人直播 | B18: YXHD20 | C18: 快手直播坑位费 | D18: 达人直播 | E18: 服务费-快手 | F18: 启用 | G18: 是 | H18: 快手花西子旗舰店 | I18: DP031 | J18: 快手 | K18: 快手达播 | L18: 快手达播 | M18: 否 | N18: 否 | O18: 否 | P18: 否 | Q18: 营销费用 | R18: 渠道推广费 | S18: 直播坑位费 | T18: 品牌运营中心 | U18: 市场广告推广部 | V18: 达播2部
A19: 李佳琦 | B19: YXHD22 | C19: 天猫直播服务费-李佳琦 | D19: 达人直播 | E19: 佣金-佳琦 | F19: 启用 | G19: 是 | H19: 天猫花西子旗舰店 | I19: DP015 | J19: 天猫 | K19: 天猫达播-LJQ | L19: 天猫达播-LJQ | M19: 是 | N19: 是 | O19: 否 | P19: 否 | Q19: 营销费用 | R19: 渠道推广费 | S19: 直播服务费 | T19: 品牌运营中心 | U19: 直播运营部 | V19: SKA达播部
A20: 其他达人直播 | B20: YXHD23 | C20: 天猫直播服务费-其他 | D20: 达人直播 | E20: 佣金-淘内其他 | F20: 启用 | G20: 是 | H20: 天猫花西子旗舰店 | I20: DP015 | J20: 天猫 | K20: 天猫达播-其他 | L20: 天猫达播-其他 | M20: 是 | N20: 是 | O20: 否 | P20: 否 | Q20: 营销费用 | R20: 渠道推广费 | S20: 直播服务费 | T20: 品牌运营中心 | U20: 市场广告推广部 | V20: 达播2部
A21: 李佳琦 | B21: YXHD25 | C21: 天猫直播坑位费-李佳琦 | D21: 达人直播 | E21: 服务费-佳琦 | F21: 启用 | G21: 是 | H21: 天猫花西子旗舰店 | I21: DP015 | J21: 天猫 | K21: 天猫达播-LJQ | L21: 天猫达播-LJQ | M21: 否 | N21: 否 | O21: 否 | P21: 否 | Q21: 营销费用 | R21: 渠道推广费 | S21: 直播坑位费 | T21: 品牌运营中心 | U21: 直播运营部 | V21: SKA达播部
A22: 其他达人直播 | B22: YXHD26 | C22: 天猫直播坑位费-其他 | D22: 达人直播 | E22: 服务费-淘内其他 | F22: 启用 | G22: 是 | H22: 天猫花西子旗舰店 | I22: DP015 | J22: 天猫 | K22: 天猫达播-其他 | L22: 天猫达播-其他 | M22: 否 | N22: 否 | O22: 否 | P22: 否 | Q22: 营销费用 | R22: 渠道推广费 | S22: 直播坑位费 | T22: 品牌运营中心 | U22: 市场广告推广部 | V22: 达播2部
A23: 素材创意制作 | B23: YXHD28 | C23: AD竞价内容创意-场地租赁 | D23: 品类内容推广 | E23: AD竞价内容创意 | F23: 启用 | G23: 否 | M23: 否 | N23: 否 | O23: 是 | P23: 是 | Q23: 营销费用 | R23: 其他费用 | S23: 场地租赁费 | T23: 品牌运营中心 | U23: 市场广告推广部 | V23: 广告投放部 | W23: 内容策划组
A24: 素材创意制作 | B24: YXHD29 | C24: AD竞价内容创意-动画制作 | D24: 品类内容推广 | E24: AD竞价内容创意 | F24: 启用 | G24: 否 | M24: 否 | N24: 否 | O24: 是 | P24: 是 | Q24: 营销费用 | R24: 内容制作费 | S24: 动画制作费 | T24: 品牌运营中心 | U24: 市场广告推广部 | V24: 广告投放部 | W24: 内容策划组
A25: 素材创意制作 | B25: YXHD30 | C25: AD竞价内容创意-服化道费 | D25: 品类内容推广 | E25: AD竞价内容创意 | F25: 启用 | G25: 否 | M25: 否 | N25: 否 | O25: 是 | P25: 是 | Q25: 营销费用 | R25: 内容制作费 | S25: 服化道费用 | T25: 品牌运营中心 | U25: 市场广告推广部 | V25: 广告投放部 | W25: 内容策划组
A26: 素材创意制作 | B26: YXHD31 | C26: AD竞价内容创意-建模服务 | D26: 品类内容推广 | E26: AD竞价内容创意 | F26: 启用 | G26: 否 | M26: 否 | N26: 否 | O26: 是 | P26: 是 | Q26: 营销费用 | R26: 内容制作费 | S26: 建模服务费 | T26: 品牌运营中心 | U26: 市场广告推广部 | V26: 广告投放部 | W26: 内容策划组
A27: 素材创意制作 | B27: YXHD32 | C27: AD竞价内容创意-模特服务 | D27: 品类内容推广 | E27: AD竞价内容创意 | F27: 启用 | G27: 否 | M27: 否 | N27: 否 | O27: 是 | P27: 是 | Q27: 营销费用 | R27: 内容制作费 | S27: 模特服务费 | T27: 品牌运营中心 | U27: 市场广告推广部 | V27: 广告投放部 | W27: 内容策划组
A28: 素材创意制作 | B28: YXHD33 | C28: AD竞价内容创意-内容制作 | D28: 品类内容推广 | E28: AD竞价内容创意 | F28: 启用 | G28: 否 | M28: 否 | N28: 否 | O28: 是 | P28: 是 | Q28: 营销费用 | R28: 内容制作费 | S28: 内容制作费 | T28: 品牌运营中心 | U28: 市场广告推广部 | V28: 广告投放部 | W28: 内容策划组
A29: 素材创意制作 | B29: YXHD34 | C29: AD竞价内容创意-拍摄服务 | D29: 品类内容推广 | E29: AD竞价内容创意 | F29: 启用 | G29: 否 | M29: 否 | N29: 否 | O29: 是 | P29: 是 | Q29: 营销费用 | R29: 内容制作费 | S29: 拍摄服务费 | T29: 品牌运营中心 | U29: 市场广告推广部 | V29: 广告投放部 | W29: 内容策划组
A30: 素材创意制作 | B30: YXHD35 | C30: AD竞价内容创意-拍摄物料 | D30: 品类内容推广 | E30: AD竞价内容创意 | F30: 启用 | G30: 否 | M30: 否 | N30: 否 | O30: 是 | P30: 是 | Q30: 营销费用 | R30: 内容制作费 | S30: 拍摄物料费 | T30: 品牌运营中心 | U30: 市场广告推广部 | V30: 广告投放部 | W30: 内容策划组
A31: 素材创意制作 | B31: YXHD36 | C31: AD竞价内容创意-设备租赁 | D31: 品类内容推广 | E31: AD竞价内容创意 | F31: 启用 | G31: 否 | M31: 否 | N31: 否 | O31: 是 | P31: 是 | Q31: 营销费用 | R31: 其他费用 | S31: 设备租赁费 | T31: 品牌运营中心 | U31: 市场广告推广部 | V31: 广告投放部 | W31: 内容策划组
A32: 素材创意制作 | B32: YXHD37 | C32: AD竞价内容创意-视频制作 | D32: 品类内容推广 | E32: AD竞价内容创意 | F32: 启用 | G32: 否 | M32: 否 | N32: 否 | O32: 是 | P32: 是 | Q32: 营销费用 | R32: 内容制作费 | S32: 视频制作费 | T32: 品牌运营中心 | U32: 市场广告推广部 | V32: 广告投放部 | W32: 内容策划组
A33: 素材创意制作 | B33: YXHD38 | C33: AD竞价内容创意-图文平面制作 | D33: 品类内容推广 | E33: AD竞价内容创意 | F33: 启用 | G33: 否 | M33: 否 | N33: 否 | O33: 是 | P33: 是 | Q33: 营销费用 | R33: 内容制作费 | S33: 图文平面制作费 | T33: 品牌运营中心 | U33: 市场广告推广部 | V33: 广告投放部 | W33: 内容策划组
A34: 素材创意制作 | B34: YXHD39 | C34: AD竞价内容创意-舞台场地 | D34: 品类内容推广 | E34: AD竞价内容创意 | F34: 启用 | G34: 否 | M34: 否 | N34: 否 | O34: 是 | P34: 是 | Q34: 营销费用 | R34: 其他费用 | S34: 舞台场地搭建费 | T34: 品牌运营中心 | U34: 市场广告推广部 | V34: 广告投放部 | W34: 内容策划组
... A38: 内容加热 | B38: YXHD43 | C38: DOU+ | D38: 品类内容推广 | E38: 内容加热 | F38: 启用 | G38: 否 | M38: 否 | N38: 否 | O38: 否 | P38: 否 | Q38: 营销费用 | R38: 达人推广费 | S38: 内容推广费 | T38: 品牌运营中心 | U38: 市场广告推广部 | V38: 市场推广部 | W38: 内容投放组
A39: 素材创意制作 | B39: YXHD44 | C39: 抖音视频创意-店铺-场地租赁 | D39: 品类内容推广 | E39: 抖音视频创意-店铺 | F39: 启用 | G39: 是 | H39: 抖音花西子旗舰店 | I39: DP007 | J39: 抖音 | K39: 抖音自播 | L39: 抖音自播 | M39: 否 | N39: 否 | O39: 是 | P39: 是 | Q39: 营销费用 | R39: 其他费用 | S39: 场地租赁费 | T39: 品牌运营中心 | U39: 内容电商部 | V39: 抖音部 | W39: 内容部
A40: 素材创意制作 | B40: YXHD45 | C40: 抖音视频创意-店铺-动画制作 | D40: 品类内容推广 | E40: 抖音视频创意-店铺 | F40: 启用 | G40: 是 | H40: 抖音花西子旗舰店 | I40: DP007 | J40: 抖音 | K40: 抖音自播 | L40: 抖音自播 | M40: 否 | N40: 否 | O40: 是 | P40: 是 | Q40: 营销费用 | R40: 内容制作费 | S40: 动画制作费 | T40: 品牌运营中心 | U40: 内容电商部 | V40: 抖音部 | W40: 内容部
A41: 素材创意制作 | B41: YXHD46 | C41: 抖音视频创意-店铺-服化道费 | D41: 品类内容推广 | E41: 抖音视频创意-店铺 | F41: 启用 | G41: 是 | H41: 抖音花西子旗舰店 | I41: DP007 | J41: 抖音 | K41: 抖音自播 | L41: 抖音自播 | M41: 否 | N41: 否 | O41: 是 | P41: 是 | Q41: 营销费用 | R41: 内容制作费 | S41: 服化道费用 | T41: 品牌运营中心 | U41: 内容电商部 | V41: 抖音部 | W41: 内容部
A42: 素材创意制作 | B42: YXHD47 | C42: 抖音视频创意-店铺-建模服务 | D42: 品类内容推广 | E42: 抖音视频创意-店铺 | F42: 启用 | G42: 是 | H42: 抖音花西子旗舰店 | I42: DP007 | J42: 抖音 | K42: 抖音自播 | L42: 抖音自播 | M42: 否 | N42: 否 | O42: 是 | P42: 是 | Q42: 营销费用 | R42: 内容制作费 | S42: 建模服务费 | T42: 品牌运营中心 | U42: 内容电商部 | V42: 抖音部 | W42: 内容部
A43: 素材创意制作 | B43: YXHD48 | C43: 抖音视频创意-店铺-模特服务 | D43: 品类内容推广 | E43: 抖音视频创意-店铺 | F43: 启用 | G43: 是 | H43: 抖音花西子旗舰店 | I43: DP007 | J43: 抖音 | K43: 抖音自播 | L43: 抖音自播 | M43: 否 | N43: 否 | O43: 是 | P43: 是 | Q43: 营销费用 | R43: 内容制作费 | S43: 模特服务费 | T43: 品牌运营中心 | U43: 内容电商部 | V43: 抖音部 | W43: 内容部
...

Sheet 营销活动计划分类
A1: 营销活动计划分类 | B1: 编码
A2: IP明星内容合作 | B2: HDFL01
A3: 其他达人直播 | B3: HDFL02
A4: SKA达人 | B4: HDFL03
A5: 田恬 | B5: HDFL04
A6: 李佳琦 | B6: HDFL05
A7: 素材创意制作 | B7: HDFL06
A8: 内容加热 | B8: HDFL07
A9: 线上品宣 | B9: HDFL08
A10: 线下品宣 | B10: HDFL09
A11: IMC国妆 | B11: HDFL10
A12: IMC花养 | B12: HDFL11
... A44: GWP外采 | B44: HDFL43

Sheet 待确认
A1: 营销活动分类 | B1: 营销活动场景 | C1: 编码 | D1: 一级预算科目 | E1: 二级预算科目 | F1: 能否到店铺 | G1: 店铺 | I1: 渠道 | J1: 业务来源 | K1: 业务单元 | L1: 能否到品类（单品简称） | M1: 能否到SKU | N1: 是否允许个人报销 | O1: 是否允许无票报销 | P1: 费用类型 | Q1: 费用大类 | R1: 费用小类 | S1: 一级部门 | T1: 二级部门 | U1: 三级部门 | V1: 四级部门
A2: 平台与媒介公关费 | E2: 市场公关运营 | F2: 否 | L2: 否 | M2: 否 | N2: 是 | O2: 是 | P2: 营销费用 | Q2: 其他费用 | R2: 公关礼品费 | S2: 品牌运营中心 | T2: 渠道运营部
A3: 平台与媒介公关费 | E3: 市场公关运营 | F3: 否 | L3: 否 | M3: 否 | N3: 是 | O3: 是 | P3: 营销费用 | Q3: 其他费用 | R3: 公关礼品费 | S3: 品牌运营中心 | T3: 市场广告推广部 | U3: 广告投放部 | V3: 媒介部
A4: 平台与媒介公关费 | E4: 市场公关运营 | F4: 否 | L4: 否 | M4: 否 | N4: 是 | O4: 是 | P4: 营销费用 | Q4: 其他费用 | R4: 公关礼品费 | S4: 品牌运营中心 | T4: 运营策略部 | U4: 天猫运营部

Sheet 基础信息
A1: 字段 | B1: 字段属性 | C1: 字段解释 | D1: 用途与诉求 | E1: 字段名 | F1: 字段长度 | G1: 是否主键 | H1: 字段备注
A2: 营销活动场景 | B2: 文本
A3: 营销活动场景编码 | B3: 文本
A4: 能否到店铺 | B4: 下拉-单选
A5: 能否到品类 | B5: 下拉-单选
A6: 能否到SKU | B6: 下拉-单选
A7: 是否允许个人报销 | B7: 下拉-单选
A8: 是否允许无票报销 | B8: 下拉-单选
A9: 预算科目 | B9: 下拉-单选
A10: 营销活动类型 | B10: 文本

Sheet 营销活动与费用类型关联关系
A1: 序号 | B1: 费用大类 | C1: 费用小类 | D1: 费用类别 | E1: 营销活动场景 | G1: 一级预算科目 | H1: 二级预算科目 | I1: 一级部门 | J1: 二级部门 | K1: 三级部门 | L1: 四级部门 | M1: 会计科目（新） | N1: 科目编码（新） | O1: 是否允许无票 | P1: 发票类目建议 | Q1: 费控系统表单字段要求 | W1: 财务入账科目字段要求
F2: 是否允许个人垫付 | Q2: 项目 | R2: 一级部门 | S2: 二级部门 | T2: 品牌 | U2: 店铺 | V2: 广宣 | W2: 项目 | X2: 一级部门 | Y2: 二级部门 | Z2: 品牌 | AA2: 店铺 | AB2: 广宣
A3: =ROW(B3)-2 | B3: 媒介宣传费 | C3: 线上媒介费 | D3: 营销费用 | E3: 抖音品牌信息流 | F3: =VLOOKUP(E3,'收集数据表'!A:K,6,0) | G3: 品牌媒介 | H3: 线上品宣媒介 | I3: 品牌运营中心 | J3: 市场广告推广部 | K3: 广告投放部 | L3: 媒介部 | M3: 销售费用_营销费用_线上推广费 | N3: 6601.36.24 | P3: 技术服务费？服务费？
A4: =ROW(B4)-2 | B4: 媒介宣传费 | C4: 线上媒介费 | D4: 营销费用 | E4: 快手品牌信息流 | F4: =VLOOKUP(E4,'收集数据表'!A:K,6,0) | G4: 品牌媒介 | H4: 线上品宣媒介 | I4: 品牌运营中心 | J4: 市场广告推广部 | K4: 广告投放部 | L4: 媒介部 | M4: 销售费用_营销费用_线上推广费 | N4: 6601.36.24
A5: =ROW(B5)-2 | B5: 媒介宣传费 | C5: 线上媒介费 | D5: 营销费用 | E5: 开屏类广告 | F5: =VLOOKUP(E5,'收集数据表'!A:K,6,0) | G5: 品牌媒介 | H5: 线上品宣媒介 | I5: 品牌运营中心 | J5: 市场广告推广部 | K5: 广告投放部 | L5: 媒介部 | M5: 销售费用_营销费用_线上推广费 | N5: 6601.36.24 | P5: 广告发布费
A6: =ROW(B6)-2 | B6: 媒介宣传费 | C6: 线上媒介费 | D6: 营销费用 | E6: 程序化投放 | F6: =VLOOKUP(E6,'收集数据表'!A:K,6,0) | G6: 品牌媒介 | H6: 线上品宣媒介 | I6: 品牌运营中心 | J6: 市场广告推广部 | K6: 广告投放部 | L6: 媒介部 | M6: 销售费用_营销费用_线上推广费 | N6: 6601.36.24 | P6: 广告发布费
A7: =ROW(B7)-2 | B7: 媒介宣传费 | C7: 线上媒介费 | D7: 营销费用 | E7: OTT广告 | F7: =VLOOKUP(E7,'收集数据表'!A:K,6,0) | G7: 品牌媒介 | H7: 线上品宣媒介 | I7: 品牌运营中心 | J7: 市场广告推广部 | K7: 广告投放部 | L7: 媒介部 | M7: 销售费用_营销费用_线上推广费 | N7: 6601.36.24 | P7: 广告发布费
A8: =ROW(B8)-2 | B8: 媒介宣传费 | C8: 线上媒介费 | D8: 营销费用 | E8: OTV广告 | F8: =VLOOKUP(E8,'收集数据表'!A:K,6,0) | G8: 品牌媒介 | H8: 线上品宣媒介 | I8: 品牌运营中心 | J8: 市场广告推广部 | K8: 广告投放部 | L8: 媒介部 | M8: 销售费用_营销费用_线上推广费 | N8: 6601.36.24 | P8: 广告发布费
A9: =ROW(B9)-2 | B9: 媒介宣传费 | C9: 线上媒介费 | D9: 营销费用 | E9: 商业化资源包合作 | F9: =VLOOKUP(E9,'收集数据表'!A:K,6,0) | G9: 品牌媒介 | H9: 线上品宣媒介 | I9: 品牌运营中心 | J9: 市场广告推广部 | K9: 广告投放部 | L9: 媒介部 | M9: 销售费用_营销费用_线上推广费 | N9: 6601.36.24 | P9: 广告发布费
A10: =ROW(B10)-2 | B10: 媒介宣传费 | C10: 线上媒介费 | D10: 营销费用 | E10: 广告效果监测 | F10: =VLOOKUP(E10,'收集数据表'!A:K,6,0) | G10: 品牌媒介 | H10: 线上品宣媒介 | I10: 品牌运营中心 | J10: 市场广告推广部 | K10: 广告投放部 | L10: 媒介部 | M10: 销售费用_营销费用_线上推广费 | N10: 6601.36.24 | P10: 广告发布费
A11: =ROW(B11)-2 | B11: 媒介宣传费 | C11: 线下媒介费 | D11: 营销费用 | E11: 电梯广告 | F11: =VLOOKUP(E11,'收集数据表'!A:K,6,0) | G11: 品牌媒介 | H11: 线下品宣媒介 | I11: 品牌运营中心 | J11: 市场广告推广部 | K11: 广告投放部 | L11: 媒介部 | M11: 销售费用_营销费用_线下推广费 | N11: 6601.36.25 | P11: 广告发布费
A12: =ROW(B12)-2 | B12: 媒介宣传费 | C12: 线下媒介费 | D12: 营销费用 | E12: 电影院广告 | F12: =VLOOKUP(E12,'收集数据表'!A:K,6,0) | G12: 品牌媒介 | H12: 线下品宣媒介 | I12: 品牌运营中心 | J12: 市场广告推广部 | K12: 广告投放部 | L12: 媒介部 | M12: 销售费用_营销费用_线下推广费 | N12: 6601.36.25 | P12: 广告发布费
A13: =ROW(B13)-2 | B13: 媒介宣传费 | C13: 线下媒介费 | D13: 营销费用 | E13: 地标广告 | F13: =VLOOKUP(E13,'收集数据表'!A:K,6,0) | G13: 品牌媒介 | H13: 线下品宣媒介 | I13: 品牌运营中心 | J13: 市场广告推广部 | K13: 广告投放部 | L13: 媒介部 | M13: 销售费用_营销费用_线下推广费 | N13: 6601.36.25 | P13: 广告发布费
A14: =ROW(B14)-2 | B14: 品牌宣传费 | C14: 市场调研费 | D14: 营销费用 | E14: 投放策略调研 | F14: =VLOOKUP(E14,'收集数据表'!A:K,6,0) | G14: 品牌媒介 | H14: 调研费（其他非标） | I14: 品牌运营中心 | J14: 市场广告推广部 | K14: 策略部 | M14: ="销售费用_"&D14&"_"&C14 | N14: 6601.36.20 | P14: 调研服务费
A15: =ROW(B15)-2 | B15: 内容制作费 | C15: 视频制作费 | D15: 营销费用 | E15: =H15&"-"&LEFT(C15,4) | F15: =VLOOKUP(E15,'收集数据表'!A:K,6,0) | G15: 品类内容推广 | H15: AD竞价内容创意 | I15: 品牌运营中心 | J15: 市场广告推广部 | K15: 广告投放部 | L15: 内容策划组 | M15: ="销售费用_"&D15&"_"&C15 | N15: 6601.36.21 | P15: =C15
A16: =ROW(B16)-2 | B16: 内容制作费 | C16: 动画制作费 | D16: 营销费用 | E16: =H16&"-"&LEFT(C16,4) | F16: =VLOOKUP(E16,'收集数据表'!A:K,6,0) | G16: 品类内容推广 | H16: AD竞价内容创意 | I16: 品牌运营中心 | J16: 市场广告推广部 | K16: 广告投放部 | L16: 内容策划组 | M16: ="销售费用_"&D16&"_"&C16 | N16: 6601.36.07 | P16: =C16
A17: =ROW(B17)-2 | B17: 内容制作费 | C17: 图文平面制作费 | D17: 营销费用 | E17: =H17&"-"&LEFT(C17,6) | F17: =VLOOKUP(E17,'收集数据表'!A:K,6,0) | G17: 品类内容推广 | H17: AD竞价内容创意 | I17: 品牌运营中心 | J17: 市场广告推广部 | K17: 广告投放部 | L17: 内容策划组 | M17: ="销售费用_"&D17&"_"&C17 | N17: 6601.36.22 | P17: =C17
A18: =ROW(B18)-2 | B18: 内容制作费 | C18: 建模服务费 | D18: 营销费用 | E18: =H18&"-"&LEFT(C18,4) | F18: =VLOOKUP(E18,'收集数据表'!A:K,6,0) | G18: 品类内容推广 | H18: AD竞价内容创意 | I18: 品牌运营中心 | J18: 市场广告推广部 | K18: 广告投放部 | L18: 内容策划组 | M18: ="销售费用_"&D18&"_"&C18 | N18: 6601.36.10 | P18: =C18
A19: =ROW(B19)-2 | B19: 内容制作费 | C19: 渲染服务费 | D19: 营销费用 | E19: =H19&"-"&LEFT(C19,4) | F19: =VLOOKUP(E19,'收集数据表'!A:K,6,0) | G19: 品类内容推广 | H19: AD竞价内容创意 | I19: 品牌运营中心 | J19: 市场广告推广部 | K19: 广告投放部 | L19: 内容策划组 | M19: ="销售费用_"&D19&"_"&C19 | N19: 6601.36.26 | P19: =C19
A20: =ROW(B20)-2 | B20: 内容制作费 | C20: 模特服务费 | D20: 营销费用 | E20: =H20&"-"&LEFT(C20,4) | F20: =VLOOKUP(E20,'收集数据表'!A:K,6,0) | G20: 品类内容推广 | H20: AD竞价内容创意 | I20: 品牌运营中心 | J20: 市场广告推广部 | K20: 广告投放部 | L20: 内容策划组 | M20: ="销售费用_"&D20&"_"&C20 | N20: 6601.36.13 | P20: =C20
A21: =ROW(B21)-2 | B21: 内容制作费 | C21: 专业人物合作费 | D21: 营销费用 | E21: =H21&"-"&LEFT(C21,6) | F21: =VLOOKUP(E21,'收集数据表'!A:K,6,0) | G21: 品类内容推广 | H21: AD竞价内容创意 | I21: 品牌运营中心 | J21: 市场广告推广部 | K21: 广告投放部 | L21: 内容策划组 | M21: ="销售费用_"&D21&"_"&C21 | N21: 6601.36.32 | P21: =C21
A22: =ROW(B22)-2 | B22: 内容制作费 | C22: 服化道费用 | D22: 营销费用 | E22: =H22&"-"&LEFT(C22,4) | F22: =VLOOKUP(E22,'收集数据表'!A:K,6,0) | G22: 品类内容推广 | H22: AD竞价内容创意 | I22: 品牌运营中心 | J22: 市场广告推广部 | K22: 广告投放部 | L22: 内容策划组 | M22: ="销售费用_"&D22&"_"&C22 | N22: 6601.36.08 | P22: 服装费、化妆费、道具费
A23: =ROW(B23)-2 | B23: 内容制作费 | C23: 拍摄服务费 | D23: 营销费用 | E23: =H23&"-"&LEFT(C23,4) | F23: =VLOOKUP(E23,'收集数据表'!A:K,6,0) | G23: 品类内容推广 | H23: AD竞价内容创意 | I23: 品牌运营中心 | J23: 市场广告推广部 | K23: 广告投放部 | L23: 内容策划组 | M23: ="销售费用_"&D23&"_"&C23 | N23: 6601.36.15 | P23: =C23
A24: =ROW(B24)-2 | B24: 内容制作费 | C24: 拍摄物料费 | D24: 营销费用 | E24: =H24&"-"&LEFT(C24,4) | F24: =VLOOKUP(E24,'收集数据表'!A:K,6,0) | G24: 品类内容推广 | H24: AD竞价内容创意 | I24: 品牌运营中心 | J24: 市场广告推广部 | K24: 广告投放部 | L24: 内容策划组 | M24: ="销售费用_"&D24&"_"&C24 | N24: 6601.36.16 | P24: =C24
A25: =ROW(B25)-2 | B25: 内容制作费 | C25: 内容制作费 | D25: 营销费用 | E25: =H25&"-"&LEFT(C25,4) | F25: =VLOOKUP(E25,'收集数据表'!A:K,6,0) | G25: 品类内容推广 | H25: AD竞价内容创意 | I25: 品牌运营中心 | J25: 市场广告推广部 | K25: 广告投放部 | L25: 内容策划组 | M25: ="销售费用_"&D25&"_"&C25 | N25: 6601.36.14 | P25: =C25
A26: =ROW(B26)-2 | B26: 达人推广费 | C26: 内容推广费 | D26: 营销费用 | E26: DOU+ | F26: =VLOOKUP(E26,'收集数据表'!A:K,6,0) | G26: 品类内容推广 | H26: 内容加热 | I26: 品牌运营中心 | J26: 市场广告推广部 | K26: 市场推广部 | L26: 内容投放组 | M26: 销售费用_营销费用_线上推广费 | N26: 6601.36.24 | P26: 技术服务费？服务费？
A27: =ROW(B27)-2 | B27: 达人推广费 | C27: 内容推广费 | D27: 营销费用 | E27: 快手作品推荐 | F27: =VLOOKUP(E27,'收集数据表'!A:K,6,0) | G27: 品类内容推广 | H27: 内容加热 | I27: 品牌运营中心 | J27: 市场广告推广部 | K27: 市场推广部 | L27: 内容投放组 | M27: 销售费用_营销费用_线上推广费 | N27: 6601.36.24 | P27: 技术服务费？服务费？
A28: =ROW(B28)-2 | B28: 达人推广费 | C28: 内容推广费 | D28: 营销费用 | E28: 内容热推 | F28: =VLOOKUP(E28,'收集数据表'!A:K,6,0) | G28: 品类内容推广 | H28: 内容加热 | I28: 品牌运营中心 | J28: 市场广告推广部 | K28: 市场推广部 | L28: 内容投放组 | M28: 销售费用_营销费用_线上推广费 | N28: 6601.36.24 | P28: 技术服务费？服务费？
A29: =ROW(B29)-2 | B29: 达人推广费 | C29: 内容推广费 | D29: 营销费用 | E29: 内容服务 | F29: =VLOOKUP(E29,'收集数据表'!A:K,6,0) | G29: 品类内容推广 | H29: 内容加热 | I29: 品牌运营中心 | J29: 市场广告推广部 | K29: 市场推广部 | L29: 内容投放组 | M29: 销售费用_营销费用_线上推广费 | N29: 6601.36.24 | P29: 技术服务费？服务费？
A30: =ROW(B30)-2 | B30: 达人推广费 | C30: 内容推广费 | D30: 营销费用 | E30: 星聚力 | F30: =VLOOKUP(E30,'收集数据表'!A:K,6,0) | G30: 品类内容推广 | H30: 内容加热 | I30: 品牌运营中心 | J30: 市场广告推广部 | K30: 市场推广部 | L30: 内容投放组 | M30: 销售费用_营销费用_线上推广费 | N30: 6601.36.24 | P30: 技术服务费？服务费？
A31: =ROW(B31)-2 | B31: 达人推广费 | C31: 内容推广费 | D31: 营销费用 | E31: 小红书加热 | F31: =VLOOKUP(E31,'收集数据表'!A:K,6,0) | G31: 品类内容推广 | H31: 其他新媒体加热 | I31: 品牌运营中心 | J31: 市场广告推广部 | K31: 市场推广部 | L31: 内容投放组 | M31: 销售费用_营销费用_线上推广费 | N31: 6601.36.24 | P31: 技术服务费？服务费？
A32: =ROW(B32)-2 | B32: 达人推广费 | C32: 内容推广费 | D32: 营销费用 | E32: B站起飞加热 | F32: =VLOOKUP(E32,'收集数据表'!A:K,6,0) | G32: 品类内容推广 | H32: 其他新媒体加热 | I32: 品牌运营中心 | J32: 市场广告推广部 | K32: 市场推广部 | L32: 内容投放组 | M32: 销售费用_营销费用_线上推广费 | N32: 6601.36.24 | P32: 技术服务费？服务费？
A33: =ROW(B33)-2 | B33: 达人推广费 | C33: 内容推广费 | D33: 营销费用 | E33: 微博粉条 | F33: =VLOOKUP(E33,'收集数据表'!A:K,6,0) | G33: 品类内容推广 | H33: 其他新媒体加热 | I33: 品牌运营中心 | J33: 市场广告推广部 | K33: 市场推广部 | L33: 内容投放组 | M33: 销售费用_营销费用_线上推广费 | N33: 6601.36.24 | P33: 技术服务费？服务费？
A34: =ROW(B34)-2 | B34: 达人推广费 | C34: 内容推广费 | D34: 营销费用 | E34: 粉丝通 | F34: =VLOOKUP(E34,'收集数据表'!A:K,6,0) | G34: 品类内容推广 | H34: 其他新媒体加热 | I34: 品牌运营中心 | J34: 市场广告推广部 | K34: 市场推广部 | L34: 内容投放组 | M34: 销售费用_营销费用_线上推广费 | N34: 6601.36.24 | P34: 技术服务费？服务费？
A35: =ROW(B35)-2 | B35: 达人推广费 | C35: 内容推广费 | D35: 营销费用 | E35: 微博搜索 | F35: =VLOOKUP(E35,'收集数据表'!A:K,6,0) | G35: 品类内容推广 | H35: 其他新媒体加热 | I35: 品牌运营中心 | J35: 市场广告推广部 | K35: 市场推广部 | L35: 内容投放组 | M35: 销售费用_营销费用_线上推广费 | N35: 6601.36.24 | P35: 技术服务费？服务费？
A36: =ROW(B36)-2 | B36: 渠道推广费 | C36: 站内推广费 | D36: 营销费用 | E36: 天猫-直通车 | F36: =VLOOKUP(E36,'收集数据表'!A:K,6,0) | G36: 平台电商推广 | H36: 淘内-推广 | I36: 品牌运营中心 | J36: 运营策略部 | K36: 天猫运营部 | L36: 天猫推广组 | M36: 销售费用_营销费用_线上推广费 | N36: 6601.36.24 | P36: 技术服务费？服务费？
A37: =ROW(B37)-2 | B37: 渠道推广费 | C37: 站内推广费 | D37: 营销费用 | E37: 天猫-引力魔方 | F37: =VLOOKUP(E37,'收集数据表'!A:K,6,0) | G37: 平台电商推广 | H37: 淘内-推广 | I37: 品牌运营中心 | J37: 运营策略部 | K37: 天猫运营部 | L37: 天猫推广组 | M37: 销售费用_营销费用_线上推广费 | N37: 6601.36.24 | P37: 技术服务费？服务费？
... A58: =ROW(B58)-2 | B58: 渠道推广费 | C58: 站内推广费 | D58: 营销费用 | E58: 京东POP-联合活动 | F58: =VLOOKUP(E58,'收集数据表'!A:K,6,0) | G58: 平台电商推广 | H58: 京东渠道推广（POP） | I58: 品牌运营中心 | J58: 渠道运营部 | K58: 特色电商部 | L58: 京东唯品推广组 | M58: 销售费用_营销费用_线上推广费 | N58: 6601.36.24 | P58: 技术服务费？服务费？广告费？
A59: =ROW(B59)-2 | B59: 品牌宣传费 | C59: 明星合作费 | D59: 营销费用 | E59: =H59 | F59: =VLOOKUP(E59,'收集数据表'!A:K,6,0) | G59: 品牌项目 | H59: 日常-创意与物料 | I59: 品牌产品中心 | J59: 品牌营销部 | M59: 销售费用_营销费用_明星合作费 | N59: 6601.36.12 | P59: 代言费 | Q59: Y
A60: =ROW(B60)-2 | B60: 渠道推广费 | C60: 站内推广费 | D60: 营销费用 | E60: 唯品会-唯品常规投放 | F60: =VLOOKUP(E60,'收集数据表'!A:K,6,0) | G60: 平台电商推广 | H60: 唯品渠道推广 | I60: 品牌运营中心 | J60: 渠道运营部 | K60: 特色电商部 | L60: 京东唯品推广组 | M60: 销售费用_营销费用_线上推广费 | N60: 6601.36.24 | P60: 技术服务费？服务费？
...

Sheet 营销计划（活动-更新）
A1: 营销活动分类 | B1: 营销活动场景 | C1: 判断是否新增 | D1: 一级预算科目 | E1: 二级预算科目 | G1: 能否到店铺 | H1: 店铺 | I1: 渠道 | J1: 业务来源 | K1: 业务单元 | L1: 能否到品类（单品简称） | M1: 能否到SKU | N1: 是否允许个人报销 | O1: 是否允许无票报销 | P1: 费用类型 | Q1: 费用大类 | R1: 费用小类 | S1: 一级部门 | T1: 二级部门 | U1: 三级部门 | V1: 四级部门
A2: IP明星内容合作 | B2: IP合作 | C2: =VLOOKUP(B2,'收集数据表'!$A$2:$A$201,1,FALSE) | D2: IP明星内容合作 | E2: 品牌IP及娱乐营销 | F2: 品牌IP及娱乐营销 | G2: 否 | L2: 否 | M2: 否 | N2: 否 | O2: 否 | P2: 营销费用 | Q2: 品牌宣传费 | R2: 创意策划服务费 | S2: 品牌运营中心 | T2: 市场广告推广部 | U2: 市场推广部 | V2: 市场PR部
A3: IP明星内容合作 | B3: 明星差旅 | C3: =VLOOKUP(B3,'收集数据表'!$A$2:$A$201,1,FALSE) | D3: IP明星内容合作 | E3: 明星差旅 | F3: 明星差旅 | G3: 否 | L3: 否 | M3: 否 | N3: 是 | O3: 是 | P3: 营销费用 | Q3: 其他费用 | R3: 明星差旅费 | S3: 品牌运营中心 | T3: 市场广告推广部 | U3: 市场推广部 | V3: 娱乐营销部
A4: IP明星内容合作 | B4: 明星代言单次合作 | C4: =VLOOKUP(B4,'收集数据表'!$A$2:$A$201,1,FALSE) | D4: IP明星内容合作 | E4: 明星代言单次 | F4: 明星代言单次 | G4: 否 | L4: 否 | M4: 否 | N4: 否 | O4: 否 | P4: 营销费用 | Q4: 品牌宣传费 | R4: 明星合作费 | S4: 品牌运营中心 | T4: 市场广告推广部 | U4: 市场推广部 | V4: 娱乐营销部
A5: IP明星内容合作 | B5: 明星代言合作 | C5: =VLOOKUP(B5,'收集数据表'!$A$2:$A$201,1,FALSE) | D5: IP明星内容合作 | E5: 明星代言摊销 | F5: 明星代言摊销 | G5: 否 | L5: 否 | M5: 否 | N5: 否 | O5: 否 | P5: 营销费用 | Q5: 品牌宣传费 | R5: 明星合作费 | S5: 品牌运营中心 | T5: 市场广告推广部 | U5: 市场推广部 | V5: 娱乐营销部
A6: IP明星内容合作 | B6: 明星拍摄 | C6: =VLOOKUP(B6,'收集数据表'!$A$2:$A$201,1,FALSE) | D6: IP明星内容合作 | E6: 明星拍摄 | F6: 明星拍摄 | G6: 否 | L6: 否 | M6: 否 | N6: 是 | O6: 是 | P6: 营销费用 | Q6: 其他费用 | R6: 场地租赁费 | S6: 品牌运营中心 | T6: 市场广告推广部 | U6: 市场推广部 | V6: 娱乐营销部
A7: IP明星内容合作 | B7: 明星影综营销号 | C7: =VLOOKUP(B7,'收集数据表'!$A$2:$A$201,1,FALSE) | D7: IP明星内容合作 | E7: 品牌IP及娱乐营销 | F7: 品牌IP及娱乐营销 | G7: 否 | L7: 否 | M7: 否 | N7: 否 | O7: 否 | P7: 营销费用 | Q7: 品牌宣传费 | R7: 营销宣传费 | S7: 品牌运营中心 | T7: 市场广告推广部 | U7: 市场推广部 | V7: 娱乐营销部
A8: IP明星内容合作 | B8: 明星妆发造 | C8: =VLOOKUP(B8,'收集数据表'!$A$2:$A$201,1,FALSE) | D8: IP明星内容合作 | E8: 明星妆发造 | F8: 明星妆发造 | G8: 否 | L8: 否 | M8: 否 | N8: 是 | O8: 是 | P8: 营销费用 | Q8: 内容制作费 | R8: 服化道费用 | S8: 品牌运营中心 | T8: 市场广告推广部 | U8: 市场推广部 | V8: 娱乐营销部
A9: IP明星内容合作 | B9: 明星综艺线下活动 | C9: =VLOOKUP(B9,'收集数据表'!$A$2:$A$201,1,FALSE) | D9: IP明星内容合作 | E9: 明星代言单次 | F9: 明星代言单次 | G9: 否 | L9: 否 | M9: 否 | N9: 否 | O9: 否 | P9: 营销费用 | Q9: 品牌宣传费 | R9: 创意策划服务费 | S9: 品牌运营中心 | T9: 市场广告推广部 | U9: 市场推广部 | V9: 娱乐营销部
A10: IP明星内容合作 | B10: 影视综艺植入 | C10: =VLOOKUP(B10,'收集数据表'!$A$2:$A$201,1,FALSE) | D10: IP明星内容合作 | E10: 品牌IP及娱乐营销 | F10: 品牌IP及娱乐营销 | G10: 否 | L10: 否 | M10: 否 | N10: 否 | O10: 否 | P10: 营销费用 | Q10: 品牌宣传费 | R10: 品牌植入费 | S10: 品牌运营中心 | T10: 市场广告推广部 | U10: 市场推广部 | V10: 娱乐营销部
A11: 其他达人直播 | B11: 抖音直播服务费-抖音其他 | C11: =VLOOKUP(B11,'收集数据表'!$A$2:$A$201,1,FALSE) | D11: 达人直播 | E11: 服务费-抖音其他 | F11: 服务费-抖音其他 | G11: 是 | H11: 抖音花西子官方旗舰店 | I11: 抖音渠道 | J11: 抖音达播 | L11: 是 | M11: 否 | N11: 否 | O11: 否 | P11: 营销费用 | Q11: 渠道推广费 | R11: 直播服务费 | S11: 品牌运营中心 | T11: 市场广告推广部 | U11: 达播2部
A12: SKA达人 | B12: 抖音直播服务费-抖音其他 | C12: =VLOOKUP(B12,'收集数据表'!$A$2:$A$201,1,FALSE) | D12: 达人直播 | E12: 服务费-抖音其他 | F12: 服务费-抖音其他 | G12: 是 | H12: 抖音花西子官方旗舰店 | I12: 抖音渠道 | J12: 抖音达播 | L12: 是 | M12: 否 | N12: 否 | O12: 否 | P12: 营销费用 | Q12: 渠道推广费 | R12: 直播服务费 | S12: 品牌运营中心 | T12: 市场广告推广部 | U12: 达播2部
A13: 田恬 | B13: 抖音直播服务费-田恬 | C13: =VLOOKUP(B13,'收集数据表'!$A$2:$A$201,1,FALSE) | D13: 达人直播 | E13: 佣金-田恬 | F13: 佣金-田恬 | G13: 是 | H13: 抖音花西子官方旗舰店 | I13: 抖音渠道 | J13: 抖音达播 | L13: 是 | M13: 是 | N13: 否 | O13: 否 | P13: 营销费用 | Q13: 渠道推广费 | R13: 直播服务费 | S13: 品牌运营中心 | T13: 直播运营部 | U13: 达播BD部
A14: 其他达人直播 | B14: 抖音直播服务费-团长计划 | C14: =VLOOKUP(B14,'收集数据表'!$A$2:$A$201,1,FALSE) | D14: 达人直播 | E14: 服务费-团长计划 | F14: 服务费-团长计划 | G14: 是 | H14: 抖音花西子官方旗舰店 | I14: 抖音渠道 | J14: 抖音达播 | L14: 是 | M14: 否 | N14: 否 | O14: 否 | P14: 营销费用 | Q14: 渠道推广费 | R14: 直播服务费 | S14: 品牌运营中心 | T14: 市场广告推广部 | U14: 达播2部
A15: 其他达人直播 | B15: 抖音直播坑位费-抖音其他 | C15: =VLOOKUP(B15,'收集数据表'!$A$2:$A$201,1,FALSE) | D15: 达人直播 | E15: 佣金-抖音其他 | F15: 佣金-抖音其他 | G15: 是 | H15: 抖音花西子官方旗舰店 | I15: 抖音渠道 | J15: 抖音达播 | L15: 否 | M15: 否 | N15: 否 | O15: 否 | P15: 营销费用 | Q15: 渠道推广费 | R15: 直播坑位费 | S15: 品牌运营中心 | T15: 市场广告推广部 | U15: 达播2部
A16: SKA达人 | B16: 抖音直播坑位费-抖音其他 | C16: =VLOOKUP(B16,'收集数据表'!$A$2:$A$201,1,FALSE) | D16: 达人直播 | E16: 佣金-抖音其他 | F16: 佣金-抖音其他 | G16: 是 | H16: 抖音花西子官方旗舰店 | I16: 抖音渠道 | J16: 抖音达播 | L16: 否 | M16: 否 | N16: 否 | O16: 否 | P16: 营销费用 | Q16: 渠道推广费 | R16: 直播坑位费 | S16: 品牌运营中心 | T16: 市场广告推广部 | U16: 达播2部
A17: 田恬 | B17: 抖音直播坑位费-田恬 | C17: =VLOOKUP(B17,'收集数据表'!$A$2:$A$201,1,FALSE) | D17: 达人直播 | E17: 服务费-田恬 | F17: 服务费-田恬 | G17: 是 | H17: 抖音花西子官方旗舰店 | I17: 抖音渠道 | J17: 抖音达播 | L17: 否 | M17: 否 | N17: 否 | O17: 否 | P17: 营销费用 | Q17: 渠道推广费 | R17: 直播坑位费 | S17: 品牌运营中心 | T17: 直播运营部 | U17: 达播BD部
A18: 其他达人直播 | B18: 抖音直播坑位费-团长计划 | C18: =VLOOKUP(B18,'收集数据表'!$A$2:$A$201,1,FALSE) | D18: 达人直播 | E18: 佣金-团长计划 | F18: 佣金-团长计划 | G18: 是 | H18: 抖音花西子官方旗舰店 | I18: 抖音渠道 | J18: 抖音达播 | L18: 否 | M18: 否 | N18: 否 | O18: 否 | P18: 营销费用 | Q18: 渠道推广费 | R18: 直播坑位费 | S18: 品牌运营中心 | T18: 市场广告推广部 | U18: 达播2部
A19: 其他达人直播 | B19: 快手直播服务费 | C19: =VLOOKUP(B19,'收集数据表'!$A$2:$A$201,1,FALSE) | D19: 达人直播 | E19: 佣金-快手 | F19: 佣金-快手 | G19: 是 | H19: 快手花西子旗舰店 | I19: 快手渠道 | J19: 快手达播 | L19: 是 | M19: 是 | N19: 否 | O19: 否 | P19: 营销费用 | Q19: 渠道推广费 | R19: 直播服务费 | S19: 品牌运营中心 | T19: 市场广告推广部 | U19: 达播2部
A20: SKA达人 | B20: 快手直播服务费 | C20: =VLOOKUP(B20,'收集数据表'!$A$2:$A$201,1,FALSE) | D20: 达人直播 | E20: 佣金-快手 | F20: 佣金-快手 | G20: 是 | H20: 快手花西子旗舰店 | I20: 快手渠道 | J20: 快手达播 | L20: 是 | M20: 是 | N20: 否 | O20: 否 | P20: 营销费用 | Q20: 渠道推广费 | R20: 直播服务费 | S20: 品牌运营中心 | T20: 市场广告推广部 | U20: 达播2部
A21: 其他达人直播 | B21: 快手直播坑位费 | C21: =VLOOKUP(B21,'收集数据表'!$A$2:$A$201,1,FALSE) | D21: 达人直播 | E21: 服务费-快手 | F21: 服务费-快手 | G21: 是 | H21: 快手花西子旗舰店 | I21: 快手渠道 | J21: 快手达播 | L21: 否 | M21: 否 | N21: 否 | O21: 否 | P21: 营销费用 | Q21: 渠道推广费 | R21: 直播坑位费 | S21: 品牌运营中心 | T21: 市场广告推广部 | U21: 达播2部
A22: SKA达人 | B22: 快手直播坑位费 | C22: =VLOOKUP(B22,'收集数据表'!$A$2:$A$201,1,FALSE) | D22: 达人直播 | E22: 服务费-快手 | F22: 服务费-快手 | G22: 是 | H22: 快手花西子旗舰店 | I22: 快手渠道 | J22: 快手达播 | L22: 否 | M22: 否 | N22: 否 | O22: 否 | P22: 营销费用 | Q22: 渠道推广费 | R22: 直播坑位费 | S22: 品牌运营中心 | T22: 市场广告推广部 | U22: 达播2部
A23: 其他达人直播 | B23: 明星直播合作 | C23: =VLOOKUP(B23,'收集数据表'!$A$2:$A$201,1,FALSE) | D23: 达人直播 | E23: 服务费 | F23: 服务费 | G23: 是 | L23: 否 | M23: 否 | N23: 否 | O23: 否 | P23: 营销费用 | Q23: 品牌宣传费 | R23: 明星合作费 | S23: 品牌运营中心 | T23: 直播运营部 | U23: 达播BD部
A24: 其他达人直播 | B24: 其他直播服务费 | C24: =VLOOKUP(B24,'收集数据表'!$A$2:$A$201,1,FALSE) | D24: 达人直播 | E24: 佣金-其他 | F24: 佣金-其他 | G24: 是 | L24: 是 | M24: 是 | N24: 否 | O24: 否 | P24: 营销费用 | Q24: 渠道推广费 | R24: 直播服务费 | S24: 品牌运营中心 | T24: 直播运营部 | U24: 达播BD部
A25: 其他达人直播 | B25: 其他直播坑位费 | C25: =VLOOKUP(B25,'收集数据表'!$A$2:$A$201,1,FALSE) | D25: 达人直播 | E25: 服务费-其他 | F25: 服务费-其他 | G25: 是 | L25: 否 | M25: 否 | N25: 否 | O25: 否 | P25: 营销费用 | Q25: 渠道推广费 | R25: 直播坑位费 | S25: 品牌运营中心 | T25: 直播运营部 | U25: 达播BD部
A26: 李佳琦 | B26: 天猫直播服务费-李佳琦 | C26: =VLOOKUP(B26,'收集数据表'!$A$2:$A$201,1,FALSE) | D26: 达人直播 | E26: 佣金-佳琦 | F26: 佣金-佳琦 | G26: 是 | H26: 天猫花西子旗舰店 | I26: 天猫渠道 | J26: 天猫达播 | L26: 是 | M26: 是 | N26: 否 | O26: 否 | P26: 营销费用 | Q26: 渠道推广费 | R26: 直播服务费 | S26: 品牌运营中心 | T26: 直播运营部 | U26: 达播BD部
A27: 其他达人直播 | B27: 天猫直播服务费-其他 | C27: =VLOOKUP(B27,'收集数据表'!$A$2:$A$201,1,FALSE) | D27: 达人直播 | E27: 佣金-淘内其他 | F27: 佣金-淘内其他 | G27: 是 | H27: 天猫花西子旗舰店 | I27: 天猫渠道 | J27: 天猫达播 | L27: 是 | M27: 是 | N27: 否 | O27: 否 | P27: 营销费用 | Q27: 渠道推广费 | R27: 直播服务费 | S27: 品牌运营中心 | T27: 直播运营部 | U27: 达播BD部
A28: SKA达人 | B28: 天猫直播服务费-其他 | C28: =VLOOKUP(B28,'收集数据表'!$A$2:$A$201,1,FALSE) | D28: 达人直播 | E28: 佣金-淘内其他 | F28: 佣金-淘内其他 | G28: 是 | H28: 天猫花西子旗舰店 | I28: 天猫渠道 | J28: 天猫达播 | L28: 是 | M28: 是 | N28: 否 | O28: 否 | P28: 营销费用 | Q28: 渠道推广费 | R28: 直播服务费 | S28: 品牌运营中心 | T28: 直播运营部 | U28: 达播BD部
A29: 李佳琦 | B29: 天猫直播坑位费-李佳琦 | C29: =VLOOKUP(B29,'收集数据表'!$A$2:$A$201,1,FALSE) | D29: 达人直播 | E29: 服务费-佳琦 | F29: 服务费-佳琦 | G29: 是 | H29: 天猫花西子旗舰店 | I29: 天猫渠道 | J29: 天猫达播 | L29: 否 | M29: 否 | N29: 否 | O29: 否 | P29: 营销费用 | Q29: 渠道推广费 | R29: 直播坑位费 | S29: 品牌运营中心 | T29: 直播运营部 | U29: 达播BD部
A30: 其他达人直播 | B30: 天猫直播坑位费-其他 | C30: =VLOOKUP(B30,'收集数据表'!$A$2:$A$201,1,FALSE) | D30: 达人直播 | E30: 服务费-淘内其他 | F30: 服务费-淘内其他 | G30: 是 | H30: 天猫花西子旗舰店 | I30: 天猫渠道 | J30: 天猫达播 | L30: 否 | M30: 否 | N30: 否 | O30: 否 | P30: 营销费用 | Q30: 渠道推广费 | R30: 直播坑位费 | S30: 品牌运营中心 | T30: 直播运营部 | U30: 达播BD部
A31: SKA达人 | B31: 天猫直播坑位费-其他 | C31: =VLOOKUP(B31,'收集数据表'!$A$2:$A$201,1,FALSE) | D31: 达人直播 | E31: 服务费-淘内其他 | F31: 服务费-淘内其他 | G31: 是 | H31: 天猫花西子旗舰店 | I31: 天猫渠道 | J31: 天猫达播 | L31: 否 | M31: 否 | N31: 否 | O31: 否 | P31: 营销费用 | Q31: 渠道推广费 | R31: 直播坑位费 | S31: 品牌运营中心 | T31: 直播运营部 | U31: 达播BD部
A32: 达人直播 | B32: 直播专场服务 | C32: =VLOOKUP(B32,'收集数据表'!$A$2:$A$201,1,FALSE) | D32: 达人直播 | E32: 服务费-淘内其他 | F32: 服务费-淘内其他 | G32: 是 | L32: 否 | M32: 否 | N32: 否 | O32: 否 | P32: 营销费用 | Q32: 内容制作费 | R32: 专业人物合作费 | S32: 品牌运营中心 | T32: 直播运营部 | U32: 达播BD部
A33: 素材创意制作 | B33: AD竞价内容创意-场地租赁 | C33: =VLOOKUP(B33,'收集数据表'!$A$2:$A$201,1,FALSE) | D33: 品类内容推广 | E33: AD竞价内容创意 | F33: AD竞价内容创意 | G33: 否 | L33: 否 | M33: 否 | N33: 是 | O33: 是 | P33: 营销费用 | Q33: 其他费用 | R33: 场地租赁费 | S33: 品牌运营中心 | T33: 市场广告推广部 | U33: 广告投放部 | V33: 内容策划组
A34: 素材创意制作 | B34: AD竞价内容创意-动画制作 | C34: =VLOOKUP(B34,'收集数据表'!$A$2:$A$201,1,FALSE) | D34: 品类内容推广 | E34: AD竞价内容创意 | F34: AD竞价内容创意 | G34: 否 | L34: 否 | M34: 否 | N34: 是 | O34: 是 | P34: 营销费用 | Q34: 内容制作费 | R34: 动画制作费 | S34: 品牌运营中心 | T34: 市场广告推广部 | U34: 广告投放部 | V34: 内容策划组
A35: 素材创意制作 | B35: AD竞价内容创意-服化道费 | C35: =VLOOKUP(B35,'收集数据表'!$A$2:$A$201,1,FALSE) | D35: 品类内容推广 | E35: AD竞价内容创意 | F35: AD竞价内容创意 | G35: 否 | L35: 否 | M35: 否 | N35: 是 | O35: 是 | P35: 营销费用 | Q35: 内容制作费 | R35: 服化道费用 | S35: 品牌运营中心 | T35: 市场广告推广部 | U35: 广告投放部 | V35: 内容策划组
A36: 素材创意制作 | B36: AD竞价内容创意-建模服务 | C36: =VLOOKUP(B36,'收集数据表'!$A$2:$A$201,1,FALSE) | D36: 品类内容推广 | E36: AD竞价内容创意 | F36: AD竞价内容创意 | G36: 否 | L36: 否 | M36: 否 | N36: 是 | O36: 是 | P36: 营销费用 | Q36: 内容制作费 | R36: 建模服务费 | S36: 品牌运营中心 | T36: 市场广告推广部 | U36: 广告投放部 | V36: 内容策划组
A37: 素材创意制作 | B37: AD竞价内容创意-模特服务 | C37: =VLOOKUP(B37,'收集数据表'!$A$2:$A$201,1,FALSE) | D37: 品类内容推广 | E37: AD竞价内容创意 | F37: AD竞价内容创意 | G37: 否 | L37: 否 | M37: 否 | N37: 是 | O37: 是 | P37: 营销费用 | Q37: 内容制作费 | R37: 模特服务费 | S37: 品牌运营中心 | T37: 市场广告推广部 | U37: 广告投放部 | V37: 内容策划组
A38: 素材创意制作 | B38: AD竞价内容创意-内容制作 | C38: =VLOOKUP(B38,'收集数据表'!$A$2:$A$201,1,FALSE) | D38: 品类内容推广 | E38: AD竞价内容创意 | F38: AD竞价内容创意 | G38: 否 | L38: 否 | M38: 否 | N38: 是 | O38: 是 | P38: 营销费用 | Q38: 内容制作费 | R38: 内容制作费 | S38: 品牌运营中心 | T38: 市场广告推广部 | U38: 广告投放部 | V38: 内容策划组
A39: 素材创意制作 | B39: AD竞价内容创意-拍摄服务 | C39: =VLOOKUP(B39,'收集数据表'!$A$2:$A$201,1,FALSE) | D39: 品类内容推广 | E39: AD竞价内容创意 | F39: AD竞价内容创意 | G39: 否 | L39: 否 | M39: 否 | N39: 是 | O39: 是 | P39: 营销费用 | Q39: 内容制作费 | R39: 拍摄服务费 | S39: 品牌运营中心 | T39: 市场广告推广部 | U39: 广告投放部 | V39: 内容策划组
A40: 素材创意制作 | B40: AD竞价内容创意-拍摄物料 | C40: =VLOOKUP(B40,'收集数据表'!$A$2:$A$201,1,FALSE) | D40: 品类内容推广 | E40: AD竞价内容创意 | F40: AD竞价内容创意 | G40: 否 | L40: 否 | M40: 否 | N40: 是 | O40: 是 | P40: 营销费用 | Q40: 内容制作费 | R40: 拍摄物料费 | S40: 品牌运营中心 | T40: 市场广告推广部 | U40: 广告投放部 | V40: 内容策划组
...

Sheet 收集数据表
A1: 营销活动场景名称 | C1: 营销活动场景编码 | D1: 能否到店铺 | E1: 店铺 | F1: 渠道 | G1: 业务来源 | H1: 业务单元 | I1: 能否到品类（单品简称） | J1: 能否到SKU | K1: 是否允许个人报销 | L1: 是否允许无票报销 | M1: 预算科目 | N1: 预算二级科目 | O1: 费用类型 | P1: 费用大类 | Q1: 费用小类
A2: 抖音品牌信息流 | B2: =VLOOKUP(A2,'营销计划（活动-更新）'!$B$2:$D$213,1,FALSE) | C2: YXHD01 | D2: 否 | I2: 否 | K2: 否 | L2: =K2 | M2: 品牌媒介 | N2: 线上品宣媒介 | O2: 营销费用 | P2: 媒介宣传费 | Q2: 线上媒介费
A3: 快手品牌信息流 | B3: =VLOOKUP(A3,'营销计划（活动-更新）'!$B$2:$D$213,1,FALSE) | C3: YXHD02 | D3: 否 | I3: 否 | K3: 否 | L3: =K3 | M3: 品牌媒介 | N3: 线上品宣媒介 | O3: 营销费用 | P3: 媒介宣传费 | Q3: 线上媒介费
A4: 开屏类广告 | B4: =VLOOKUP(A4,'营销计划（活动-更新）'!$B$2:$D$213,1,FALSE) | C4: YXHD03 | D4: 否 | I4: 否 | K4: 否 | L4: =K4 | M4: 品牌媒介 | N4: 线上品宣媒介 | O4: 营销费用 | P4: 媒介宣传费 | Q4: 线上媒介费
A5: 程序化投放 | B5: =VLOOKUP(A5,'营销计划（活动-更新）'!$B$2:$D$213,1,FALSE) | C5: YXHD04 | D5: 否 | I5: 否 | K5: 否 | L5: =K5 | M5: 品牌媒介 | N5: 线上品宣媒介 | O5: 营销费用 | P5: 媒介宣传费 | Q5: 线上媒介费
A6: OTT广告 | B6: =VLOOKUP(A6,'营销计划（活动-更新）'!$B$2:$D$213,1,FALSE) | C6: YXHD05 | D6: 否 | I6: 否 | K6: 否 | L6: =K6 | M6: 品牌媒介 | N6: 线上品宣媒介 | O6: 营销费用 | P6: 媒介宣传费 | Q6: 线上媒介费
A7: OTV广告 | B7: =VLOOKUP(A7,'营销计划（活动-更新）'!$B$2:$D$213,1,FALSE) | C7: YXHD06 | D7: 否 | I7: 否 | K7: 否 | L7: =K7 | M7: 品牌媒介 | N7: 线上品宣媒介 | O7: 营销费用 | P7: 媒介宣传费 | Q7: 线上媒介费
A8: 商业化资源包合作 | B8: =VLOOKUP(A8,'营销计划（活动-更新）'!$B$2:$D$213,1,FALSE) | C8: YXHD07 | D8: 否 | I8: 否 | K8: 否 | L8: =K8 | M8: 品牌媒介 | N8: 线上品宣媒介 | O8: 营销费用 | P8: 媒介宣传费 | Q8: 线上媒介费
A9: 广告效果监测 | B9: =VLOOKUP(A9,'营销计划（活动-更新）'!$B$2:$D$213,1,FALSE) | C9: YXHD08 | D9: 否 | I9: 否 | K9: 否 | L9: =K9 | M9: 品牌媒介 | N9: 线上品宣媒介 | O9: 营销费用 | P9: 媒介宣传费 | Q9: 线上媒介费
A10: 电梯广告 | B10: =VLOOKUP(A10,'营销计划（活动-更新）'!$B$2:$D$213,1,FALSE) | C10: YXHD09 | D10: 否 | I10: 否 | K10: 否 | L10: =K10 | M10: 品牌媒介 | N10: 线下品宣媒介 | O10: 营销费用 | P10: 媒介宣传费 | Q10: 线下媒介费
A11: 电影院广告 | B11: =VLOOKUP(A11,'营销计划（活动-更新）'!$B$2:$D$213,1,FALSE) | C11: YXHD10 | D11: 否 | I11: 否 | K11: 否 | L11: =K11 | M11: 品牌媒介 | N11: 线下品宣媒介 | O11: 营销费用 | P11: 媒介宣传费 | Q11: 线下媒介费
A12: 地标广告 | B12: =VLOOKUP(A12,'营销计划（活动-更新）'!$B$2:$D$213,1,FALSE) | C12: YXHD11 | D12: 否 | I12: 否 | K12: 否 | L12: =K12 | M12: 品牌媒介 | N12: 线下品宣媒介 | O12: 营销费用 | P12: 媒介宣传费 | Q12: 线下媒介费
A13: 投放策略调研 | B13: =VLOOKUP(A13,'营销计划（活动-更新）'!$B$2:$D$213,1,FALSE) | C13: YXHD12 | D13: 否 | I13: 否 | K13: 否 | L13: =K13 | M13: 品牌媒介 | N13: 调研费（其他非标） | O13: 营销费用 | P13: 品牌宣传费 | Q13: 市场调研费
... A25: DOU+ | B25: =VLOOKUP(A25,'营销计划（活动-更新）'!$B$2:$D$213,1,FALSE) | C25: YXHD24 | D25: 否 | I25: 否 | K25: 否 | L25: =K25 | M25: 品类内容推广 | N25: 内容加热 | O25: 营销费用 | P25: 达人推广费 | Q25: 内容推广费
A26: 快手作品推荐 | B26: =VLOOKUP(A26,'营销计划（活动-更新）'!$B$2:$D$213,1,FALSE) | C26: YXHD25 | D26: 是 | E26: 天猫花西子旗舰店 | I26: 否 | K26: 否 | L26: =K26 | M26: 品类内容推广 | N26: 内容加热 | O26: 营销费用 | P26: 达人推广费 | Q26: 内容推广费
A27: 内容热推 | B27: =VLOOKUP(A27,'营销计划（活动-更新）'!$B$2:$D$213,1,FALSE) | C27: YXHD26 | D27: 否 | I27: 否 | K27: 否 | L27: =K27 | M27: 品类内容推广 | N27: 内容加热 | O27: 营销费用 | P27: 达人推广费 | Q27: 内容推广费
A28: 内容服务 | B28: =VLOOKUP(A28,'营销计划（活动-更新）'!$B$2:$D$213,1,FALSE) | C28: YXHD27 | D28: 否 | I28: 否 | K28: 否 | L28: =K28 | M28: 品类内容推广 | N28: 内容加热 | O28: 营销费用 | P28: 达人推广费 | Q28: 内容推广费
A29: 星聚力 | B29: =VLOOKUP(A29,'营销计划（活动-更新）'!$B$2:$D$213,1,FALSE) | C29: YXHD28 | D29: 否 | I29: 否 | K29: 否 | L29: =K29 | M29: 品类内容推广 | N29: 内容加热 | O29: 营销费用 | P29: 达人推广费 | Q29: 内容推广费
A30: 小红书加热 | B30: =VLOOKUP(A30,'营销计划（活动-更新）'!$B$2:$D$213,1,FALSE) | C30: YXHD29 | D30: 否 | I30: 否 | K30: 否 | L30: =K30 | M30: 品类内容推广 | N30: 其他新媒体加热 | O30: 营销费用 | P30: 达人推广费 | Q30: 内容推广费
A31: B站起飞加热 | B31: =VLOOKUP(A31,'营销计划（活动-更新）'!$B$2:$D$213,1,FALSE) | C31: YXHD30 | D31: 否 | I31: 否 | K31: 否 | L31: =K31 | M31: 品类内容推广 | N31: 其他新媒体加热 | O31: 营销费用 | P31: 达人推广费 | Q31: 内容推广费
A32: 微博粉条 | B32: =VLOOKUP(A32,'营销计划（活动-更新）'!$B$2:$D$213,1,FALSE) | C32: YXHD31 | D32: 否 | I32: 否 | K32: 否 | L32: =K32 | M32: 品类内容推广 | N32: 其他新媒体加热 | O32: 营销费用 | P32: 达人推广费 | Q32: 内容推广费
A33: 粉丝通 | B33: =VLOOKUP(A33,'营销计划（活动-更新）'!$B$2:$D$213,1,FALSE) | C33: YXHD32 | D33: 否 | I33: 否 | K33: 否 | L33: =K33 | M33: 品类内容推广 | N33: 其他新媒体加热 | O33: 营销费用 | P33: 达人推广费 | Q33: 内容推广费
A34: 微博搜索 | B34: =VLOOKUP(A34,'营销计划（活动-更新）'!$B$2:$D$213,1,FALSE) | C34: YXHD33 | D34: 否 | I34: 否 | K34: 否 | L34: =K34 | M34: 品类内容推广 | N34: 其他新媒体加热 | O34: 营销费用 | P34: 达人推广费 | Q34: 内容推广费
A35: 天猫-直通车 | B35: =VLOOKUP(A35,'营销计划（活动-更新）'!$B$2:$D$213,1,FALSE) | C35: YXHD34 | D35: 是 | E35: 天猫花西子旗舰店 | F35: 天猫渠道 | G35: 天猫货架 | I35: 是 | J35: 是 | K35: 否 | L35: =K35 | M35: 平台电商推广 | N35: 淘内-推广 | O35: 营销费用 | P35: 渠道推广费 | Q35: 站内推广费
A36: 天猫-引力魔方 | B36: =VLOOKUP(A36,'营销计划（活动-更新）'!$B$2:$D$213,1,FALSE) | C36: YXHD35 | D36: 是 | E36: 天猫花西子旗舰店 | F36: 天猫渠道 | G36: 天猫货架 | I36: 是 | J36: 是 | K36: 否 | L36: =K36 | M36: 平台电商推广 | N36: 淘内-推广 | O36: 营销费用 | P36: 渠道推广费 | Q36: 站内推广费
A37: 天猫-万相台-超级短视频 | B37: =VLOOKUP(A37,'营销计划（活动-更新）'!$B$2:$D$213,1,FALSE) | C37: YXHD36 | D37: 是 | E37: 天猫花西子旗舰店 | F37: 天猫渠道 | G37: 天猫货架 | I37: 否 | J37: 否 | K37: 否 | L37: =K37 | M37: 平台电商推广 | N37: 淘内-推广 | O37: 营销费用 | P37: 渠道推广费 | Q37: 站内推广费
A38: 天猫-明星店铺 | B38: =VLOOKUP(A38,'营销计划（活动-更新）'!$B$2:$D$213,1,FALSE) | C38: YXHD37 | D38: 是 | E38: 天猫花西子旗舰店 | F38: 天猫渠道 | G38: 天猫货架 | I38: 否 | J38: 否 | K38: 否 | L38: =K38 | M38: 平台电商推广 | N38: 淘内-推广 | O38: 营销费用 | P38: 渠道推广费 | Q38: 站内推广费
A39: 天猫-互动城 | B39: =VLOOKUP(A39,'营销计划（活动-更新）'!$B$2:$D$213,1,FALSE) | C39: YXHD38 | D39: 是 | E39: 天猫花西子旗舰店 | F39: 天猫渠道 | G39: 天猫货架 | I39: 否 | J39: 否 | K39: 否 | L39: =K39 | M39: 平台电商推广 | N39: 淘内-推广 | O39: 营销费用 | P39: 渠道推广费 | Q39: 站内推广费
A40: 天猫-万相台-超级直播 | B40: =VLOOKUP(A40,'营销计划（活动-更新）'!$B$2:$D$213,1,FALSE) | C40: YXHD39 | D40: 是 | E40: 天猫花西子旗舰店 | F40: 天猫渠道 | G40: 天猫自播 | I40: 否 | J40: 否 | K40: 否 | L40: =K40 | M40: 平台电商推广 | N40: 淘内-推广 | O40: 营销费用 | P40: 渠道推广费 | Q40: 站内推广费
A41: 天猫-超级互动城 | B41: =VLOOKUP(A41,'营销计划（活动-更新）'!$B$2:$D$213,1,FALSE) | C41: YXHD40 | D41: 是 | E41: 天猫花西子旗舰店 | F41: 天猫渠道 | G41: 天猫货架 | I41: 否 | J41: 否 | K41: 否 | L41: =K41 | M41: 平台电商推广 | N41: 淘内-推广 | O41: 营销费用 | P41: 渠道推广费 | Q41: 站内推广费
A42: 天猫-极速推 | B42: =VLOOKUP(A42,'营销计划（活动-更新）'!$B$2:$D$213,1,FALSE) | C42: YXHD41 | D42: 是 | E42: 天猫花西子旗舰店 | F42: 天猫渠道 | G42: 天猫货架 | I42: 否 | J42: 否 | K42: 否 | L42: =K42 | M42: 平台电商推广 | N42: 淘内-推广 | O42: 营销费用 | P42: 渠道推广费 | Q42: 站内推广费
A43: 天猫-妈妈Club | B43: =VLOOKUP(A43,'营销计划（活动-更新）'!$B$2:$D$213,1,FALSE) | C43: YXHD42 | D43: 是 | E43: 天猫花西子旗舰店 | F43: 天猫渠道 | G43: 天猫货架 | I43: 否 | J43: 否 | K43: 否 | L43: =K43 | M43: 平台电商推广 | N43: 淘内-推广 | O43: 营销费用 | P43: 渠道推广费 | Q43: 站内推广费
A44: 天猫-品牌专区 | B44: =VLOOKUP(A44,'营销计划（活动-更新）'!$B$2:$D$213,1,FALSE) | C44: YXHD43 | D44: 是 | E44: 天猫花西子旗舰店 | F44: 天猫渠道 | G44: 天猫货架 | I44: 否 | J44: 否 | K44: 否 | L44: =K44 | M44: 平台电商推广 | N44: 淘内-品专 | O44: 营销费用 | P44: 渠道推广费 | Q44: 站内推广费
A45: 淘宝客 | B45: =VLOOKUP(A45,'营销计划（活动-更新）'!$B$2:$D$213,1,FALSE) | C45: YXHD44 | D45: 是 | E45: 天猫花西子旗舰店 | F45: 天猫渠道 | G45: 天猫货架 | I45: 是 | J45: 是 | K45: 否 | L45: =K45 | M45: 平台电商推广 | N45: 淘内-淘宝客 | O45: 营销费用 | P45: 渠道推广费 | Q45: 站内推广费
A46: 京东自营-京准通常规投放 | B46: =VLOOKUP(A46,'营销计划（活动-更新）'!$B$2:$D$213,1,FALSE) | C46: YXHD45 | D46: 是 | E46: 花西子京东自营旗舰店 | F46: 京东渠道 | G46: 自营货架 | I46: 是 | J46: 是 | K46: 否 | L46: =K46 | M46: 平台电商推广 | N46: 京东渠道推广（自营） | O46: 营销费用 | P46: 渠道推广费 | Q46: 站内推广费
... A57: 京东POP-联合活动 | B57: =VLOOKUP(A57,'营销计划（活动-更新）'!$B$2:$D$213,1,FALSE) | C57: YXHD56 | D57: 是 | E57: 京东花西子旗舰店 | F57: 京东渠道 | G57: POP货架 | I57: 否 | J57: 否 | K57: 否 | L57: =K57 | M57: 平台电商推广 | N57: 京东渠道推广（POP） | O57: 营销费用 | P57: 渠道推广费 | Q57: 站内推广费
A58: 日常-创意与物料 | B58: =VLOOKUP(A58,'营销计划（活动-更新）'!$B$2:$D$213,1,FALSE) | C58: YXHD57 | D58: 否 | I58: 否 | J58: 否 | K58: 否 | L58: =K58 | M58: 品牌项目 | N58: 日常-创意与物料 | O58: 营销费用 | P58: 品牌宣传费 | Q58: 明星合作费
A59: 唯品会-唯品常规投放 | B59: =VLOOKUP(A59,'营销计划（活动-更新）'!$B$2:$D$213,1,FALSE) | C59: YXHD58 | D59: 是 | E59: 唯品会自营花西子旗舰店 | F59: 唯品会 | G59: 唯品货架 | I59: 是 | J59: 否 | K59: 否 | L59: =K59 | M59: 平台电商推广 | N59: 唯品渠道推广 | O59: 营销费用 | P59: 渠道推广费 | Q59: 站内推广费
A60: 唯品会-达人卖货 | B60: =VLOOKUP(A60,'营销计划（活动-更新）'!$B$2:$D$213,1,FALSE) | C60: YXHD59 | D60: 是 | E60: 唯品会自营花西子旗舰店 | F60: 唯品会 | G60: 唯品货架 | I60: 是 | J60: 是 | K60: 否 | L60: =K60 | M60: 平台电商推广 | N60: 唯品渠道推广 | O60: 营销费用 | P60: 渠道推广费 | Q60: 站内推广费
A61: 自营其他 | B61: =VLOOKUP(A61,'营销计划（活动-更新）'!$B$2:$D$213,1,FALSE) | C61: YXHD60 | D61: 是 | K61: 否 | L61: =K61 | M61: 平台电商推广 | N61: 自营其他渠道推广 | O61: 营销费用 | P61: 渠道推广费 | Q61: 站内推广费
...

Sheet 预算部门->营销活动计划分类
A1: 营销活动分类 | C1: 一级部门 | D1: 二级部门 | E1: 三级部门 | F1: 四级部门 | H1: YSZZ01030205 | I1: HDFL01 | J1: HDFL01
A2: IP明星内容合作 | B2: =VLOOKUP(A2,'营销活动计划分类'!$A$1:$B$43,2,FALSE) | C2: 品牌运营中心 | D2: 市场广告推广部 | E2: 市场推广部 | F2: 市场PR组 | H2: YSZZ0102 | I2: HDFL39 | J2: HDFL39
A3: IP明星内容合作 | B3: =VLOOKUP(A3,'营销活动计划分类'!$A$1:$B$43,2,FALSE) | C3: 品牌运营中心 | D3: 市场广告推广部 | E3: 市场推广部 | F3: 娱乐营销组 | H3: YSZZ010201 | I3: HDFL38 | J3: HDFL38
A4: IP明星内容合作 | B4: =VLOOKUP(A4,'营销活动计划分类'!$A$1:$B$43,2,FALSE) | C4: 品牌运营中心 | D4: 市场广告推广部 | E4: 市场推广部 | F4: 娱乐营销组 | H4: YSZZ010202 | I4: HDFL04 | J4: HDFL04；HDFL05；HDFL16；HDFL17
A5: IP明星内容合作 | B5: =VLOOKUP(A5,'营销活动计划分类'!$A$1:$B$43,2,FALSE) | C5: 品牌运营中心 | D5: 市场广告推广部 | E5: 市场推广部 | F5: 娱乐营销组 | H5: YSZZ010202 | I5: HDFL05
A6: IP明星内容合作 | B6: =VLOOKUP(A6,'营销活动计划分类'!$A$1:$B$43,2,FALSE) | C6: 品牌运营中心 | D6: 市场广告推广部 | E6: 市场推广部 | F6: 娱乐营销组 | H6: YSZZ010202 | I6: HDFL16
A7: IP明星内容合作 | B7: =VLOOKUP(A7,'营销活动计划分类'!$A$1:$B$43,2,FALSE) | C7: 品牌运营中心 | D7: 市场广告推广部 | E7: 市场推广部 | F7: 娱乐营销组 | H7: YSZZ010202 | I7: HDFL17
A8: IP明星内容合作 | B8: =VLOOKUP(A8,'营销活动计划分类'!$A$1:$B$43,2,FALSE) | C8: 品牌运营中心 | D8: 市场广告推广部 | E8: 市场推广部 | F8: 娱乐营销组 | H8: YSZZ010204 | I8: HDFL38 | J8: HDFL38；HDFL41
A9: IP明星内容合作 | B9: =VLOOKUP(A9,'营销活动计划分类'!$A$1:$B$43,2,FALSE) | C9: 品牌运营中心 | D9: 市场广告推广部 | E9: 市场推广部 | F9: 娱乐营销组 | H9: YSZZ010204 | I9: HDFL41
A10: IP明星内容合作 | B10: =VLOOKUP(A10,'营销活动计划分类'!$A$1:$B$43,2,FALSE) | C10: 品牌运营中心 | D10: 市场广告推广部 | E10: 市场推广部 | F10: 娱乐营销组 | H10: YSZZ01030101 | I10: HDFL06 | J10: HDFL06
A11: 其他达人直播 | B11: =VLOOKUP(A11,'营销活动计划分类'!$A$1:$B$43,2,FALSE) | C11: 品牌运营中心 | D11: 市场广告推广部 | E11: 达播2部 | H11: YSZZ01030102 | I11: HDFL08 | J11: HDFL08；HDFL09
A12: 田恬 | B12: =VLOOKUP(A12,'营销活动计划分类'!$A$1:$B$43,2,FALSE) | C12: 品牌运营中心 | D12: 直播运营部 | E12: SKA达播部 | H12: YSZZ01030102 | I12: HDFL09
A13: 其他达人直播 | B13: =VLOOKUP(A13,'营销活动计划分类'!$A$1:$B$43,2,FALSE) | C13: 品牌运营中心 | D13: 市场广告推广部 | E13: 达播2部 | H13: YSZZ010302 | I13: HDFL18 | J13: HDFL18；HDFL30；HDFL31
A14: 其他达人直播 | B14: =VLOOKUP(A14,'营销活动计划分类'!$A$1:$B$43,2,FALSE) | C14: 品牌运营中心 | D14: 市场广告推广部 | E14: 达播2部 | H14: YSZZ010302 | I14: HDFL30
A15: 田恬 | B15: =VLOOKUP(A15,'营销活动计划分类'!$A$1:$B$43,2,FALSE) | C15: 品牌运营中心 | D15: 直播运营部 | E15: SKA达播部 | H15: YSZZ010302 | I15: HDFL31
A16: 其他达人直播 | B16: =VLOOKUP(A16,'营销活动计划分类'!$A$1:$B$43,2,FALSE) | C16: 品牌运营中心 | D16: 市场广告推广部 | E16: 达播2部 | H16: YSZZ01030204 | I16: HDFL01 | J16: HDFL01
A17: 其他达人直播 | B17: =VLOOKUP(A17,'营销活动计划分类'!$A$1:$B$43,2,FALSE) | C17: 品牌运营中心 | D17: 市场广告推广部 | E17: 达播2部 | H17: YSZZ01030205 | I17: HDFL31 | J17: HDFL31
A18: 其他达人直播 | B18: =VLOOKUP(A18,'营销活动计划分类'!$A$1:$B$43,2,FALSE) | C18: 品牌运营中心 | D18: 市场广告推广部 | E18: 达播2部 | H18: YSZZ01030206 | I18: HDFL07 | J18: HDFL07
A19: 李佳琦 | B19: =VLOOKUP(A19,'营销活动计划分类'!$A$1:$B$43,2,FALSE) | C19: 品牌运营中心 | D19: 直播运营部 | E19: SKA达播部 | H19: YSZZ010303 | I19: HDFL08 | J19: HDFL08
A20: 其他达人直播 | B20: =VLOOKUP(A20,'营销活动计划分类'!$A$1:$B$43,2,FALSE) | C20: 品牌运营中心 | D20: 市场广告推广部 | E20: 达播2部 | H20: YSZZ010304 | I20: HDFL02 | J20: HDFL02；HDFL06；HDFL17；HDFL38
A21: 李佳琦 | B21: =VLOOKUP(A21,'营销活动计划分类'!$A$1:$B$43,2,FALSE) | C21: 品牌运营中心 | D21: 直播运营部 | E21: SKA达播部 | H21: YSZZ010304 | I21: HDFL06
A22: 其他达人直播 | B22: =VLOOKUP(A22,'营销活动计划分类'!$A$1:$B$43,2,FALSE) | C22: 品牌运营中心 | D22: 市场广告推广部 | E22: 达播2部 | H22: YSZZ010304 | I22: HDFL17
A23: 素材创意制作 | B23: =VLOOKUP(A23,'营销活动计划分类'!$A$1:$B$43,2,FALSE) | C23: 品牌运营中心 | D23: 市场广告推广部 | E23: 广告投放部 | F23: 内容策划组 | H23: YSZZ010304 | I23: HDFL38
A24: 素材创意制作 | B24: =VLOOKUP(A24,'营销活动计划分类'!$A$1:$B$43,2,FALSE) | C24: 品牌运营中心 | D24: 市场广告推广部 | E24: 广告投放部 | F24: 内容策划组 | H24: YSZZ010401 | I24: HDFL36 | J24: HDFL36
A25: 素材创意制作 | B25: =VLOOKUP(A25,'营销活动计划分类'!$A$1:$B$43,2,FALSE) | C25: 品牌运营中心 | D25: 市场广告推广部 | E25: 广告投放部 | F25: 内容策划组 | H25: YSZZ01040101 | I25: HDFL33 | J25: HDFL33
A26: 素材创意制作 | B26: =VLOOKUP(A26,'营销活动计划分类'!$A$1:$B$43,2,FALSE) | C26: 品牌运营中心 | D26: 市场广告推广部 | E26: 广告投放部 | F26: 内容策划组 | H26: YSZZ010402 | I26: HDFL29 | J26: HDFL29
A27: 素材创意制作 | B27: =VLOOKUP(A27,'营销活动计划分类'!$A$1:$B$43,2,FALSE) | C27: 品牌运营中心 | D27: 市场广告推广部 | E27: 广告投放部 | F27: 内容策划组 | H27: YSZZ01040301 | I27: HDFL06 | J27: HDFL06
A28: 素材创意制作 | B28: =VLOOKUP(A28,'营销活动计划分类'!$A$1:$B$43,2,FALSE) | C28: 品牌运营中心 | D28: 市场广告推广部 | E28: 广告投放部 | F28: 内容策划组 | H28: YSZZ01040302 | I28: HDFL06 | J28: HDFL06；HDFL07；HDFL34；HDFL35
A29: 素材创意制作 | B29: =VLOOKUP(A29,'营销活动计划分类'!$A$1:$B$43,2,FALSE) | C29: 品牌运营中心 | D29: 市场广告推广部 | E29: 广告投放部 | F29: 内容策划组 | H29: YSZZ01040302 | I29: HDFL07
A30: 素材创意制作 | B30: =VLOOKUP(A30,'营销活动计划分类'!$A$1:$B$43,2,FALSE) | C30: 品牌运营中心 | D30: 市场广告推广部 | E30: 广告投放部 | F30: 内容策划组 | H30: YSZZ01040302 | I30: HDFL34
A31: 素材创意制作 | B31: =VLOOKUP(A31,'营销活动计划分类'!$A$1:$B$43,2,FALSE) | C31: 品牌运营中心 | D31: 市场广告推广部 | E31: 广告投放部 | F31: 内容策划组 | H31: YSZZ01040302 | I31: HDFL35
A32: 素材创意制作 | B32: =VLOOKUP(A32,'营销活动计划分类'!$A$1:$B$43,2,FALSE) | C32: 品牌运营中心 | D32: 市场广告推广部 | E32: 广告投放部 | F32: 内容策划组 | H32: YSZZ01040306 | I32: HDFL07 | J32: HDFL07；HDFL37
A33: 素材创意制作 | B33: =VLOOKUP(A33,'营销活动计划分类'!$A$1:$B$43,2,FALSE) | C33: 品牌运营中心 | D33: 市场广告推广部 | E33: 广告投放部 | F33: 内容策划组 | H33: YSZZ01040306 | I33: HDFL37
A34: 素材创意制作 | B34: =VLOOKUP(A34,'营销活动计划分类'!$A$1:$B$43,2,FALSE) | C34: 品牌运营中心 | D34: 市场广告推广部 | E34: 广告投放部 | F34: 内容策划组 | H34: YSZZ010501 | I34: HDFL19 | J34: HDFL19；HDFL24
A35: 素材创意制作 | B35: =VLOOKUP(A35,'营销活动计划分类'!$A$1:$B$43,2,FALSE) | C35: 品牌运营中心 | D35: 市场广告推广部 | E35: 广告投放部 | F35: 内容策划组 | H35: YSZZ010501 | I35: HDFL24
A36: 素材创意制作 | B36: =VLOOKUP(A36,'营销活动计划分类'!$A$1:$B$43,2,FALSE) | C36: 品牌运营中心 | D36: 市场广告推广部 | E36: 广告投放部 | F36: 内容策划组 | H36: YSZZ0106 | I36: HDFL25 | J36: HDFL25
A37: 内容加热 | B37: =VLOOKUP(A37,'营销活动计划分类'!$A$1:$B$43,2,FALSE) | C37: 品牌运营中心 | D37: 市场广告推广部 | E37: 市场推广部 | F37: 内容投放组 | H37: YSZZ010801 | I37: HDFL40 | J37: HDFL40；HDFL42
A38: 内容加热 | B38: =VLOOKUP(A38,'营销活动计划分类'!$A$1:$B$43,2,FALSE) | C38: 品牌运营中心 | D38: 市场广告推广部 | E38: 市场推广部 | F38: 内容投放组 | H38: YSZZ010801 | I38: HDFL42
A39: 素材创意制作 | B39: =VLOOKUP(A39,'营销活动计划分类'!$A$1:$B$43,2,FALSE) | C39: 品牌运营中心 | D39: 内容电商部 | E39: 抖音部 | F39: 内容部 | H39: YSZZ010802 | I39: HDFL22 | J39: HDFL22
A40: 素材创意制作 | B40: =VLOOKUP(A40,'营销活动计划分类'!$A$1:$B$43,2,FALSE) | C40: 品牌运营中心 | D40: 内容电商部 | E40: 抖音部 | F40: 内容部 | H40: YSZZ010902 | I40: HDFL20 | J40: HDFL20；HDFL21；HDFL28
...

Sheet Sheet9
A1: 得物部 | B1: HDFL08 | C1: HDFL08；HDFL26；HDFL27；HDFL05；HDFL04；HDFL40；HDFL42
A2: 得物部 | B2: HDFL26
A3: 得物部 | B3: HDFL27
A4: 得物部 | B4: HDFL05
A5: 得物部 | B5: HDFL04
A6: 得物部 | B6: HDFL40
A7: 得物部 | B7: HDFL42
A8: 抖音部 | B8: HDFL06
A9: 抖音部 | B9: HDFL07
A10: 抖音部 | B10: HDFL08 | C10: HDFL08；HDFL24；HDFL25；HDFL34；HDFL35；HDFL37
A11: 抖音部 | B11: HDFL24
A12: 抖音部 | B12: HDFL25
A13: 抖音部 | B13: HDFL34
A14: 抖音部 | B14: HDFL35
A15: 抖音部 | B15: HDFL37
A16: 京东部 | B16: HDFL20 | C16: HDFL20；HDFL21；HDFL28
A17: 京东部 | B17: HDFL21
A18: 京东部 | B18: HDFL28
A19: 快手部 | B19: HDFL07 | C19: HDFL07；HDFL08；HDFL09；HDFL24；HDFL25；HDFL33；HDFL36；HDFL38
A20: 快手部 | B20: HDFL08
A21: 快手部 | B21: HDFL09
A22: 快手部 | B22: HDFL24
A23: 快手部 | B23: HDFL25
A24: 快手部 | B24: HDFL33
A25: 快手部 | B25: HDFL36
A26: 快手部 | B26: HDFL38
A27: 拼多多部 | B27: HDFL07 | C27: HDFL07；HDFL22
A28: 拼多多部 | B28: HDFL22
A29: 品牌产品中心 | B29: HDFL10 | C29: HDFL10；HDFL11；HDFL12；HDFL13；HDFL14；HDFL15；HDFL27；HDFL29；HDFL23；HDFL40
A30: 品牌产品中心 | B30: HDFL11
A31: 品牌产品中心 | B31: HDFL12
A32: 品牌产品中心 | B32: HDFL13
A33: 品牌产品中心 | B33: HDFL14
A34: 品牌产品中心 | B34: HDFL15
A35: 品牌运营中心 | B35: HDFL27
A36: 品牌运营中心 | B36: HDFL29
A37: 品牌运营中心 | B37: HDFL23
A38: 品牌运营中心 | B38: HDFL40
A39: 市场广告推广部 | B39: HDFL01 | C39: HDFL01；HDFL02；HDFL06；HDFL07；HDFL08；HDFL17；HDFL18；HDFL30；HDFL31
A40: 市场广告推广部 | B40: HDFL02
...
